Workbook

Sheet Info
B2: Номер | C2: Нормативные документы | D2: Ссылки | F2: Schedule | 1 Division | H2: ссылка | J2: Active modification | L2: Banned heroes
B3: 1 | C3: Tournament format | D3: ссылка | F3: Matches and results | 1 Division | H3: ссылка | J3: Сломанные стены | L3: Name | M3: Date of ban
B4: 2 | C4: Регламент | D4: ссылка | F4: Teams | 1 Division | H4: ссылка | J4: Опасные заросли | L4: Aulus | M4: 22.04.2026 - 29.04.2026
B5: 3 | C5: Технические правила | D5: ссылка | J5: Летящее облако | L5: Gloo | M5: 24.04.2026 - 03.05.2026
B6: 4 | C6: Правила трансляций | D6: ссылка | F6: Schedule | 2 Division | H6: ссылка | J6: Бурные реки | L6: Hirara | M6: Неопределенный срок
B7: 5 | C7: Дисциплинарный регламент ФКС России | D7: ссылка | F7: Matches and results | 2 Division | H7: ссылка
B8: 6 | C8: Регламент ФКС России по этике | D8: ссылка | F8: Teams | 2 Division | H8: ссылка
B9: 7 | C9: Официальные правила вида спорта «компьютерный спорт» | D9: ссылка
F10: Schedule | CQ + Playoffs | H10: ссылка
F11: Matches | CQ + Playoffs | H11: ссылка

Sheet Tournament format
A2: RoL Split 1&2 Qualifiers to 2 Division
C3: Qualifier 1 | E3: Qualifier 3
C5: Qualifier 2 | E5: Qualifier 4
A9: RoL Split 1&2 Double round-robin stage
C10: 1 Division | G10: 2 Division
C11: Final Place | D11: Prize | E11: Progression | G11: Final Place | H11: Prize | I11: Progression
D12: 980000 | E12: Split Final | H12: 210000
D13: 720000 | E13: Split Final | H13: 160000
D14: 560000 | H14: 140000
D15: 460000 | H15: 130000
D16: 360000 | H16: 110000
D17: 350000 | H17: 100000
D18: 290000 | H18: 80000
D19: 280000 | H19: 70000
C20: Double round-robin BO3 14 days 56 matches | G20: Double round-robin BO3 14 days 56 matches
A26: RoL Split 1&2 Final
C27: Closed Qualifier (ONLINE) | D27: Participants | G27: Info | H27: Stage | I27: Stage | J27: Stage | K27: Stage | L27: Stage | M27: Stage | N27: Stage
D28: Team name | E28: Team standings | F28: Position | H28: I | I28: II | J28: III | K28: III | L28: IV | M28: IV | N28: V
D29: ='Schedule | 1 Division'!B17 -> Virtus.pro | E29: 3rd of Division 1 | F29: Tier 1 | H29: Day 1 BO3 | I29: Day 2 BO3 | J29: Day 3 BO3 | K29: Day 3 BO3 | L29: Day 4 BO5 | M29: Day 5 BO5 | N29: Day 5 BO7
D30: ='Schedule | 1 Division'!B18 -> Team Yandex | E30: 4th of Division 1 | F30: Tier 1 | G30: Winner Bracket (WB)
D31: ='Schedule | 1 Division'!B19 -> FORZE | E31: 5th of Division 1 | F31: Tier 2 | H31: =D35 -> The Soulless Team | I31: =D31 -> FORZE
D32: ='Schedule | 1 Division'!B20 -> CYBERHERO | E32: 6th of Division 1 | F32: Tier 2 | H32: Match 1 | I32: Match 5
D33: ='Schedule | 1 Division'!B21 -> Magic | E33: 7th of Division 1 | F33: Tier 2 | H33: =D42 -> Suplex team | I33: ='Schedule | CQ + Playoffs'!I10 -> The Soulless Team | J33: ='Schedule | CQ + Playoffs'!E16 -> FORZE | K33: =D29 -> Virtus.pro
D34: ='Schedule | 1 Division'!B22 -> Aura Farmers | E34: 8th of Division 1 | F34: Tier 2 | J34: Match 9 | K34: Match 11
D35: ='Schedule | 2 Division'!B15 -> The Soulless Team | E35: 1st of Division 2 | F35: Tier 3 | H35: =D36 -> HARD GRIND | I35: =D32 -> CYBERHERO | J35: ='Schedule | CQ + Playoffs'!I16 -> CYBERHERO | K35: ='Schedule | CQ + Playoffs'!I18 -> CYBERHERO
D36: ='Schedule | 2 Division'!B16 -> HARD GRIND | E36: 2nd of Division 2 | F36: Tier 3 | H36: Match 2 | I36: Match 6
D37: ='Schedule | 2 Division'!B17 -> TSA White | E37: 3rd of Division 2 | F37: Tier 3 | H37: =D41 -> Dark Phoenix | I37: ='Schedule | CQ + Playoffs'!I11 -> HARD GRIND | L37: =K33 -> Virtus.pro
D38: ='Schedule | 2 Division'!B18 -> INVISION | E38: 4th of Division 2 | F38: Tier 3 | L38: Match 13
D39: ='Schedule | 2 Division'!B19 -> Aterion Esports | E39: 5th of Division 2 | F39: Tier 3 | H39: =D37 -> TSA White | I39: =D33 -> Magic | L39: =K41 -> Team Yandex
D40: ='Schedule | 2 Division'!B20 -> Omnix | E40: 6th of Division 2 | F40: Tier 3 | H40: Match 3 | I40: Match 7
D41: ='Schedule | 2 Division'!B21 -> Dark Phoenix | E41: 7th of Division 2 | F41: Tier 3 | H41: =D40 -> Omnix | I41: ='Schedule | CQ + Playoffs'!I12 -> Omnix | J41: =I41 -> Omnix | K41: =D30 -> Team Yandex
D42: ='Schedule | 2 Division'!B22 -> Suplex team | E42: 8th of Division 2 | F42: Tier 3 | J42: Match 10 | K42: Match 12
H43: =D38 -> INVISION | I43: =D34 -> Aura Farmers | J43: ='Schedule | CQ + Playoffs'!I17 -> Aura Farmers | K43: =J41 -> Omnix
H44: Match 4 | I44: Match 8
H45: =D39 -> Aterion Esports | I45: ='Schedule | CQ + Playoffs'!I13 -> Aterion Esports
G47: Loser Bracket (LB)
L48: =K43 -> Omnix
L49: Match 14
L50: =J33 -> FORZE | M50: =L50 -> FORZE | N50: =L39 -> Team Yandex
M51: Match 16 | N51: Match 17
...

Sheet Schedule | CQ + Playoffs
A1: Teams & Results | E1: Schedule | Closed Qualifier | M1: Schedule | Playoffs
A2: Total Results | E2: 46188 | M2: 46194
A3: Team | B3: Place | C3: Prize | E3: Team 1 | F3: Score | G3: Time | H3: Score | I3: Team 2 | J3: Format | K3: Match | M3: Team 1 | N3: Score | O3: Time | P3: Score | Q3: Team 2 | R3: Bracket | S3: Format | T3: Match
B4: 1 | C4: 1750000 | E4: ='Tournament format'!H31 -> The Soulless Team | F4: ='Matches | CQ + Playoffs'!G73 -> 2 | G4: 0.75 | H4: ='Matches | CQ + Playoffs'!H73 -> 1 | I4: ='Tournament format'!H33 -> Suplex team | J4: Best of 3 | K4: Match 1 | M4: =A23 -> Team Spirit | N4: ='Matches | CQ + Playoffs'!BO83 -> 3 | O4: 0.625 | P4: ='Matches | CQ + Playoffs'!BP83 -> 2 | Q4: =A26 -> FORZE | R4: Upper Semi-final | S4: Best of 5 | T4: Match 1
B5: 2 | C5: 1250000 | E5: ='Tournament format'!H35 -> HARD GRIND | F5: ='Matches | CQ + Playoffs'!G93 -> 2 | G5: 0.8125 | H5: ='Matches | CQ + Playoffs'!H93 -> 0 | I5: ='Tournament format'!H37 -> Dark Phoenix | J5: Best of 3 | K5: Match 2 | M5: =A24 -> Verso Time | N5: ='Matches | CQ + Playoffs'!BO113 -> 3 | O5: 0.6875 | P5: ='Matches | CQ + Playoffs'!BP113 -> 0 | Q5: =A25 -> Virtus.pro | R5: Upper Semi-final | S5: Best of 5 | T5: Match 2
B6: 3 | C6: 750000 | E6: ='Tournament format'!H39 -> TSA White | F6: ='Matches | CQ + Playoffs'!G113 -> 0 | G6: 0.875 | H6: ='Matches | CQ + Playoffs'!H113 -> 2 | I6: ='Tournament format'!H41 -> Omnix | J6: Best of 3 | K6: Match 3 | M6: =A23 -> Team Spirit | N6: ='Matches | CQ + Playoffs'!BO143 -> 1 | O6: 0.75 | P6: ='Matches | CQ + Playoffs'!BP143 -> 3 | Q6: =A24 -> Verso Time | R6: Upper Final | S6: Best of 5 | T6: Match 3
A7: =A25 -> Virtus.pro | B7: 4 | C7: 250000 | E7: ='Tournament format'!H43 -> INVISION | F7: ='Matches | CQ + Playoffs'!G133 -> 1 | G7: 0.9375 | H7: ='Matches | CQ + Playoffs'!H133 -> 2 | I7: ='Tournament format'!H45 -> Aterion Esports | J7: Best of 3 | K7: Match 4 | M7: =A26 -> FORZE | N7: ='Matches | CQ + Playoffs'!BO173 -> 3 | O7: 0.8125 | P7: ='Matches | CQ + Playoffs'!BP173 -> 2 | Q7: =A25 -> Virtus.pro | R7: Lower Semi-Final | S7: Best of 5 | T7: Match 4
A8: =I22 -> Team Yandex | B8: 46148 | E8: 46189 | M8: 46256
A9: =I27 -> CYBERHERO | B9: 46148 | E9: Team 1 | F9: Score | G9: Time | H9: Score | I9: Team 2 | J9: Format | K9: Match | M9: Team 1 | N9: Score | O9: Time | P9: Score | Q9: Team 2 | R9: Bracket | S9: Format | T9: Match
A10: =E24 -> Aura Farmers | B10: 46211 | E10: ='Tournament format'!I31 -> FORZE | F10: ='Matches | CQ + Playoffs'!S73 -> 2 | G10: 0.75 | H10: ='Matches | CQ + Playoffs'!T73 -> 0 | I10: =E4 -> The Soulless Team | J10: Best of 3 | K10: Match 5 | M10: =A23 -> Team Spirit | N10: 0 | P10: 0 | Q10: =M7 -> FORZE | R10: Lower Final | S10: Best of 5 | T10: Match 5
A11: =I23 -> Omnix | B11: 46211 | E11: ='Tournament format'!I35 -> CYBERHERO | F11: ='Matches | CQ + Playoffs'!S93 -> 2 | G11: 0.8125 | H11: ='Matches | CQ + Playoffs'!T93 -> 0 | I11: =E5 -> HARD GRIND | J11: Best of 3 | K11: Match 6 | M11: =A24 -> Verso Time | N11: 0 | P11: 0 | R11: Grand-Final | S11: Best of 7 | T11: Match 6
A12: =I13 -> Aterion Esports | B12: 46277 | E12: ='Tournament format'!I39 -> Magic | F12: ='Matches | CQ + Playoffs'!S113 -> 0 | G12: 0.875 | H12: ='Matches | CQ + Playoffs'!T113 -> 2 | I12: =I6 -> Omnix | J12: Best of 3 | K12: Match 7
A13: =E12 -> Magic | B13: 46277 | E13: ='Tournament format'!I43 -> Aura Farmers | F13: ='Matches | CQ + Playoffs'!S133 -> 2 | G13: 0.9375 | H13: ='Matches | CQ + Playoffs'!T133 -> 1 | I13: =I7 -> Aterion Esports | J13: Best of 3 | K13: Match 8
A14: =I11 -> HARD GRIND | B14: 46277 | E14: 46190
A15: =I10 -> The Soulless Team | B15: 46277 | E15: Team 1 | F15: Score | G15: Time | H15: Score | I15: Team 2 | J15: Format | K15: Match
A16: =E7 -> INVISION | B16: 13-16 | E16: =E10 -> FORZE | F16: ='Matches | CQ + Playoffs'!AE73 -> 0 | G16: 0.75 | H16: ='Matches | CQ + Playoffs'!AF73 -> 2 | I16: =E11 -> CYBERHERO | J16: Best of 3 | K16: Match 9
A17: =E6 -> TSA White | B17: 13-16 | E17: =I12 -> Omnix | F17: ='Matches | CQ + Playoffs'!AE93 -> 2 | G17: 0.8125 | H17: ='Matches | CQ + Playoffs'!AF93 -> 0 | I17: =E13 -> Aura Farmers | J17: Best of 3 | K17: Match 10
A18: =I5 -> Dark Phoenix | B18: 13-16 | E18: ='Tournament format'!K33 -> Virtus.pro | F18: ='Matches | CQ + Playoffs'!AE113 -> 2 | G18: 0.875 | H18: ='Matches | CQ + Playoffs'!AF113 -> 0 | I18: =I16 -> CYBERHERO | J18: Best of 3 | K18: Match 11
A19: =I4 -> Suplex team | B19: 13-16 | E19: ='Tournament format'!K41 -> Team Yandex | F19: ='Matches | CQ + Playoffs'!AE133 -> 2 | G19: 0.9375 | H19: ='Matches | CQ + Playoffs'!AF133 -> 1 | I19: =I12 -> Omnix | J19: Best of 3 | K19: Match 12
E20: 46191
A21: Playoffs Teams | E21: Team 1 | F21: Score | G21: Time | H21: Score | I21: Team 2 | J21: Format | K21: Match
A22: Team name | B22: Position | E22: =E18 -> Virtus.pro | F22: ='Matches | CQ + Playoffs'!AQ83 -> 3 | G22: 0.66666667 | H22: ='Matches | CQ + Playoffs'!AR83 -> 2 | I22: =E19 -> Team Yandex | J22: Best of 5 | K22: Match 13
A23: ='Tournament format'!D59 -> Team Spirit | B23: 1 | E23: =E16 -> FORZE | F23: ='Matches | CQ + Playoffs'!AQ113 -> 3 | G23: 0.72916667 | H23: ='Matches | CQ + Playoffs'!AR113 -> 2 | I23: =I19 -> Omnix | J23: Best of 5 | K23: Match 14
A24: ='Tournament format'!D60 -> Verso Time | B24: 2 | E24: =I17 -> Aura Farmers | F24: ='Matches | CQ + Playoffs'!AQ143 -> 1 | G24: 0.79166667 | H24: ='Matches | CQ + Playoffs'!AR143 -> 3 | I24: =I18 -> CYBERHERO | J24: Best of 5 | K24: Match 15
A25: ='Tournament format'!D61 -> Virtus.pro | B25: 3 | E25: 46192
A26: ='Tournament format'!D62 -> FORZE | B26: 4 | E26: Team 1 | F26: Score | G26: Time | H26: Score | I26: Team 2 | J26: Format | K26: Match
E27: =E23 -> FORZE | F27: ='Matches | CQ + Playoffs'!BC83 -> 3 | G27: 0.66666667 | H27: ='Matches | CQ + Playoffs'!BD83 -> 2 | I27: =I24 -> CYBERHERO | J27: Best of 5 | K27: Match 16
A28: Closed Qualifier Teams | E28: =I22 -> Team Yandex | F28: ='Matches | CQ + Playoffs'!BC123 -> 2 | G28: 0.72916667 | H28: ='Matches | CQ + Playoffs'!BD123 -> 4 | I28: =E27 -> FORZE | J28: Best of 7 | K28: Match 17
A29: ='Tournament format'!D28 -> Team name | B29: ='Tournament format'!E28 -> Team standings | C29: ='Tournament format'!F28 -> Position
A30: ='Tournament format'!D29 -> Virtus.pro | B30: ='Tournament format'!E29 -> 3rd of Division 1 | C30: ='Tournament format'!F29 -> Tier 1
A31: ='Tournament format'!D30 -> Team Yandex | B31: ='Tournament format'!E30 -> 4th of Division 1 | C31: ='Tournament format'!F30 -> Tier 1
A32: ='Tournament format'!D31 -> FORZE | B32: ='Tournament format'!E31 -> 5th of Division 1 | C32: ='Tournament format'!F31 -> Tier 2
A33: ='Tournament format'!D32 -> CYBERHERO | B33: ='Tournament format'!E32 -> 6th of Division 1 | C33: ='Tournament format'!F32 -> Tier 2
A34: ='Tournament format'!D33 -> Magic | B34: ='Tournament format'!E33 -> 7th of Division 1 | C34: ='Tournament format'!F33 -> Tier 2
A35: ='Tournament format'!D34 -> Aura Farmers | B35: ='Tournament format'!E34 -> 8th of Division 1 | C35: ='Tournament format'!F34 -> Tier 2
A36: ='Tournament format'!D35 -> The Soulless Team | B36: ='Tournament format'!E35 -> 1st of Division 2 | C36: ='Tournament format'!F35 -> Tier 3
A37: ='Tournament format'!D36 -> HARD GRIND | B37: ='Tournament format'!E36 -> 2nd of Division 2 | C37: ='Tournament format'!F36 -> Tier 3
A38: ='Tournament format'!D37 -> TSA White | B38: ='Tournament format'!E37 -> 3rd of Division 2 | C38: ='Tournament format'!F37 -> Tier 3
A39: ='Tournament format'!D38 -> INVISION | B39: ='Tournament format'!E38 -> 4th of Division 2 | C39: ='Tournament format'!F38 -> Tier 3
A40: ='Tournament format'!D39 -> Aterion Esports | B40: ='Tournament format'!E39 -> 5th of Division 2 | C40: ='Tournament format'!F39 -> Tier 3
...

Sheet Matches | CQ + Playoffs
B1: CLOSED QUALIFIER BRACKET
B4: Match 1 | C4: ='Schedule | CQ + Playoffs'!J4 -> Best of 3 | G4: Match 5 | H4: ='Schedule | CQ + Playoffs'!J10 -> Best of 3
B5: ='Schedule | CQ + Playoffs'!E2 -> 46188 | C5: ='Schedule | CQ + Playoffs'!E4 -> The Soulless Team | D5: Winner | E5: Loser | G5: ='Schedule | CQ + Playoffs'!E8 -> 46189 | H5: ='Schedule | CQ + Playoffs'!E10 -> FORZE | I5: Winner | J5: Loser
B6: ='Schedule | CQ + Playoffs'!G4 -> 0.75 | C6: ='Schedule | CQ + Playoffs'!I4 -> Suplex team | E6: =A27 | G6: ='Schedule | CQ + Playoffs'!G10 -> 0.75 | H6: Winner of M1 | J6: =F27 | L6: Match 9 | M6: ='Schedule | CQ + Playoffs'!J16 -> Best of 3 | Q6: Match 11 | R6: ='Schedule | CQ + Playoffs'!J18 -> Best of 3
L7: ='Schedule | CQ + Playoffs'!E14 -> 46190 | M7: Winner of M5 | N7: Winner | O7: Loser | Q7: ='Schedule | CQ + Playoffs'!E14 -> 46190 | R7: 3rd of Division 1 | S7: Winner | T7: Loser
B8: Match 2 | C8: ='Schedule | CQ + Playoffs'!J5 -> Best of 3 | G8: Match 6 | H8: ='Schedule | CQ + Playoffs'!J11 -> Best of 3 | L8: ='Schedule | CQ + Playoffs'!G16 -> 0.75 | M8: Winner of M6 | O8: =K29 | Q8: ='Schedule | CQ + Playoffs'!G18 -> 0.875 | R8: Winner of M9
B9: ='Schedule | CQ + Playoffs'!E2 -> 46188 | C9: ='Schedule | CQ + Playoffs'!E5 -> HARD GRIND | D9: Winner | E9: Loser | G9: ='Schedule | CQ + Playoffs'!E8 -> 46189 | H9: ='Schedule | CQ + Playoffs'!E11 -> CYBERHERO | I9: Winner | J9: Loser
B10: ='Schedule | CQ + Playoffs'!G5 -> 0.8125 | C10: ='Schedule | CQ + Playoffs'!I5 -> Dark Phoenix | E10: =A32 | G10: ='Schedule | CQ + Playoffs'!G11 -> 0.8125 | H10: Winner of M2 | J10: =F32 | V10: Match 13 | W10: ='Schedule | CQ + Playoffs'!J22 -> Best of 5
V11: ='Schedule | CQ + Playoffs'!E20 -> 46191 | W11: Wineer of M11 | X11: Winner | Y11: Loser
B12: Match 3 | C12: ='Schedule | CQ + Playoffs'!J6 -> Best of 3 | G12: Match 7 | H12: ='Schedule | CQ + Playoffs'!J12 -> Best of 3 | V12: ='Schedule | CQ + Playoffs'!G22 -> 0.66666667 | W12: Winner of M12
B13: ='Schedule | CQ + Playoffs'!E2 -> 46188 | C13: ='Schedule | CQ + Playoffs'!E6 -> TSA White | D13: Winner | E13: Loser | G13: ='Schedule | CQ + Playoffs'!E8 -> 46189 | H13: ='Schedule | CQ + Playoffs'!E12 -> Magic | I13: Winner | J13: Loser
B14: ='Schedule | CQ + Playoffs'!G6 -> 0.875 | C14: ='Schedule | CQ + Playoffs'!I6 -> Omnix | G14: ='Schedule | CQ + Playoffs'!G12 -> 0.875 | H14: Winner of M3 | L14: Match 10 | M14: ='Schedule | CQ + Playoffs'!J17 -> Best of 3 | Q14: Match 12 | R14: ='Schedule | CQ + Playoffs'!J19 -> Best of 3
L15: ='Schedule | CQ + Playoffs'!E14 -> 46190 | M15: Winner of M7 | N15: Winner | O15: Loser | Q15: ='Schedule | CQ + Playoffs'!E14 -> 46190 | R15: 4th of Division 1 | S15: Winner | T15: Loser
B16: Match 4 | C16: ='Schedule | CQ + Playoffs'!J7 -> Best of 3 | G16: Match 8 | H16: ='Schedule | CQ + Playoffs'!J13 -> Best of 3 | L16: ='Schedule | CQ + Playoffs'!G17 -> 0.8125 | M16: Winner of M8 | Q16: ='Schedule | CQ + Playoffs'!G19 -> 0.9375 | R16: Winner of M10
B17: ='Schedule | CQ + Playoffs'!E2 -> 46188 | C17: ='Schedule | CQ + Playoffs'!E7 -> INVISION | D17: Winner | E17: Loser | G17: ='Schedule | CQ + Playoffs'!E8 -> 46189 | H17: ='Schedule | CQ + Playoffs'!E13 -> Aura Farmers | I17: Winner | J17: Loser
B18: ='Schedule | CQ + Playoffs'!G7 -> 0.9375 | C18: ='Schedule | CQ + Playoffs'!I7 -> Aterion Esports | G18: ='Schedule | CQ + Playoffs'!G13 -> 0.9375 | H18: Winner of M4
Q23: Match 14 | R23: ='Schedule | CQ + Playoffs'!J23 -> Best of 5
Q24: ='Schedule | CQ + Playoffs'!E20 -> 46191 | R24: Loser of M12 | S24: Winner | T24: Loser
Q25: ='Schedule | CQ + Playoffs'!G23 -> 0.72916667 | R25: Loser of M9 | V25: Match 16 | W25: ='Schedule | CQ + Playoffs'!J27 -> Best of 5 | AA25: Match 17 | AB25: ='Schedule | CQ + Playoffs'!J28 -> Best of 7
V26: ='Schedule | CQ + Playoffs'!E25 -> 46192 | W26: Winner of M14 | X26: Winner | Y26: Loser | AA26: ='Schedule | CQ + Playoffs'!E25 -> 46192 | AB26: Loser of M13 | AC26: Winner | AD26: Loser
Q27: Match 15 | R27: ='Schedule | CQ + Playoffs'!J24 -> Best of 5 | V27: ='Schedule | CQ + Playoffs'!G27 -> 0.66666667 | W27: Winner of M15 | AA27: ='Schedule | CQ + Playoffs'!G28 -> 0.72916667 | AB27: Winner of M16 | AD27: =Z187
Q28: ='Schedule | CQ + Playoffs'!E20 -> 46191 | R28: Loser of M11 | S28: Winner | T28: Loser
Q29: ='Schedule | CQ + Playoffs'!G24 -> 0.79166667 | R29: Loser of M10
B32: FINALS BRACKET
B35: Match 1 | C35: ='Schedule | CQ + Playoffs'!S4 -> Best of 5
B36: ='Schedule | CQ + Playoffs'!M2 -> 46194 | C36: ='Schedule | CQ + Playoffs'!M4 -> Team Spirit | D36: Winner | E36: Loser
B37: ='Schedule | CQ + Playoffs'!O4 -> 0.625 | E37: =A59 | G37: Match 3 | H37: ='Schedule | CQ + Playoffs'!S6 -> Best of 5 | Q37: Match 6 | R37: ='Schedule | CQ + Playoffs'!S11 -> Best of 7
G38: ='Schedule | CQ + Playoffs'!M2 -> 46194 | I38: Winner | J38: Loser | Q38: ='Schedule | CQ + Playoffs'!M8 -> 46256 | S38: Winner | T38: Loser
B39: Match 2 | C39: ='Schedule | CQ + Playoffs'!S5 -> Best of 5 | G39: ='Schedule | CQ + Playoffs'!O6 -> 0.75 | J39: =F61 | Q39: ='Schedule | CQ + Playoffs'!O11
B40: ='Schedule | CQ + Playoffs'!M2 -> 46194 | C40: ='Schedule | CQ + Playoffs'!M5 -> Verso Time | D40: Winner | E40: Loser
B41: ='Schedule | CQ + Playoffs'!O5 -> 0.6875 | E41: =A63
G46: Match 4 | H46: ='Schedule | CQ + Playoffs'!S7 -> Best of 5 | L46: Match 5 | M46: ='Schedule | CQ + Playoffs'!S10 -> Best of 5
G47: ='Schedule | CQ + Playoffs'!M2 -> 46194 | I47: Winner | J47: Loser | L47: ='Schedule | CQ + Playoffs'!M8 -> 46256 | N47: Winner | O47: Loser
G48: ='Schedule | CQ + Playoffs'!O7 -> 0.8125 | J48: =F68 -> Blue | L48: ='Schedule | CQ + Playoffs'!O10
B51: MATCHES RESULTS
G53: ='Schedule | CQ + Playoffs'!E2 -> 46188 | S53: ='Schedule | CQ + Playoffs'!E8 -> 46189 | AE53: ='Schedule | CQ + Playoffs'!E14 -> 46190 | AQ53: ='Schedule | CQ + Playoffs'!E20 -> 46191 | BC53: ='Schedule | CQ + Playoffs'!E25 -> 46192 | BO53: ='Schedule | CQ + Playoffs'!M2 -> 46194 | CA53: ='Schedule | CQ + Playoffs'!M8 -> 46256
B55: ='Schedule | CQ + Playoffs'!E4 -> The Soulless Team | G55: ='Schedule | CQ + Playoffs'!K4 -> Match 1 | I55: ='Schedule | CQ + Playoffs'!I4 -> Suplex team | N55: ='Schedule | CQ + Playoffs'!E10 -> FORZE | S55: ='Schedule | CQ + Playoffs'!K10 -> Match 5 | U55: ='Schedule | CQ + Playoffs'!I10 -> The Soulless Team | Z55: ='Schedule | CQ + Playoffs'!E16 -> FORZE | AE55: ='Schedule | CQ + Playoffs'!AJ4 | AG55: ='Schedule | CQ + Playoffs'!I16 -> CYBERHERO | AL55: Virtus.pro | AQ55: ='Schedule | CQ + Playoffs'!AV4 | AS55: Team Yandex | AX55: FORZE | BC55: ='Schedule | CQ + Playoffs'!BH4 | BE55: CYBERHERO | BJ55: ='Schedule | CQ + Playoffs'!M4 -> Team Spirit | BO55: ='Schedule | CQ + Playoffs'!T4 -> Match 1 | BQ55: ='Schedule | CQ + Playoffs'!Q4 -> FORZE | BV55: ='Schedule | CQ + Playoffs'!BN4 | CA55: ='Schedule | CQ + Playoffs'!BT4 | CC55: ='Schedule | CQ + Playoffs'!BR4
B57: Map | C57: Ban Team 1 | D57: Players Team 1 | E57: Pick Team 1 | F57: Side | G57: Score | I57: Side | J57: Pick Team 2 | K57: Players Team 2 | L57: Ban Team 2 | N57: Map | O57: Ban Team 1 | P57: Players Team 1 | Q57: Pick Team 1 | R57: Side | S57: Score | U57: Side | V57: Pick Team 2 | W57: Players Team 2 | X57: Ban Team 2 | Z57: Map | AA57: Ban Team 1 | AB57: Players Team 1 | AC57: Pick Team 1 | AD57: Side | AE57: Score | AG57: Side | AH57: Pick Team 2 | AI57: Players Team 2 | AJ57: Ban Team 2 | AL57: Map | AM57: Ban Team 1 | AN57: Players Team 1 | AO57: Pick Team 1 | AP57: Side | AQ57: Score | AS57: Side | AT57: Pick Team 2 | AU57: Players Team 2 | AV57: Ban Team 2 | AX57: Map | AY57: Ban Team 1 | AZ57: Players Team 1 | BA57: Pick Team 1 | BB57: Side | BC57: Score | BE57: Side | BF57: Pick Team 2 | BG57: Players Team 2 | BH57: Ban Team 2 | BJ57: Map | BK57: Ban Team 1 | BL57: Players Team 1 | BM57: Pick Team 1 | BN57: Side | BO57: Score | BQ57: Side | BR57: Pick Team 2 | BS57: Players Team 2 | BT57: Ban Team 2 | BV57: Map | BW57: Ban Team 1 | BX57: Players Team 1 | BY57: Pick Team 1 | BZ57: Side | CA57: Score | CC57: Side | CD57: Pick Team 2 | CE57: Players Team 2 | CF57: Ban Team 2
B58: 1 | C58: Phoveus | D58: Hamster | E58: Harley | F58: Blue | G58: W | H58: L | I58: Red | J58: Hilda | K58: Quko_QQ | L58: Marcel | N58: 1 | O58: Guinevere | P58: Maniak | Q58: Freya | R58: Blue | S58: W | T58: L | U58: Red | V58: Harith | W58: Hamster | X58: Gusion | Z58: 1 | AA58: Guinevere | AB58: Repa | AC58: Baxia | AD58: Blue | AE58: L | AF58: W | AG58: Red | AH58: Atlas | AI58: Super Yoshi | AJ58: Fanny | AL58: 1 | AM58: Phoveus | AN58: Marl | AO58: Harley | AP58: Blue | AQ58: W | AR58: L | AS58: Red | AT58: Harith | AU58: Dont | AV58: Baxia | AX58: 1 | AY58: Yve | AZ58: ShowMe | BA58: Marcel | BB58: Blue | BC58: W | BD58: L | BE58: Red | BF58: Harith | BG58: Ptenchik | BH58: Fanny | BJ58: 1 | BK58: Yve | BL58: Kidbomba | BM58: Paquito | BN58: Blue | BO58: W | BP58: L | BQ58: Red | BR58: Marcel | BS58: ShowMe | BT58: Zhuxin | BV58: 1
C59: Leomord | D59: Darl | E59: Yve | J59: Paquito | K59: honored one | L59: Zhuxin | O59: Baxia | P59: Repa | Q59: Fanny | V59: Gord | W59: Darl | X59: Helcurt | AA59: Terizla | AB59: Avilio. | AC59: Harith | AH59: Yve | AI59: Solitude | AJ59: Marcel | AM59: Guinevere | AN59: Bober | AO59: Valentina | AT59: Freya | AU59: gxn1us | AV59: Zhuxin | AY59: Phoveus | AZ59: Maniak | BA59: Benedetta | BF59: Paquito | BG59: Marbon | BH59: Freya | BK59: Phoveus | BL59: zaur egoist | BM59: Akai | BR59: Baxia | BS59: Repa | BT59: Freya
...

Sheet Teams | CQ + Playoffs
A1: Teams | CQ + Playoffs
A2: Captain | B2: Role | C2: Nickname | D2: Pronounce | E2: Captain | F2: Role | G2: Nickname | H2: Pronounce | I2: Captain | J2: Role | K2: Nickname | L2: Pronounce
A3: ='Tournament format'!D59 -> Team Spirit | E3: ='Tournament format'!D60 -> Verso Time | I3: ='Tournament format'!D29 -> Virtus.pro
A4: Captain | B4: Mid | C4: SunsetLover | D4: сАнсет лАвер | E4: Captain | F4: Gold | G4: versoMarch | H4: мАрч | I4: Captain | J4: Gold | K4: superegorka | L4: сУперегОрка
A5: Player | B5: Roam | C5: SAWO | D5: сАво | E5: Player | F5: Roam | G5: versoAFK | H5: АфЭкА | I5: Player | J5: Roam | K5: Nagib | L5: нагИб
A6: Player | B6: Exp | C6: Kidbomba | D6: кИд бОмба | E6: Player | F6: Exp | G6: versoCastle | H6: кАсл | I6: Player | J6: Exp | K6: BadKot | L6: бЭдкот
A7: Player | B7: Jungler | C7: zaur egoist | D7: заУр эгоИст | E7: Player | F7: Jungler | G7: versoYustinian | H7: Юстиниан | I7: Player | J7: Jungler | K7: Marl | L7: мАрл
A8: Player | B8: Gold | C8: Hiko | D8: хИко | E8: Player | F8: Mid | G8: versoKodjikk | H8: кОджик | I8: Player | J8: Mid | K8: Bober | L8: бобЁр
A9: Substitute | B9: Multirole | C9: HarmonySoul | D9: хАрмони сОул | E9: Substitute | F9: Jungler | G9: versoNovel | H9: новЕл | I9: Substitute | J9: Roam | K9: Fangor | L9: фангОр
A10: Substitute | C10: Coldstar | D10: колдстАр | E10: Substitute | I10: Substitute | J10: Multirole | K10: Kerrigan | L10: кЕрриган
A11: Coach | C11: Ooops | D11: Упс | E11: Coach | G11: Ospreay | H11: оспрЕй | I11: Coach | K11: flysolo | L11: флАйсОло
A12: Manager | C12: euphoria | D12: эйфорИя | E12: Manager | G12: Parma | H12: пАрма | I12: Manager
A13: ='Tournament format'!D30 -> Team Yandex | E13: ='Tournament format'!D31 -> FORZE | I13: ='Tournament format'!D32 -> CYBERHERO
A14: Captain | B14: Gold | C14: Dont | D14: дОнт | E14: Captain | F14: Exp | G14: Maniak | H14: Маньяк | I14: Captain | J14: Roam | K14: Super Yoshi | L14: сУпер ЙОши
A15: Player | B15: Roam | C15: Loveeeely | D15: лАвли | E15: Player | F15: Jungler | G15: Repa | H15: рЕпа | I15: Player | J15: Jungler | K15: Hadess | L15: хЕйдэс/хЕйдис
A16: Player | B16: Jungler | C16: Mashiro | D16: мАширо | E16: Player | F16: Roam | G16: ShowMe | H16: шОуми | I16: Player | J16: Gold | K16: Ptenchik | L16: птЕнчик
A17: Player | B17: Mid | C17: Troublemaker | D17: трАблмЕйкер | E17: Player | F17: Gold | G17: Avilio. | H17: Авилио | I17: Player | J17: Mid | K17: Solitude | L17: солитьЮд
A18: Player | B18: Exp | C18: gxn1us | D18: гЕниус | E18: Player | F18: Mid | G18: Reaper | H18: рИпер | I18: Player | J18: Exp | K18: Marbon | L18: марбОн
A19: Substitute | B19: Multirole | C19: EvilKing | D19: Эвил-кИнг | E19: Substitute | I19: Substitute | J19: Multirole | K19: Yui' | L19: Юи
A20: Substitute | E20: Substitute | I20: Substitute | J20: Roam | K20: Q1let | L20: килЕт
A21: Coach | C21: Badgalseph | E21: Coach | I21: Coach | K21: Coach Cody | L21: кОди
A22: Manager | C22: Filip_Filipsov | D22: Филип Филипсов | E22: Manager | F22: Roam | G22: KinDer | H22: кИндер | I22: Manager | K22: Zefirka | L22: зефИрка
A23: ='Tournament format'!D33 -> Magic | E23: ='Tournament format'!D34 -> Aura Farmers | I23: ='Tournament format'!D35 -> The Soulless Team
A24: Captain | B24: Gold | C24: ilovee | D24: айлАв | E24: Captain | F24: Roam | G24: NEIL | H24: нЭйл | I24: Captain | J24: Gold | K24: Hamster | L24: хАмстер
A25: Player | B25: Exp | C25: Solist | D25: солИст | E25: Player | F25: Exp | G25: Summer | H25: сАмэр | I25: Player | J25: Mid | K25: Darl | L25: дАрл
A26: Player | B26: Roam | C26: KOKUSHIBO | D26: кокушИбо | E26: Player | F26: Jungler | G26: Inneskite | H26: инэскАйт | I26: Player | J26: Exp | K26: Shiba. | L26: Шиба
A27: Player | B27: Jungler | C27: shelianer | D27: шелианЕр | E27: Player | F27: Gold | G27: Baratrum | H27: баратрУм | I27: Player | J27: Roam | K27: Wojak | L27: вожАк
A28: Player | B28: Mid | C28: shvedskii | D28: швЕдский | E28: Player | F28: Mid | G28: Twizy | H28: твИзи | I28: Player | J28: Jungler | K28: Bеrt | L28: бЕрт
A29: Substitute | B29: Multirole | C29: Zwihsk | D29: звИск | E29: Substitute | I29: Substitute
A30: Substitute | B30: Jungler | C30: VillainTzy | D30: вилАйн | E30: Substitute | I30: Substitute
A31: Coach | C31: denaliens | D31: денАлиенс | E31: Coach | G31: Deus | H31: дЭус | I31: Coach | J31: Multirole | K31: Rikki Tikki Tavi | L31: Рики
A32: Manager | C32: Yago | D32: ягО | E32: Manager | G32: Gulliver | H32: гуливЕр | I32: Manager
A33: ='Tournament format'!D36 -> HARD GRIND | E33: ='Tournament format'!D37 -> TSA White | I33: ='Tournament format'!D38 -> INVISION
A34: Captain | B34: Roam | C34: BUBLIKKK X ROAM | D34: бУблик х роУм | E34: Captain | F34: Roam | G34: Ligyshka | H34: лягУшка | I34: Captain | J34: Roam | K34: INSAAANE | L34: инсЕйн
A35: Player | B35: Gold | C35: cпокойствие | D35: спокойствие | E35: Player | F35: Exp | G35: MatadQr | H35: матадОр | I35: Player | J35: Jungler | K35: Kulik | L35: кулик
A36: Player | B36: Exp | C36: Kang Lim | D36: Канг Лим | E36: Player | F36: Jungler | G36: FIRSTAAAB | H36: фёрстАб | I36: Player | J36: Exp | K36: Dzhuki | L36: джУки
A37: Player | B37: Jungler | C37: izma•Eliminated. | D37: Измайлов | E37: Player | F37: Gold | G37: Neyronoff | H37: нейрОнов | I37: Player | J37: Gold | K37: MKIRI! | L37: мкИри
A38: Player | B38: Mid | C38: Vermishelius | D38: вермишЕлиус | E38: Player | F38: Mid | G38: keks | H38: кЕкс | I38: Player | J38: Mid | K38: Bimoo | L38: бИмо
A39: Substitute | B39: Jungler | C39: bloha poleteli. | D39: блоха полетели | E39: Substitute | I39: Substitute | J39: Roam | K39: Flash | L39: флеш
A40: Substitute | E40: Substitute | I40: Substitute
...

Sheet Schedule | 1 Division
E1: Schedule | 1 Division
A2: Team № | B2: Team | E2: Round 1 | K2: Round 2
A3: 1 | B3: Aura Farmers | E3: 46133 | K3: 46154
A4: 2 | B4: Magic | E4: Team 1 | F4: Score | G4: Time | H4: Score | I4: Team 2 | J4: Match | K4: Team 1 | L4: Score | M4: Time | N4: Score | O4: Team 2 | P4: Match
A5: 3 | B5: Virtus.pro | E5: =$B$3 -> Aura Farmers | F5: ='Matches | 1 Division'!D15 -> 0 | G5: 0.75 | H5: ='Matches | 1 Division'!E15 -> 2 | I5: =$B$6 -> Team Spirit | J5: Match 1 | K5: =$B$6 -> Team Spirit | L5: ='Matches | 1 Division'!D43 -> 2 | M5: 0.75 | N5: ='Matches | 1 Division'!E43 -> 0 | O5: =$B$4 -> Magic | P5: Match 29
A6: 4 | B6: Team Spirit | E6: =$B$10 -> Verso Time | F6: ='Matches | 1 Division'!D16 -> 2 | G6: 0.8125 | H6: ='Matches | 1 Division'!E16 -> 0 | I6: =$B$7 -> FORZE | J6: Match 2 | K6: =$B$9 -> Team Yandex | L6: ='Matches | 1 Division'!D44 -> 2 | M6: 0.8125 | N6: ='Matches | 1 Division'!E44 -> 1 | O6: =$B$7 -> FORZE | P6: Match 30
A7: 5 | B7: FORZE | E7: =$B$8 -> CYBERHERO | F7: ='Matches | 1 Division'!D17 -> 2 | G7: 0.875 | H7: ='Matches | 1 Division'!E17 -> 0 | I7: =$B$9 -> Team Yandex | J7: Match 3 | K7: =$B$10 -> Verso Time | L7: ='Matches | 1 Division'!D45 -> 2 | M7: 0.875 | N7: ='Matches | 1 Division'!E45 -> 0 | O7: =$B$8 -> CYBERHERO | P7: Match 31
A8: 6 | B8: CYBERHERO | E8: =$B$4 -> Magic | F8: ='Matches | 1 Division'!D18 -> 1 | G8: 0.9375 | H8: ='Matches | 1 Division'!E18 -> 2 | I8: =$B$5 -> Virtus.pro | J8: Match 4 | K8: =$B$5 -> Virtus.pro | L8: ='Matches | 1 Division'!D46 -> 2 | M8: 0.9375 | N8: ='Matches | 1 Division'!E46 -> 0 | O8: =$B$3 -> Aura Farmers | P8: Match 32
A9: 7 | B9: Team Yandex | E9: 46134 | K9: 46155
A10: 8 | B10: Verso Time | E10: Team 1 | F10: Score | G10: Time | H10: Score | I10: Team 2 | J10: Match | K10: Team 1 | L10: Score | M10: Time | N10: Score | O10: Team 2 | P10: Match
E11: =$B$6 -> Team Spirit | F11: ='Matches | 1 Division'!D19 -> 2 | G11: 0.75 | H11: ='Matches | 1 Division'!E19 -> 0 | I11: =$B$8 -> CYBERHERO | J11: Match 5 | K11: =$B$9 -> Team Yandex | L11: ='Matches | 1 Division'!D47 -> 1 | M11: 0.75 | N11: ='Matches | 1 Division'!E47 -> 2 | O11: =$B$5 -> Virtus.pro | P11: Match 33
E12: =$B$5 -> Virtus.pro | F12: ='Matches | 1 Division'!D20 -> 2 | G12: 0.8125 | H12: ='Matches | 1 Division'!E20 -> 1 | I12: =$B$7 -> FORZE | J12: Match 6 | K12: =$B$4 -> Magic | L12: ='Matches | 1 Division'!D48 -> 0 | M12: 0.8125 | N12: ='Matches | 1 Division'!E48 -> 2 | O12: =$B$7 -> FORZE | P12: Match 34
E13: =$B$4 -> Magic | F13: ='Matches | 1 Division'!D21 -> 0 | G13: 0.875 | H13: ='Matches | 1 Division'!E21 -> 2 | I13: =$B$10 -> Verso Time | J13: Match 7 | K13: =$B$10 -> Verso Time | L13: ='Matches | 1 Division'!D49 -> 1 | M13: 0.875 | N13: ='Matches | 1 Division'!E49 -> 2 | O13: =$B$6 -> Team Spirit | P13: Match 35
A14: Place | B14: Team | C14: Progression | E14: =$B$9 -> Team Yandex | F14: ='Matches | 1 Division'!D22 -> 2 | G14: 0.9375 | H14: ='Matches | 1 Division'!E22 -> 0 | I14: =$B$3 -> Aura Farmers | J14: Match 8 | K14: =$B$3 -> Aura Farmers | L14: ='Matches | 1 Division'!D50 -> 0 | M14: 0.9375 | N14: ='Matches | 1 Division'!E50 -> 2 | O14: =$B$8 -> CYBERHERO | P14: Match 36
A15: 1 | B15: =B6 -> Team Spirit | C15: To final stage | E15: 46140 | K15: 46168
A16: 2 | B16: =B10 -> Verso Time | C16: To final stage | E16: Team 1 | F16: Score | G16: Time | H16: Score | I16: Team 2 | J16: Match | K16: Team 1 | L16: Score | M16: Time | N16: Score | O16: Team 2 | P16: Match
A17: 3 | B17: =B5 -> Virtus.pro | C17: Match 11 of CQ | E17: =$B$5 -> Virtus.pro | F17: ='Matches | 1 Division'!D23 -> 2 | G17: 0.75 | H17: ='Matches | 1 Division'!E23 -> 1 | I17: =$B$9 -> Team Yandex | J17: Match 9 | K17: =$B$8 -> CYBERHERO | L17: ='Matches | 1 Division'!D51 -> 0 | M17: 0.75 | N17: ='Matches | 1 Division'!E51 -> 2 | O17: =$B$6 -> Team Spirit | P17: Match 37
A18: 4 | B18: =B9 -> Team Yandex | C18: Match 12 of CQ | E18: =$B$6 -> Team Spirit | F18: ='Matches | 1 Division'!D24 -> 2 | G18: 0.8125 | H18: ='Matches | 1 Division'!E24 -> 1 | I18: =$B$10 -> Verso Time | J18: Match 10 | K18: =$B$3 -> Aura Farmers | L18: ='Matches | 1 Division'!D52 -> 0 | M18: 0.8125 | N18: ='Matches | 1 Division'!E52 -> 2 | O18: =$B$9 -> Team Yandex | P18: Match 38
A19: 5 | B19: =B7 -> FORZE | C19: Match 5 of CQ | E19: =$B$8 -> CYBERHERO | F19: ='Matches | 1 Division'!D25 -> 2 | G19: 0.875 | H19: ='Matches | 1 Division'!E25 -> 1 | I19: =$B$3 -> Aura Farmers | J19: Match 11 | K19: =$B$7 -> FORZE | L19: ='Matches | 1 Division'!D53 -> 1 | M19: 0.875 | N19: ='Matches | 1 Division'!E53 -> 2 | O19: =$B$5 -> Virtus.pro | P19: Match 39
A20: 6 | B20: =B8 -> CYBERHERO | C20: Match 6 of CQ | E20: =$B$7 -> FORZE | F20: ='Matches | 1 Division'!D26 -> 2 | G20: 0.9375 | H20: ='Matches | 1 Division'!E26 -> 1 | I20: =$B$4 -> Magic | J20: Match 12 | K20: =$B$10 -> Verso Time | L20: ='Matches | 1 Division'!D54 -> 2 | M20: 0.9375 | N20: ='Matches | 1 Division'!E54 -> 0 | O20: =$B$4 -> Magic | P20: Match 40
A21: 7 | B21: =B4 -> Magic | C21: Match 7 of CQ | E21: 46141 | K21: 46169
A22: 8 | B22: =B3 -> Aura Farmers | C22: Match 8 of CQ | E22: Team 1 | F22: Score | G22: Time | H22: Score | I22: Team 2 | J22: Match | K22: Team 1 | L22: Score | M22: Time | N22: Score | O22: Team 2 | P22: Match
E23: =$B$7 -> FORZE | F23: ='Matches | 1 Division'!D27 -> 2 | G23: 0.75 | H23: ='Matches | 1 Division'!E27 -> 1 | I23: =$B$3 -> Aura Farmers | J23: Match 13 | K23: =$B$5 -> Virtus.pro | L23: ='Matches | 1 Division'!D55 -> 1 | M23: 0.75 | N23: ='Matches | 1 Division'!E55 -> 2 | O23: =$B$10 -> Verso Time | P23: Match 41
E24: =$B$6 -> Team Spirit | F24: ='Matches | 1 Division'!D28 -> 2 | G24: 0.8125 | H24: ='Matches | 1 Division'!E28 -> 0 | I24: =$B$9 -> Team Yandex | J24: Match 14 | K24: =$B$3 -> Aura Farmers | L24: ='Matches | 1 Division'!D56 -> 1 | M24: 0.8125 | N24: ='Matches | 1 Division'!E56 -> 2 | O24: =$B$7 -> FORZE | P24: Match 42
E25: =$B$8 -> CYBERHERO | F25: ='Matches | 1 Division'!D29 -> 2 | G25: 0.875 | H25: ='Matches | 1 Division'!E29 -> 0 | I25: =$B$4 -> Magic | J25: Match 15 | K25: =$B$4 -> Magic | L25: ='Matches | 1 Division'!D57 -> 2 | M25: 0.875 | N25: ='Matches | 1 Division'!E57 -> 0 | O25: =$B$8 -> CYBERHERO | P25: Match 43
E26: =$B$10 -> Verso Time | F26: ='Matches | 1 Division'!D30 -> 2 | G26: 0.9375 | H26: ='Matches | 1 Division'!E30 -> 0 | I26: =$B$5 -> Virtus.pro | J26: Match 16 | K26: =$B$9 -> Team Yandex | L26: ='Matches | 1 Division'!D58 -> 2 | M26: 0.9375 | N26: ='Matches | 1 Division'!E58 -> 1 | O26: =$B$6 -> Team Spirit | P26: Match 44
E27: 46147 | K27: 46170
E28: Team 1 | F28: Score | G28: Time | H28: Score | I28: Team 2 | J28: Match | K28: Team 1 | L28: Score | M28: Time | N28: Score | O28: Team 2 | P28: Match
E29: =$B$7 -> FORZE | F29: ='Matches | 1 Division'!D31 -> 2 | G29: 0.75 | H29: ='Matches | 1 Division'!E31 -> 0 | I29: =$B$9 -> Team Yandex | J29: Match 17 | K29: =$B$10 -> Verso Time | L29: ='Matches | 1 Division'!D59 -> 2 | M29: 0.75 | N29: ='Matches | 1 Division'!E59 -> 0 | O29: =$B$3 -> Aura Farmers | P29: Match 45
E30: =$B$8 -> CYBERHERO | F30: ='Matches | 1 Division'!D32 -> 0 | G30: 0.8125 | H30: ='Matches | 1 Division'!E32 -> 2 | I30: =$B$10 -> Verso Time | J30: Match 18 | K30: =$B$9 -> Team Yandex | L30: ='Matches | 1 Division'!D60 -> 2 | M30: 0.8125 | N30: ='Matches | 1 Division'!E60 -> 0 | O30: =$B$4 -> Magic | P30: Match 46
E31: =$B$3 -> Aura Farmers | F31: ='Matches | 1 Division'!D33 -> 2 | G31: 0.875 | H31: ='Matches | 1 Division'!E33 -> 1 | I31: =$B$5 -> Virtus.pro | J31: Match 19 | K31: =$B$8 -> CYBERHERO | L31: ='Matches | 1 Division'!D61 -> 0 | M31: 0.875 | N31: ='Matches | 1 Division'!E61 -> 2 | O31: =$B$5 -> Virtus.pro | P31: Match 47
E32: =$B$4 -> Magic | F32: ='Matches | 1 Division'!D34 -> 0 | G32: 0.9375 | H32: ='Matches | 1 Division'!E34 -> 2 | I32: =$B$6 -> Team Spirit | J32: Match 20 | K32: =$B$7 -> FORZE | L32: ='Matches | 1 Division'!D62 -> 0 | M32: 0.9375 | N32: ='Matches | 1 Division'!E62 -> 2 | O32: =$B$6 -> Team Spirit | P32: Match 48
E33: 46148 | K33: 46175
E34: Team 1 | F34: Score | G34: Time | H34: Score | I34: Team 2 | J34: Match | K34: Team 1 | L34: Score | M34: Time | N34: Score | O34: Team 2 | P34: Match
E35: =$B$3 -> Aura Farmers | F35: ='Matches | 1 Division'!D35 -> 0 | G35: 0.75 | H35: ='Matches | 1 Division'!E35 -> 2 | I35: =$B$10 -> Verso Time | J35: Match 21 | K35: =$B$7 -> FORZE | L35: ='Matches | 1 Division'!D63 -> 0 | M35: 0.75 | N35: ='Matches | 1 Division'!E63 -> 2 | O35: =$B$10 -> Verso Time | P35: Match 49
E36: =$B$4 -> Magic | F36: ='Matches | 1 Division'!D36 -> 0 | G36: 0.8125 | H36: ='Matches | 1 Division'!E36 -> 2 | I36: =$B$9 -> Team Yandex | J36: Match 22 | K36: =$B$5 -> Virtus.pro | L36: ='Matches | 1 Division'!D64 -> 2 | M36: 0.8125 | N36: ='Matches | 1 Division'!E64 -> 0 | O36: =$B$4 -> Magic | P36: Match 50
E37: =$B$5 -> Virtus.pro | F37: ='Matches | 1 Division'!D37 -> 2 | G37: 0.875 | H37: ='Matches | 1 Division'!E37 -> 0 | I37: =$B$8 -> CYBERHERO | J37: Match 23 | K37: =$B$6 -> Team Spirit | L37: ='Matches | 1 Division'!D65 -> 2 | M37: 0.875 | N37: ='Matches | 1 Division'!E65 -> 0 | O37: =$B$3 -> Aura Farmers | P37: Match 51
E38: =$B$6 -> Team Spirit | F38: ='Matches | 1 Division'!D38 -> 2 | G38: 0.9375 | H38: ='Matches | 1 Division'!E38 -> 0 | I38: =$B$7 -> FORZE | J38: Match 24 | K38: =$B$9 -> Team Yandex | L38: ='Matches | 1 Division'!D66 -> 2 | M38: 0.9375 | N38: ='Matches | 1 Division'!E66 -> 0 | O38: =$B$8 -> CYBERHERO | P38: Match 52
E39: 46149 | K39: 46176
E40: Team 1 | F40: Score | G40: Time | H40: Score | I40: Team 2 | J40: Match | K40: Team 1 | L40: Score | M40: Time | N40: Score | O40: Team 2 | P40: Match
...

Sheet Matches | 1 Division
A1: Matches | 1 Division | R1: ='Schedule | 1 Division'!E2 -> Round 1 | AD1: ='Schedule | 1 Division'!E2 -> Round 1 | AP1: ='Schedule | 1 Division'!E2 -> Round 1 | BB1: ='Schedule | 1 Division'!E2 -> Round 1 | BN1: ='Schedule | 1 Division'!E2 -> Round 1 | BZ1: ='Schedule | 1 Division'!E2 -> Round 1 | CL1: ='Schedule | 1 Division'!E2 -> Round 1 | CX1: ='Schedule | 1 Division'!K2 -> Round 2 | DJ1: ='Schedule | 1 Division'!K2 -> Round 2 | DV1: ='Schedule | 1 Division'!K2 -> Round 2 | EH1: ='Schedule | 1 Division'!K2 -> Round 2 | ET1: ='Schedule | 1 Division'!K2 -> Round 2 | FF1: ='Schedule | 1 Division'!K2 -> Round 2 | FR1: ='Schedule | 1 Division'!K2 -> Round 2
R2: ='Schedule | 1 Division'!E3 -> 46133 | AD2: ='Schedule | 1 Division'!E9 -> 46134 | AP2: ='Schedule | 1 Division'!E15 -> 46140 | BB2: ='Schedule | 1 Division'!E21 -> 46141 | BN2: ='Schedule | 1 Division'!E27 -> 46147 | BZ2: ='Schedule | 1 Division'!E33 -> 46148 | CL2: ='Schedule | 1 Division'!E39 -> 46149 | CX2: ='Schedule | 1 Division'!K3 -> 46154 | DJ2: ='Schedule | 1 Division'!K9 -> 46155 | DV2: ='Schedule | 1 Division'!K15 -> 46168 | EH2: ='Schedule | 1 Division'!K21 -> 46169 | ET2: ='Schedule | 1 Division'!K27 -> 46170 | FF2: ='Schedule | 1 Division'!K33 -> 46175 | FR2: ='Schedule | 1 Division'!K39 -> 46176
A3: Current Place | B3: Team | C3: Total score | D3: Totat Matches | E3: Match winner 2:0 | F3: Match winner 2:1 | G3: Match loser 1:2 | H3: Match loser 0:2 | I3: Maps won | J3: Maps lose | K3: Maps Diff | M3: ='Schedule | 1 Division'!E5 -> Aura Farmers | R3: ='Schedule | 1 Division'!J5 -> Match 1 | T3: ='Schedule | 1 Division'!I5 -> Team Spirit | Y3: ='Schedule | 1 Division'!E11 -> Team Spirit | AD3: ='Schedule | 1 Division'!J11 -> Match 5 | AF3: ='Schedule | 1 Division'!I11 -> CYBERHERO | AK3: ='Schedule | 1 Division'!E17 -> Virtus.pro | AP3: ='Schedule | 1 Division'!J17 -> Match 9 | AR3: ='Schedule | 1 Division'!I17 -> Team Yandex | AW3: ='Schedule | 1 Division'!E23 -> FORZE | BB3: ='Schedule | 1 Division'!J23 -> Match 13 | BD3: ='Schedule | 1 Division'!I23 -> Aura Farmers | BI3: ='Schedule | 1 Division'!E29 -> FORZE | BN3: ='Schedule | 1 Division'!J29 -> Match 17 | BP3: ='Schedule | 1 Division'!I29 -> Team Yandex | BU3: ='Schedule | 1 Division'!E35 -> Aura Farmers | BZ3: ='Schedule | 1 Division'!J35 -> Match 21 | CB3: ='Schedule | 1 Division'!I35 -> Verso Time | CG3: ='Schedule | 1 Division'!E41 -> Team Yandex | CL3: ='Schedule | 1 Division'!J41 -> Match 25 | CN3: ='Schedule | 1 Division'!I41 -> Verso Time | CS3: ='Schedule | 1 Division'!K5 -> Team Spirit | CX3: ='Schedule | 1 Division'!P5 -> Match 29 | CZ3: ='Schedule | 1 Division'!O5 -> Magic | DE3: ='Schedule | 1 Division'!K11 -> Team Yandex | DJ3: ='Schedule | 1 Division'!P11 -> Match 33 | DL3: ='Schedule | 1 Division'!O11 -> Virtus.pro | DQ3: ='Schedule | 1 Division'!K17 -> CYBERHERO | DV3: ='Schedule | 1 Division'!P17 -> Match 37 | DX3: ='Schedule | 1 Division'!O17 -> Team Spirit | EC3: ='Schedule | 1 Division'!K23 -> Virtus.pro | EH3: ='Schedule | 1 Division'!P23 -> Match 41 | EJ3: ='Schedule | 1 Division'!O23 -> Verso Time | EO3: ='Schedule | 1 Division'!K29 -> Verso Time | ET3: ='Schedule | 1 Division'!P29 -> Match 45 | EV3: ='Schedule | 1 Division'!O29 -> Aura Farmers | FA3: ='Schedule | 1 Division'!K35 -> FORZE | FF3: ='Schedule | 1 Division'!P35 -> Match 49 | FH3: ='Schedule | 1 Division'!O35 -> Verso Time | FM3: ='Schedule | 1 Division'!K41 -> CYBERHERO | FR3: ='Schedule | 1 Division'!P41 -> Match 53 | FT3: ='Schedule | 1 Division'!O41 -> FORZE
A4: 1 | B4: ='Schedule | 1 Division'!B6 -> Team Spirit | C4: =E4*3+F4*2+G4 -> 37 | D4: =SUM(E4:H4) -> 14 | E4: =COUNTIF($G$15:$G$70, B4) -> 10 | F4: =COUNTIF($H$15:$H$70, B4) -> 3 | G4: =COUNTIF($I$15:$I$70, B4) -> 1 | H4: =COUNTIF($J$15:$J$70, B4) -> 0 | I4: =SUMIFS($D$15:$D$70,$C$15:$C$70,B4)+SUMIFS($E$15:$E$70,$F$15:$F$70,B4) -> 27 | J4: =SUMIFS($D$15:$D$70,$F$15:$F$70,B4)+SUMIFS($E$15:$E$70,$C$15:$C$70,B4) -> 5 | K4: =I4-J4 -> 22
A5: 2 | B5: ='Schedule | 1 Division'!B10 -> Verso Time | C5: =E5*3+F5*2+G5 -> 34 | D5: =SUM(E5:H5) -> 14 | E5: =COUNTIF($G$15:$G$70, B5) -> 10 | F5: =COUNTIF($H$15:$H$70, B5) -> 1 | G5: =COUNTIF($I$15:$I$70, B5) -> 2 | H5: =COUNTIF($J$15:$J$70, B5) -> 1 | I5: =SUMIFS($D$15:$D$70,$C$15:$C$70,B5)+SUMIFS($E$15:$E$70,$F$15:$F$70,B5) -> 24 | J5: =SUMIFS($D$15:$D$70,$F$15:$F$70,B5)+SUMIFS($E$15:$E$70,$C$15:$C$70,B5) -> 7 | K5: =I5-J5 -> 17 | M5: Map | N5: Ban Team 1 | O5: Players Team 1 | P5: Pick Team 1 | Q5: Side | R5: Score | T5: Side | U5: Pick Team 2 | V5: Players Team 2 | W5: Ban Team 2 | Y5: Map | Z5: Ban Team 1 | AA5: Players Team 1 | AB5: Pick Team 1 | AC5: Side | AD5: Score | AF5: Side | AG5: Pick Team 2 | AH5: Players Team 2 | AI5: Ban Team 2 | AK5: Map | AL5: Ban Team 1 | AM5: Players Team 1 | AN5: Pick Team 1 | AO5: Side | AP5: Score | AR5: Side | AS5: Pick Team 2 | AT5: Players Team 2 | AU5: Ban Team 2 | AW5: Map | AX5: Ban Team 1 | AY5: Players Team 1 | AZ5: Pick Team 1 | BA5: Side | BB5: Score | BD5: Side | BE5: Pick Team 2 | BF5: Players Team 2 | BG5: Ban Team 2 | BI5: Map | BJ5: Ban Team 1 | BK5: Players Team 1 | BL5: Pick Team 1 | BM5: Side | BN5: Score | BP5: Side | BQ5: Pick Team 2 | BR5: Players Team 2 | BS5: Ban Team 2 | BU5: Map | BV5: Ban Team 1 | BW5: Players Team 1 | BX5: Pick Team 1 | BY5: Side | BZ5: Score | CB5: Side | CC5: Pick Team 2 | CD5: Players Team 2 | CE5: Ban Team 2 | CG5: Map | CH5: Ban Team 1 | CI5: Players Team 1 | CJ5: Pick Team 1 | CK5: Side | CL5: Score | CN5: Side | CO5: Pick Team 2 | CP5: Players Team 2 | CQ5: Ban Team 2 | CS5: Map | CT5: Ban Team 1 | CU5: Players Team 1 | CV5: Pick Team 1 | CW5: Side | CX5: Score | CZ5: Side | DA5: Pick Team 2 | DB5: Players Team 2 | DC5: Ban Team 2 | DE5: Map | DF5: Ban Team 1 | DG5: Players Team 1 | DH5: Pick Team 1 | DI5: Side | DJ5: Score | DL5: Side | DM5: Pick Team 2 | DN5: Players Team 2 | DO5: Ban Team 2 | DQ5: Map | DR5: Ban Team 1 | DS5: Players Team 1 | DT5: Pick Team 1 | DU5: Side | DV5: Score | DX5: Side | DY5: Pick Team 2 | DZ5: Players Team 2 | EA5: Ban Team 2 | EC5: Map | ED5: Ban Team 1 | EE5: Players Team 1 | EF5: Pick Team 1 | EG5: Side | EH5: Score | EJ5: Side | EK5: Pick Team 2 | EL5: Players Team 2 | EM5: Ban Team 2 | EO5: Map | EP5: Ban Team 1 | EQ5: Players Team 1 | ER5: Pick Team 1 | ES5: Side | ET5: Score | EV5: Side | EW5: Pick Team 2 | EX5: Players Team 2 | EY5: Ban Team 2 | FA5: Map | FB5: Ban Team 1 | FC5: Players Team 1 | FD5: Pick Team 1 | FE5: Side | FF5: Score | FH5: Side | FI5: Pick Team 2 | FJ5: Players Team 2 | FK5: Ban Team 2 | FM5: Map | FN5: Ban Team 1 | FO5: Players Team 1 | FP5: Pick Team 1 | FQ5: Side | FR5: Score | FT5: Side | FU5: Pick Team 2 | FV5: Players Team 2 | FW5: Ban Team 2
A6: 3 | B6: ='Schedule | 1 Division'!B5 -> Virtus.pro | C6: =E6*3+F6*2+G6 -> 25 | D6: =SUM(E6:H6) -> 14 | E6: =COUNTIF($G$15:$G$70, B6) -> 4 | F6: =COUNTIF($H$15:$H$70, B6) -> 5 | G6: =COUNTIF($I$15:$I$70, B6) -> 3 | H6: =COUNTIF($J$15:$J$70, B6) -> 2 | I6: =SUMIFS($D$15:$D$70,$C$15:$C$70,B6)+SUMIFS($E$15:$E$70,$F$15:$F$70,B6) -> 21 | J6: =SUMIFS($D$15:$D$70,$F$15:$F$70,B6)+SUMIFS($E$15:$E$70,$C$15:$C$70,B6) -> 15 | K6: =I6-J6 -> 6 | M6: 1 | N6: Baxia | O6: NEIL | P6: Gatotkaca | Q6: Blue | R6: L | S6: W | T6: Red | U6: Moskov | V6: Hiko | W6: Phoveus | Y6: 1 | Z6: Phoveus | AA6: zaur egoist | AB6: Guinevere | AC6: Blue | AD6: W | AE6: L | AF6: Red | AG6: Valentina | AH6: Solitude | AI6: Marcel | AK6: 1 | AL6: Harley | AM6: superegorka | AN6: Beatrix | AO6: Blue | AP6: W | AQ6: L | AR6: Red | AS6: Harith | AT6: Dont | AU6: Marcel | AW6: 1 | AX6: Fanny | AY6: Maniak | AZ6: Phoveus | BA6: Blue | BB6: W | BC6: L | BD6: Red | BE6: Kalea | BF6: NEIL | BG6: Chou | BI6: 1 | BJ6: Harith | BK6: ShowMe | BL6: Khufra | BM6: Blue | BN6: W | BO6: L | BP6: Red | BQ6: Fanny | BR6: Mashiro | BS6: Freya | BU6: 1 | BV6: Guinevere | BW6: NEIL | BX6: Baxia | BY6: Blue | BZ6: L | CA6: W | CB6: Red | CC6: Fredrinn | CD6: versoYustinian | CE6: Marcel | CG6: 1 | CH6: Baxia | CI6: Dont | CJ6: Harith | CK6: Blue | CL6: L | CM6: W | CN6: Red | CO6: Guinevere | CP6: versoYustinian | CQ6: Harley | CS6: 1 | CT6: Harith | CU6: SAWO | CV6: Baxia | CW6: Blue | CX6: W | CY6: L | CZ6: Red | DA6: Chou | DB6: KOKUSHIBO | DC6: Marcel | DE6: 1 | DF6: Phoveus | DG6: Loveeeely | DH6: Marcel | DI6: Blue | DJ6: L | DK6: W | DL6: Red | DM6: Harith | DN6: superegorka | DO6: Freya | DQ6: 1 | DR6: Phoveus | DS6: Marbon | DT6: Freya | DU6: Blue | DV6: L | DW6: W | DX6: Red | DY6: Zhuxin | DZ6: SunsetLover | EA6: Harith | EC6: 1 | ED6: Harley | EE6: superegorka | EF6: Moskov | EG6: Blue | EH6: L | EI6: W | EJ6: Red | EK6: Suyou | EL6: versoYustinian | EM6: Harith | EO6: 1 | EP6: Fanny | EQ6: versoKodjikk | ER6: Zhuxin | ES6: Blue | ET6: W | EU6: L | EV6: Red | EW6: Harith | EX6: Gorkiy | EY6: Marcel | FA6: 1 | FB6: Harley | FC6: Maniak | FD6: Paquito | FE6: Blue | FF6: L | FG6: W | FH6: Red | FI6: Kalea | FJ6: versoAFK | FK6: Baxia | FM6: 1 | FN6: Harley | FO6: Q1let | FP6: Marcel | FQ6: Blue | FR6: L | FS6: W | FT6: Red | FU6: Harith | FV6: Avilio. | FW6: Baxia
A7: 4 | B7: ='Schedule | 1 Division'!B9 -> Team Yandex | C7: =E7*3+F7*2+G7 -> 24 | D7: =SUM(E7:H7) -> 14 | E7: =COUNTIF($G$15:$G$70, B7) -> 6 | F7: =COUNTIF($H$15:$H$70, B7) -> 2 | G7: =COUNTIF($I$15:$I$70, B7) -> 2 | H7: =COUNTIF($J$15:$J$70, B7) -> 4 | I7: =SUMIFS($D$15:$D$70,$C$15:$C$70,B7)+SUMIFS($E$15:$E$70,$F$15:$F$70,B7) -> 18 | J7: =SUMIFS($D$15:$D$70,$F$15:$F$70,B7)+SUMIFS($E$15:$E$70,$C$15:$C$70,B7) -> 14 | K7: =I7-J7 -> 4 | N7: Guinevere | O7: Gorkiy | P7: Karrie | U7: Suyou | V7: zaur egoist | W7: Marcel | Z7: Zetian | AA7: Kidbomba | AB7: Benedetta | AG7: Gloo | AH7: Q1let | AI7: Harith | AL7: Freya | AM7: Fangor | AN7: Khufra | AS7: Kalea | AT7: Loveeeely | AU7: Phoveus | AX7: Harith | AY7: Repa | AZ7: Baxia | BE7: Alice | BF7: Summer | BG7: Marcel | BJ7: Yve | BK7: Maniak | BL7: Phoveus | BQ7: Kalea | BR7: Loveeeely | BS7: Marcel | BV7: Harley | BW7: Inneskite | BX7: Leomord | CC7: Kalea | CD7: versoAFK | CE7: Harith | CH7: Kalea | CI7: gxn1us | CJ7: Uranus | CO7: Khaleed | CP7: versoAFK | CQ7: Marcel | CT7: Yve | CU7: Kidbomba | CV7: Sora | DA7: Suyou | DB7: shelianer | DC7: Zhuxin | DF7: Baxia | DG7: Mashiro | DH7: Leomord | DM7: Zhuxin | DN7: Bober | DO7: Harley | DR7: Guinevere | DS7: Solitude | DT7: Yve | DY7: Baxia | DZ7: zaur egoist | EA7: Harley | ED7: Yve | EE7: Bober | EF7: Gord | EK7: Valentina | EL7: versoKodjikk | EM7: Marcel | EP7: Phoveus | EQ7: versoYustinian | ER7: Baxia | EW7: Yve | EX7: Twizy | EY7: Guinevere | FB7: Phoveus | FC7: Repa | FD7: Leomord | FI7: Guinevere | FJ7: versoYustinian | FK7: Marcel | FN7: Phoveus | FO7: Bert | FP7: Leomord | FU7: Zhuxin | FV7: Reaper | FW7: Freya
A8: 5 | B8: ='Schedule | 1 Division'!B7 -> FORZE | C8: =E8*3+F8*2+G8 -> 21 | D8: =SUM(E8:H8) -> 14 | E8: =COUNTIF($G$15:$G$70, B8) -> 4 | F8: =COUNTIF($H$15:$H$70, B8) -> 3 | G8: =COUNTIF($I$15:$I$70, B8) -> 3 | H8: =COUNTIF($J$15:$J$70, B8) -> 4 | I8: =SUMIFS($D$15:$D$70,$C$15:$C$70,B8)+SUMIFS($E$15:$E$70,$F$15:$F$70,B8) -> 17 | J8: =SUMIFS($D$15:$D$70,$F$15:$F$70,B8)+SUMIFS($E$15:$E$70,$C$15:$C$70,B8) -> 17 | K8: =I8-J8 -> 0 | N8: Valentina | O8: Inneskite | P8: Fanny | U8: Zhuxin | V8: SunsetLover | W8: Kalea | Z8: Harley | AA8: SAWO | AB8: Hylos | AG8: Fanny | AH8: Rienzy | AI8: Baxia | AL8: Yve | AM8: BadKot | AN8: Sora | AS8: Fanny | AT8: Mashiro | AU8: Zhuxin | AX8: Arlott | AY8: ShowMe | AZ8: Badang | BE8: Harley | BF8: Inneskite | BG8: Zhuxin | BJ8: Harley | BK8: Repa | BL8: Baxia | BQ8: Karrie | BR8: Dont | BS8: Zhuxin | BV8: Zhuxin | BW8: Summer | BX8: Terizla | CC8: Kimmy | CD8: versoKodjikk | CE8: Freya | CH8: Yve | CI8: Mashiro | CJ8: Suyou | CO8: Gord | CP8: versoKodjikk | CQ8: Zhuxin | CT8: Gloo | CU8: SunsetLover | CV8: Valentina | DA8: Zetian | DB8: shvedskii | DC8: Freya | DF8: Guinevere | DG8: Dont | DH8: Claude | DM8: Fredrinn | DN8: Marl | DO8: Suyou | DR8: Marcel | DS8: Q1let | DT8: Gloo | DY8: Claude | DZ8: Hiko | EA8: Hilda | ED8: Baxia | EE8: Marl | EF8: Guinevere | EK8: Claude | EL8: versoMarch | EM8: Zhuxin | EP8: Freya | EQ8: versoMarch | ER8: Claude | EW8: Leomord | EX8: Inneskite | EY8: Suyou | FB8: Yve | FC8: Avilio. | FD8: Harith | FI8: Sora | FJ8: versoCastle | FK8: Zhuxin | FN8: Yve | FO8: Ptenchik | FP8: Brody | FU8: Fanny | FV8: Repa | FW8: Claude
A9: 6 | B9: ='Schedule | 1 Division'!B8 -> CYBERHERO | C9: =E9*3+F9*2+G9 -> 11 | D9: =SUM(E9:H9) -> 14 | E9: =COUNTIF($G$15:$G$70, B9) -> 3 | F9: =COUNTIF($H$15:$H$70, B9) -> 1 | G9: =COUNTIF($I$15:$I$70, B9) -> 0 | H9: =COUNTIF($J$15:$J$70, B9) -> 10 | I9: =SUMIFS($D$15:$D$70,$C$15:$C$70,B9)+SUMIFS($E$15:$E$70,$F$15:$F$70,B9) -> 8 | J9: =SUMIFS($D$15:$D$70,$F$15:$F$70,B9)+SUMIFS($E$15:$E$70,$C$15:$C$70,B9) -> 21 | K9: =I9-J9 -> -13 | N9: Hilda | O9: Twizy | P9: Yve | U9: Badang | V9: SAWO | W9: Claude | Z9: Yve | AA9: Hiko | AB9: Beatrix | AG9: Clint | AH9: yuurikoshik | AI9: Moskov | AL9: Yu Zhong | AM9: Marl | AN9: Baxia | AS9: Valentina | AT9: Ptenchik | AU9: Moskov | AX9: Terizla | AY9: Avilio. | AZ9: Claude | BE9: Valentina | BF9: Twizy | BG9: Hilda | BJ9: Terizla | BK9: Reaper | BL9: Valir | BQ9: Valentina | BR9: Troublemaker | BS9: Selena | BV9: Suyou | BW9: Gorkiy | BX9: Claude | CC9: Moskov | CD9: versoMarch | CE9: Valentina | CH9: Kimmy | CI9: Troublemaker | CJ9: Zetian | CO9: Moskov | CP9: versoMarch | CQ9: Gloo | CT9: Claude | CU9: Hiko | CV9: Moskov | DA9: Terizla | DB9: Solist | DC9: Kalea | DF9: Hilda | DG9: gxn1us | DH9: Terizla | DM9: Hylos | DN9: Fangor | DO9: Zetian | DR9: Belerick | DS9: Rienzy | DT9: Suyou | DY9: Paquito | DZ9: Kidbomba | EA9: Bruno | ED9: Terizla | EE9: Fangor | EF9: Badang | EK9: Belerick | EL9: versoAFK | EM9: Chou | EP9: Gloo | EQ9: versoAFK | ER9: Grock | EW9: Gatotkaca | EX9: NEIL | EY9: Hylos | FB9: Clint | FC9: Reaper | FD9: Vexana | FI9: Claude | FJ9: versoMarch | FK9: Valentina | FN9: Belerick | FO9: Solitude | FP9: Gord | FU9: Khaleed | FV9: ShowMe | FW9: Clint
A10: 7 | B10: ='Schedule | 1 Division'!B4 -> Magic | C10: =E10*3+F10*2+G10 -> 9 | D10: =SUM(E10:H10) -> 14 | E10: =COUNTIF($G$15:$G$70, B10) -> 2 | F10: =COUNTIF($H$15:$H$70, B10) -> 0 | G10: =COUNTIF($I$15:$I$70, B10) -> 3 | H10: =COUNTIF($J$15:$J$70, B10) -> 9 | I10: =SUMIFS($D$15:$D$70,$C$15:$C$70,B10)+SUMIFS($E$15:$E$70,$F$15:$F$70,B10) -> 7 | J10: =SUMIFS($D$15:$D$70,$F$15:$F$70,B10)+SUMIFS($E$15:$E$70,$C$15:$C$70,B10) -> 24 | K10: =I10-J10 -> -17 | N10: Hylos | O10: MatadQr | P10: Sora | U10: Freya | V10: Kidbomba | W10: Grock | Z10: Kalea | AA10: SunsetLover | AB10: Zhuxin | AG10: Freya | AH10: Marbon | AI10: Valentina | AL10: Cici | AM10: Bober | AN10: Selena | AS10: Terizla | AT10: gxn1us | AU10: Kimmy | AX10: Beatrix | AY10: KinDer | AZ10: Selena | BE10: Karrie | BF10: Gorkiy | BG10: Freya | BJ10: Gloo | BK10: Avilio. | BL10: Moskov | BQ10: X.Borg | BR10: gxn1us | BS10: Badang | BV10: Nolan | BW10: Twizy | BX10: Pharsa | CC10: X.Borg | CD10: versoCastle | CE10: Zetian | CH10: Hilda | CI10: Loveeeely | CJ10: Hylos | CO10: Phoveus | CP10: versoCastle | CQ10: Valentina | CT10: Gatotkaca | CU10: SAWO | CV10: Minotaur | DA10: Granger | DB10: ilovee | DC10: Hylos | DF10: Gloo | DG10: Troublemaker | DH10: Kimmy | DM10: Arlott | DN10: BadKot | DO10: Yve | DR10: Benedetta | DS10: Ptenchik | DT10: Moskov | DY10: Chip | DZ10: SAWO | EA10: Fanny | ED10: Yu Zhong | EE10: BadKot | EF10: Phoveus | EK10: Uranus | EL10: versoCastle | EM10: Kaja | EP10: Terizla | EQ10: versoCastle | ER10: Paquito | EW10: Arlott | EX10: Summer | EY10: Atlas | FB10: Gord | FC10: ShowMe | FD10: Gloo | FI10: Kimmy | FJ10: versoKodjikk | FK10: Zetian | FN10: Atlas | FO10: Marbon | FP10: Arlott | FU10: Paquito | FV10: Maniak | FW10: Moskov
A11: 8 | B11: ='Schedule | 1 Division'!B3 -> Aura Farmers | C11: =E11*3+F11*2+G11 -> 7 | D11: =SUM(E11:H11) -> 14 | E11: =COUNTIF($G$15:$G$70, B11) -> 0 | F11: =COUNTIF($H$15:$H$70, B11) -> 2 | G11: =COUNTIF($I$15:$I$70, B11) -> 3 | H11: =COUNTIF($J$15:$J$70, B11) -> 9 | I11: =SUMIFS($D$15:$D$70,$C$15:$C$70,B11)+SUMIFS($E$15:$E$70,$F$15:$F$70,B11) -> 7 | J11: =SUMIFS($D$15:$D$70,$F$15:$F$70,B11)+SUMIFS($E$15:$E$70,$C$15:$C$70,B11) -> 26 | K11: =I11-J11 -> -19 | M11: 2 | N11: Baxia | O11: NEIL | P11: Gatotkaca | Q11: Blue | R11: L | S11: W | T11: Red | U11: Freya | V11: Kidbomba | W11: Phoveus | Y11: 2 | Z11: Marcel | AA11: zaur egoist | AB11: Granger | AC11: Red | AD11: W | AE11: L | AF11: Blue | AG11: Cecilion | AH11: Solitude | AI11: Hilda | AK11: 2 | AL11: Marcel | AM11: superegorka | AN11: Karrie | AO11: Red | AP11: L | AQ11: W | AR11: Blue | AS11: Freya | AT11: gxn1us | AU11: Guinevere | AW11: 2 | AX11: Freya | AY11: Maniak | AZ11: Benedetta | BA11: Red | BB11: L | BC11: W | BD11: Blue | BE11: Marcel | BF11: NEIL | BG11: Phoveus | BI11: 2 | BJ11: Yve | BK11: ShowMe | BL11: Badang | BM11: Red | BN11: W | BO11: L | BP11: Blue | BQ11: Freya | BR11: gxn1us | BS11: Fanny | BU11: 2 | BV11: Guinevere | BW11: Twizy | BX11: Zhuxin | BY11: Blue | BZ11: L | CA11: W | CB11: Red | CC11: Yve | CD11: versoKodjikk | CE11: Marcel | CG11: 2 | CH11: Harith | CI11: Troublemaker | CJ11: Zhuxin | CK11: Blue | CL11: L | CM11: W | CN11: Red | CO11: Kimmy | CP11: versoKodjikk | CQ11: Harley | CS11: 2 | CT11: Zhuxin | CU11: zaur egoist | CV11: Harley | CW11: Red | CX11: W | CY11: L | CZ11: Blue | DA11: Marcel | DB11: KOKUSHIBO | DC11: Harith | DE11: 2 | DF11: Phoveus | DG11: Troublemaker | DH11: Zhuxin | DI11: Blue | DJ11: W | DK11: L | DL11: Red | DM11: Marcel | DN11: Fangor | DO11: Freya | DQ11: 2 | DR11: Phoveus | DS11: Marbon | DT11: Freya | DU11: Blue | DV11: L | DW11: W | DX11: Red | DY11: Zhuxin | DZ11: SunsetLover | EA11: Harith | EC11: 2 | ED11: Harley | EE11: BadKot | EF11: Yu Zhong | EG11: Blue | EH11: W | EI11: L | EJ11: Red | EK11: Freya | EL11: versoCastle | EM11: Harith | EO11: 2 | EP11: Harley | EQ11: versoKodjikk | ER11: Zhuxin | ES11: Blue | ET11: W | EU11: L | EV11: Red | EW11: Freya | EX11: Gorkiy | EY11: Marcel | FA11: 2 | FB11: Harley | FC11: ShowMe | FD11: Kalea | FE11: Blue | FF11: L | FG11: W | FH11: Red | FI11: Paquito | FJ11: versoCastle | FK11: Baxia | FM11: 2 | FN11: Phoveus | FO11: Q1let | FP11: Hylos | FQ11: Blue | FR11: L | FS11: W | FT11: Red | FU11: Kalea | FV11: ShowMe | FW11: Marcel
N12: Guinevere | O12: Inneskite | P12: Leomord | U12: Harley | V12: zaur egoist | W12: Marcel | Z12: Baxia | AA12: Kidbomba | AB12: Freya | AG12: Khaleed | AH12: Q1let | AI12: Guinevere | AL12: Zhuxin | AM12: Fangor | AN12: Kalea | AS12: Valentina | AT12: Ptenchik | AU12: Phoveus | AX12: Harley | AY12: Repa | AZ12: Baxia | BE12: Suyou | BF12: Inneskite | BG12: Kalea | BJ12: Harley | BK12: Maniak | BL12: Aulus | BQ12: Grock | BR12: Loveeeely | BS12: Harith | BV12: Harley | BW12: Inneskite | BX12: Leomord | CC12: Aulus | CD12: versoYustinian | CE12: Harith | CH12: Baxia | CI12: Loveeeely | CJ12: Hilda | CO12: Guinevere | CP12: versoYustinian | CQ12: Marcel | CT12: Baxia | CU12: Kidbomba | CV12: Freya | DA12: Leomord | DB12: shelianer | DC12: Yve | DF12: Baxia | DG12: Mashiro | DH12: Fanny | DM12: Harith | DN12: superegorka | DO12: Harley | DR12: Guinevere | DS12: Solitude | DT12: Yve | DY12: Baxia | DZ12: zaur egoist | EA12: Harley | ED12: Yve | EE12: Fangor | EF12: Hylos | EK12: Baxia | EL12: versoYustinian | EM12: Marcel | EP12: Phoveus | EQ12: versoYustinian | ER12: Baxia | EW12: Suyou | EX12: Inneskite | EY12: Guinevere | FB12: Phoveus | FC12: Maniak | FD12: Arlott | FI12: Guinevere | FJ12: versoYustinian | FK12: Marcel | FN12: Harley | FO12: Bert | FP12: Fredrinn | FU12: Guinevere | FV12: Repa | FW12: Zhuxin
A13: All matches are BO3 | N13: Sora | O13: Twizy | P13: Zhuxin | U13: Valentina | V13: SAWO | W13: Kalea | Z13: Phoveus | AA13: SAWO | AB13: Fredrinn | AG13: Harith | AH13: yuurikoshik | AI13: Fanny | AL13: Harley | AM13: BadKot | AN13: Paquito | AS13: Hylos | AT13: Loveeeely | AU13: Harith | AX13: Guinevere | AY13: ShowMe | AZ13: Kaja | BE13: Yve | BF13: Twizy | BG13: Zhuxin | BJ13: Phoveus | BK13: Repa | BL13: Baxia | BQ13: Suyou | BR13: Mashiro | BS13: Marcel | BV13: Kalea | BW13: Summer | BX13: Arlott | CC13: Khufra | CD13: versoAFK | CE13: Freya | CH13: Phoveus | CI13: Mashiro | CJ13: Suyou | CO13: Kalea | CP13: versoAFK | CQ13: Freya | CT13: Guinevere | CU13: SunsetLover | CV13: Valentina | DA13: Uranus | DB13: Solist | DC13: Phoveus | DF13: Guinevere | DG13: Dont | DH13: Claude | DM13: Valentina | DN13: Bober | DO13: Suyou | DR13: Marcel | DS13: Q1let | DT13: Gloo | DY13: Suyou | DZ13: Kidbomba | EA13: Hilda | ED13: Guinevere | EE13: Bober | EF13: Zhuxin | EK13: Atlas | EL13: versoAFK | EM13: Phoveus | EP13: Fanny | EQ13: versoMarch | ER13: Harith | EW13: Lapu-Lapu | EX13: Summer | EY13: Claude | FB13: Yve | FC13: Repa | FD13: Fredrinn | FI13: Gord | FJ13: versoKodjikk | FK13: Zhuxin | FN13: Freya | FO13: Ptenchik | FP13: Paquito | FU13: Lapu-Lapu | FV13: Maniak | FW13: Baxia
A14: Round | B14: Match | C14: Team 1 | D14: Score Team 1 | E14: Score Team 2 | F14: Team 2 | G14: Match winner 2:0 | H14: Match winner 2:1 | I14: Match loser 1:2 | J14: Match loser 0:2 | N14: Gloo | O14: MatadQr | P14: Alice | U14: Claude | V14: Hiko | W14: Hilda | Z14: Cici | AA14: Hiko | AB14: Belerick | AG14: Dyrroth | AH14: Marbon | AI14: Kalea | AL14: Fanny | AM14: Marl | AN14: Baxia | AS14: Suyou | AT14: Mashiro | AU14: Yu Zhong | AX14: Terizla | AY14: Avilio. | AZ14: Clint | BE14: Moskov | BF14: Gorkiy | BG14: Hilda | BJ14: Lylia | BK14: Reaper | BL14: Zhuxin | BQ14: Karrie | BR14: Dont | BS14: Hilda | BV14: Suyou | BW14: NEIL | BX14: Belerick | CC14: Phoveus | CD14: versoCastle | CE14: Hylos | CH14: Arlott | CI14: Dont | CJ14: Claude | CO14: Moskov | CP14: versoMarch | CQ14: Uranus | CT14: Karrie | CU14: Hiko | CV14: Clint | DA14: Kimmy | DB14: shvedskii | DC14: Gatotkaca | DF14: Fredrinn | DG14: Loveeeely | DH14: Gatotkaca | DM14: Kaja | DN14: Marl | DO14: Hylos | DR14: Benedetta | DS14: Rienzy | DT14: Fredrinn | DY14: Claude | DZ14: Hiko | EA14: Fanny | ED14: Gord | EE14: superegorka | EF14: Hanabi | EK14: Claude | EL14: versoMarch | EM14: Suyou | EP14: Yve | EQ14: versoAFK | ER14: Kalea | EW14: Hylos | EX14: NEIL | EY14: Paquito | FB14: Belerick | FC14: Reaper | FD14: Kadita | FI14: Gatotkaca | FJ14: versoAFK | FK14: Luo Yi | FN14: Gord | FO14: Solitude | FP14: Zetian | FU14: Yve | FV14: Reaper | FW14: Gloo
