Workbook

Sheet General
B2: 📝 Tournament Info | H2: 💰 Prize Pool Distribution | L2: 📋 Participants
B3: Event Name | C3: ➡️ | D3: CCT 2026 South America Series 3 | H3: Place | I3: Total | J3: Team | L3: Playoffs | M3: 1 | N3: South America VRS | O3: LP
B4: Tournament Organizer | C4: ➡️ | D4: CCT | H4: 1st | I4: 7500 | J4: =Bracket!AL19 | L4: Playoffs | M4: 2 | N4: South America VRS | O4: Imperial
B5: Location | C5: ➡️ | D5: Online, South America | H5: 2nd | I5: 4000 | J5: =IFS(OR(Bracket!AJ11=2, Bracket!AJ11="FFW"),Bracket!AI27,OR(Bracket!AJ27=2, Bracket!AJ27="FFW"),Bracket!AI11,TRUE,"") | L5: Playoffs | M5: 3 | N5: South America VRS | O5: Fluxo
B6: Prize pool | C6: ➡️ | D6: =I8 -> 15000 | H6: 3-4th | I6: 1750 | J6: =IFS(OR(Bracket!AG7=2, Bracket!AG7="FFW"),Bracket!AF15,OR(Bracket!AG15=2, Bracket!AG15="FFW"),Bracket!AF7,TRUE,"") | L6: Playoffs | M6: 4 | N6: South America VRS | O6: Bounty Hunters
B7: Invite Date | C7: ➡️ | D7: 46178 | E7: > | F7: =D7 -> 46178 | I7: 1750 | J7: =IFS(OR(Bracket!AG23=2, Bracket!AG23="FFW"),Bracket!AF31,OR(Bracket!AG31=2, Bracket!AG31="FFW"),Bracket!AF23,TRUE,"") | L7: Playoffs | M7: 5 | N7: South America VRS | O7: Fake do Biru
B8: VRS Date | C8: ➡️ | D8: =F7 -> 46178 | H8: Total | I8: =SUM(I4:I7) -> 15000 | L8: Playoffs | M8: 6 | N8: South America VRS | O8: Keyd Stars
B9: Valve Status | C9: ➡️ | D9: Tier 2 | E9: 🔀 | F9: Ranked | L9: Playoffs | M9: 7 | N9: South America VRS | O9: Isurus
B10: Rulebook | C10: ➡️ | D10: Champion of Champions Tour - Official Rulebook.pdf | H10: 📺 Tournament Socials | L10: Playoffs | M10: 8 | N10: South America VRS | O10: UNO MILLE
B11: Announcement Link & Date | C11: ➡️ | E11: 🗓️ | F11: 46073 | H11: Stream | I11: kick.com/CCT_CS3 | L11: Group Stage | M11: 1 | N11: South America VRS | O11: METANOIA Wolves
B12: Additional Info Link & Date | C12: ➡️ | E12: 🗓️ | F12: 46073 | H12: X Account | I12: x.com/CCT_CS | L12: Group Stage | M12: 2 | N12: South America VRS | O12: paiN Academy
B13: Discord | C13: ➡️ | H13: Contact 📩 | I13: support@cct.gg | L13: Group Stage | M13: 3 | N13: South America VRS | O13: GameHunters
B14: Format Stage 1 > Group Stage | C14: ➡️ | D14: Swiss Stage | L14: Group Stage | M14: 4 | N14: South America VRS | O14: ex-KRU
B15: Format Stage 2 > Playoffs | C15: ➡️ | D15: Single Elim, 16 Teams | L15: Group Stage | M15: 5 | N15: South America VRS | O15: Procyon
B16: Number of teams | C16: ➡️ | D16: Group Stage - 16 Teams > 14 Invited + 2 Qualified from Open Qualifiers Playoffs - 16 Teams > 8 Invited + 8 Qualified from Group Stage Total: 22 Invites + 2 Slots for Open Qualifiers | L16: Group Stage | M16: 6 | N16: South America VRS | O16: Vasco
L17: Group Stage | M17: 7 | N17: South America VRS | O17: BESTIA Academy
L18: Group Stage | M18: 8 | N18: South America VRS | O18: ALKA
L19: Group Stage | M19: 9 | N19: South America VRS | O19: BORRACHEIROS
L20: Group Stage | M20: 10 | N20: South America VRS | O20: GUARA
L21: Group Stage | M21: 11 | N21: South America VRS | O21: MAGICOS
L22: Group Stage | M22: 12 | N22: South America VRS | O22: Red Feet
L23: Group Stage | M23: 13 | N23: South America VRS | O23: GREMIO
L24: Group Stage | M24: 14 | N24: South America VRS | O24: Blitzkrieg
L25: Group Stage | M25: 15 | N25: Open Qualifier Slot | O25: ODDIK
L26: Group Stage | M26: 16 | N26: Open Qualifier Slot | O26: Patins da Ferrari

Sheet Bracket
B1: Group Stage - Swiss | Z1: Playoffs - Single Elimination
J5: Swiss Stage 2-0 | Z5: Round of 16
F7: GameHunters | G7: 2 | AC7: Quarter-Finals
F8: Swiss Stage 1-0
B9: METANOIA Wolves | C9: 0 | F9: ALKA | G9: 1 | J9: Swiss Stage 2-0 | Z9: Round of 16
B10: Swiss Stage 0-0
B11: Patins da Ferrari | C11: 2 | F11: Patins da Ferrari | AF11: Semi-Finals
F12: Swiss Stage 1-0
B13: paiN Academy | C13: 0 | F13: GREMIO | N13: Swiss Stage 2-1 | Z13: Round of 16
B14: Swiss Stage 0-0
B15: ODDIK | C15: 2 | F15: ODDIK | J15: Swiss Stage 1-1 | AC15: Quarter-Finals
F16: Swiss Stage 1-0
B17: GameHunters | C17: 2 | F17: Procyon | N17: Swiss Stage 2-1 | Z17: Round of 16
B18: Swiss Stage 0-0 | AL18: Champion
B19: Blitzkrieg | C19: 0 | F19: BESTIA Academy | J19: Swiss Stage 1-1 | R19: Swiss Stage 2-2 | AI19: Grand Final
F20: Swiss Stage 1-0
B21: ex-KRU | C21: FFL | F21: MAGICOS | N21: Swiss Stage 2-1 | Z21: Round of 16
B22: Swiss Stage 0-0
B23: GREMIO | C23: FFW | J23: Swiss Stage 1-1 | R23: Swiss Stage 2-2 | AC23: Quarter-Finals
B25: Procyon | C25: 2 | Z25: Round of 16
B26: Swiss Stage 0-0 | N26: Swiss Stage 1-2
B27: Red Feet | C27: 1 | F27: paiN Academy | G27: FFW | J27: Swiss Stage 1-1 | R27: Swiss Stage 2-2 | AF27: Semi-Finals
F28: Swiss Stage 0-1
B29: Vasco | C29: FFL | F29: Blitzkrieg | G29: FFL | Z29: Round of 16
B30: Swiss Stage 0-0 | N30: Swiss Stage 1-2
B31: MAGICOS | C31: FFW | F31: GUARA | G31: 1 | AC31: Quarter-Finals
F32: Swiss Stage 0-1
B33: BESTIA Academy | C33: 2 | F33: METANOIA Wolves | G33: 2 | J33: Swiss Stage 0-2 | Z33: Round of 16
B34: Swiss Stage 0-0 | N34: Swiss Stage 1-2
B35: GUARA | C35: 0 | F35: Red Feet | G35: FFW
F36: Swiss Stage 0-1
B37: ALKA | C37: 2 | F37: Vasco | G37: FFW | J37: Swiss Stage 0-2 | O37: Final Table
B38: Swiss Stage 0-0 | O38: Playoffs | R38: =IFS(OR(K4=2, K4="FFW"),J4,OR(K6=2, K6="FFW"),J6,TRUE,"") | S38: 3-0
B39: BORRACHEIROS | C39: 1 | F39: BORRACHEIROS | G39: FFW | O39: Playoffs | R39: =IFS(OR(K8=2, K8="FFW"),J8,OR(K10=2, K10="FFW"),J10,TRUE,"") | S39: 3-0
F40: Swiss Stage 0-1 | O40: Playoffs | R40: =IFS(OR(O12=2, O12="FFW"),N12,OR(O14=2, O14="FFW"),N14,TRUE,"") | S40: 45717
F41: ex-KRU | G41: FFL | O41: Playoffs | R41: =IFS(OR(O16=2, O16="FFW"),N16,OR(O18=2, O18="FFW"),N18,TRUE,"") | S41: 45717
O42: Playoffs | R42: =IFS(OR(O20=2, O20="FFW"),N20,OR(O22=2, O22="FFW"),N22,TRUE,"") | S42: 45717
O43: Playoffs | R43: =IFS(OR(S18=2, S18="FFW"),R18,OR(S20=2, S20="FFW"),R20,TRUE,"") | S43: 45718
O44: Playoffs | R44: =IFS(OR(S22=2, S22="FFW"),R22,OR(S24=2, S24="FFW"),R24,TRUE,"") | S44: 45718
O45: Playoffs | R45: =IFS(OR(S26=2, S26="FFW"),R26,OR(S28=2, S28="FFW"),R28,TRUE,"") | S45: 45718
...

Sheet Schedule
A1: Best Of | B1: Stage | C1: Match | D1: Date | E1: Local Time | F1: Start Time | G1: Team A | H1: Score | K1: Team B | M1: Map 1 Score | P1: Map 2 Score | S1: Map 3 Score | V1: Notes
A2: Bo3 | B2: Group Stage | C2: Swiss Stage 0-0 | D2: 46217 | E2: 0.41666667 | F2: =E2+Data!$A$13 -> 0.625 | G2: METANOIA Wolves | H2: =IF(M2="", "", IF(COUNT(M2:N2, P2:Q2, S2:T2) > 0, (IF(ISNUMBER(M2)*ISNUMBER(N2), M2>N2, M2="FFW")) + (IF(ISNUMBER(P2)*ISNUMBER(Q2), P2>Q2, P2="FFW")) + (IF(ISNUMBER(S2)*ISNUMBER(T2), S2>T2, S2="FFW")), IFS((M2="FFW")+(P2="FFW")+(S2="FFW")>=2, "FFW", (M2="FFL")+(P2="FFL")+(S2="FFL")>=2, "FFL", TRUE, (M2="FFW")+(P2="FFW")+(S2="FFW")))) -> 0 | J2: =IF(M2="", "", IF(COUNT(M2:N2, P2:Q2, S2:T2) > 0, (IF(ISNUMBER(M2)*ISNUMBER(N2), M2<N2, N2="FFW")) + (IF(ISNUMBER(P2)*ISNUMBER(Q2), P2<Q2, Q2="FFW")) + (IF(ISNUMBER(S2)*ISNUMBER(T2), S2<T2, T2="FFW")), IFS((N2="FFW")+(Q2="FFW")+(T2="FFW")>=2, "FFW", (N2="FFL")+(Q2="FFL")+(T2="FFL")>=2, "FFL", TRUE, (N2="FFW")+(Q2="FFW")+(T2="FFW")))) -> 2 | K2: Patins da Ferrari | M2: 1 | N2: 13 | P2: 6 | Q2: 13
A3: Bo3 | B3: Group Stage | C3: Swiss Stage 0-0 | E3: 0.54166667 | F3: =E3+Data!$A$13 -> 0.75 | G3: paiN Academy | H3: =IF(M3="", "", IF(COUNT(M3:N3, P3:Q3, S3:T3) > 0, (IF(ISNUMBER(M3)*ISNUMBER(N3), M3>N3, M3="FFW")) + (IF(ISNUMBER(P3)*ISNUMBER(Q3), P3>Q3, P3="FFW")) + (IF(ISNUMBER(S3)*ISNUMBER(T3), S3>T3, S3="FFW")), IFS((M3="FFW")+(P3="FFW")+(S3="FFW")>=2, "FFW", (M3="FFL")+(P3="FFL")+(S3="FFL")>=2, "FFL", TRUE, (M3="FFW")+(P3="FFW")+(S3="FFW")))) -> 0 | J3: =IF(M3="", "", IF(COUNT(M3:N3, P3:Q3, S3:T3) > 0, (IF(ISNUMBER(M3)*ISNUMBER(N3), M3<N3, N3="FFW")) + (IF(ISNUMBER(P3)*ISNUMBER(Q3), P3<Q3, Q3="FFW")) + (IF(ISNUMBER(S3)*ISNUMBER(T3), S3<T3, T3="FFW")), IFS((N3="FFW")+(Q3="FFW")+(T3="FFW")>=2, "FFW", (N3="FFL")+(Q3="FFL")+(T3="FFL")>=2, "FFL", TRUE, (N3="FFW")+(Q3="FFW")+(T3="FFW")))) -> 2 | K3: ODDIK | M3: 5 | N3: 13 | P3: 11 | Q3: 13
A4: Bo3 | B4: Group Stage | C4: Swiss Stage 0-0 | E4: 0.66666667 | F4: =E4+Data!$A$13 -> 0.875 | G4: Vasco | H4: =IF(M4="", "", IF(COUNT(M4:N4, P4:Q4, S4:T4) > 0, (IF(ISNUMBER(M4)*ISNUMBER(N4), M4>N4, M4="FFW")) + (IF(ISNUMBER(P4)*ISNUMBER(Q4), P4>Q4, P4="FFW")) + (IF(ISNUMBER(S4)*ISNUMBER(T4), S4>T4, S4="FFW")), IFS((M4="FFW")+(P4="FFW")+(S4="FFW")>=2, "FFW", (M4="FFL")+(P4="FFL")+(S4="FFL")>=2, "FFL", TRUE, (M4="FFW")+(P4="FFW")+(S4="FFW")))) -> FFL | J4: =IF(M4="", "", IF(COUNT(M4:N4, P4:Q4, S4:T4) > 0, (IF(ISNUMBER(M4)*ISNUMBER(N4), M4<N4, N4="FFW")) + (IF(ISNUMBER(P4)*ISNUMBER(Q4), P4<Q4, Q4="FFW")) + (IF(ISNUMBER(S4)*ISNUMBER(T4), S4<T4, T4="FFW")), IFS((N4="FFW")+(Q4="FFW")+(T4="FFW")>=2, "FFW", (N4="FFL")+(Q4="FFL")+(T4="FFL")>=2, "FFL", TRUE, (N4="FFW")+(Q4="FFW")+(T4="FFW")))) -> FFW | K4: MAGICOS | M4: FFL | N4: FFW | P4: FFL | Q4: FFW | V4: Vasco forfeited the match because they were unable to field a roster
A5: Bo3 | B5: Group Stage | C5: Swiss Stage 0-0 | E5: 0.79166667 | F5: =E5+Data!$A$13 -> 1 | G5: BESTIA Academy | H5: =IF(M5="", "", IF(COUNT(M5:N5, P5:Q5, S5:T5) > 0, (IF(ISNUMBER(M5)*ISNUMBER(N5), M5>N5, M5="FFW")) + (IF(ISNUMBER(P5)*ISNUMBER(Q5), P5>Q5, P5="FFW")) + (IF(ISNUMBER(S5)*ISNUMBER(T5), S5>T5, S5="FFW")), IFS((M5="FFW")+(P5="FFW")+(S5="FFW")>=2, "FFW", (M5="FFL")+(P5="FFL")+(S5="FFL")>=2, "FFL", TRUE, (M5="FFW")+(P5="FFW")+(S5="FFW")))) -> 2 | J5: =IF(M5="", "", IF(COUNT(M5:N5, P5:Q5, S5:T5) > 0, (IF(ISNUMBER(M5)*ISNUMBER(N5), M5<N5, N5="FFW")) + (IF(ISNUMBER(P5)*ISNUMBER(Q5), P5<Q5, Q5="FFW")) + (IF(ISNUMBER(S5)*ISNUMBER(T5), S5<T5, T5="FFW")), IFS((N5="FFW")+(Q5="FFW")+(T5="FFW")>=2, "FFW", (N5="FFL")+(Q5="FFL")+(T5="FFL")>=2, "FFL", TRUE, (N5="FFW")+(Q5="FFW")+(T5="FFW")))) -> 0 | K5: GUARA | M5: 13 | N5: 7 | P5: 13 | Q5: 4
A6: Bo3 | B6: Group Stage | C6: Swiss Stage 0-0 | D6: =D2+1 -> 46218 | E6: 0.41666667 | F6: =E6+Data!$A$13 -> 0.625 | G6: Procyon | H6: =IF(M6="", "", IF(COUNT(M6:N6, P6:Q6, S6:T6) > 0, (IF(ISNUMBER(M6)*ISNUMBER(N6), M6>N6, M6="FFW")) + (IF(ISNUMBER(P6)*ISNUMBER(Q6), P6>Q6, P6="FFW")) + (IF(ISNUMBER(S6)*ISNUMBER(T6), S6>T6, S6="FFW")), IFS((M6="FFW")+(P6="FFW")+(S6="FFW")>=2, "FFW", (M6="FFL")+(P6="FFL")+(S6="FFL")>=2, "FFL", TRUE, (M6="FFW")+(P6="FFW")+(S6="FFW")))) -> 2 | J6: =IF(M6="", "", IF(COUNT(M6:N6, P6:Q6, S6:T6) > 0, (IF(ISNUMBER(M6)*ISNUMBER(N6), M6<N6, N6="FFW")) + (IF(ISNUMBER(P6)*ISNUMBER(Q6), P6<Q6, Q6="FFW")) + (IF(ISNUMBER(S6)*ISNUMBER(T6), S6<T6, T6="FFW")), IFS((N6="FFW")+(Q6="FFW")+(T6="FFW")>=2, "FFW", (N6="FFL")+(Q6="FFL")+(T6="FFL")>=2, "FFL", TRUE, (N6="FFW")+(Q6="FFW")+(T6="FFW")))) -> 1 | K6: Red Feet | M6: 8 | N6: 13 | P6: 13 | Q6: 7 | S6: 16 | T6: 13
A7: Bo3 | B7: Group Stage | C7: Swiss Stage 0-0 | E7: 0.56597222 | F7: =E7+Data!$A$13 -> 0.77430556 | G7: GameHunters | H7: =IF(M7="", "", IF(COUNT(M7:N7, P7:Q7, S7:T7) > 0, (IF(ISNUMBER(M7)*ISNUMBER(N7), M7>N7, M7="FFW")) + (IF(ISNUMBER(P7)*ISNUMBER(Q7), P7>Q7, P7="FFW")) + (IF(ISNUMBER(S7)*ISNUMBER(T7), S7>T7, S7="FFW")), IFS((M7="FFW")+(P7="FFW")+(S7="FFW")>=2, "FFW", (M7="FFL")+(P7="FFL")+(S7="FFL")>=2, "FFL", TRUE, (M7="FFW")+(P7="FFW")+(S7="FFW")))) -> 2 | J7: =IF(M7="", "", IF(COUNT(M7:N7, P7:Q7, S7:T7) > 0, (IF(ISNUMBER(M7)*ISNUMBER(N7), M7<N7, N7="FFW")) + (IF(ISNUMBER(P7)*ISNUMBER(Q7), P7<Q7, Q7="FFW")) + (IF(ISNUMBER(S7)*ISNUMBER(T7), S7<T7, T7="FFW")), IFS((N7="FFW")+(Q7="FFW")+(T7="FFW")>=2, "FFW", (N7="FFL")+(Q7="FFL")+(T7="FFL")>=2, "FFL", TRUE, (N7="FFW")+(Q7="FFW")+(T7="FFW")))) -> 0 | K7: Blitzkrieg | M7: 13 | N7: 3 | P7: 13 | Q7: 1
A8: Bo3 | B8: Group Stage | C8: Swiss Stage 0-0 | E8: 0.66666667 | F8: =E8+Data!$A$13 -> 0.875 | G8: ex-KRU | H8: =IF(M8="", "", IF(COUNT(M8:N8, P8:Q8, S8:T8) > 0, (IF(ISNUMBER(M8)*ISNUMBER(N8), M8>N8, M8="FFW")) + (IF(ISNUMBER(P8)*ISNUMBER(Q8), P8>Q8, P8="FFW")) + (IF(ISNUMBER(S8)*ISNUMBER(T8), S8>T8, S8="FFW")), IFS((M8="FFW")+(P8="FFW")+(S8="FFW")>=2, "FFW", (M8="FFL")+(P8="FFL")+(S8="FFL")>=2, "FFL", TRUE, (M8="FFW")+(P8="FFW")+(S8="FFW")))) -> FFL | J8: =IF(M8="", "", IF(COUNT(M8:N8, P8:Q8, S8:T8) > 0, (IF(ISNUMBER(M8)*ISNUMBER(N8), M8<N8, N8="FFW")) + (IF(ISNUMBER(P8)*ISNUMBER(Q8), P8<Q8, Q8="FFW")) + (IF(ISNUMBER(S8)*ISNUMBER(T8), S8<T8, T8="FFW")), IFS((N8="FFW")+(Q8="FFW")+(T8="FFW")>=2, "FFW", (N8="FFL")+(Q8="FFL")+(T8="FFL")>=2, "FFL", TRUE, (N8="FFW")+(Q8="FFW")+(T8="FFW")))) -> FFW | K8: GREMIO | M8: FFL | N8: FFW | P8: FFL | Q8: FFW | V8: EX-KRU withdraw from the tournament as they lost VRS core.
A9: Bo3 | B9: Group Stage | C9: Swiss Stage 0-0 | E9: 0.79166667 | F9: =E9+Data!$A$13 -> 1 | G9: ALKA | H9: =IF(M9="", "", IF(COUNT(M9:N9, P9:Q9, S9:T9) > 0, (IF(ISNUMBER(M9)*ISNUMBER(N9), M9>N9, M9="FFW")) + (IF(ISNUMBER(P9)*ISNUMBER(Q9), P9>Q9, P9="FFW")) + (IF(ISNUMBER(S9)*ISNUMBER(T9), S9>T9, S9="FFW")), IFS((M9="FFW")+(P9="FFW")+(S9="FFW")>=2, "FFW", (M9="FFL")+(P9="FFL")+(S9="FFL")>=2, "FFL", TRUE, (M9="FFW")+(P9="FFW")+(S9="FFW")))) -> 2 | J9: =IF(M9="", "", IF(COUNT(M9:N9, P9:Q9, S9:T9) > 0, (IF(ISNUMBER(M9)*ISNUMBER(N9), M9<N9, N9="FFW")) + (IF(ISNUMBER(P9)*ISNUMBER(Q9), P9<Q9, Q9="FFW")) + (IF(ISNUMBER(S9)*ISNUMBER(T9), S9<T9, T9="FFW")), IFS((N9="FFW")+(Q9="FFW")+(T9="FFW")>=2, "FFW", (N9="FFL")+(Q9="FFL")+(T9="FFL")>=2, "FFL", TRUE, (N9="FFW")+(Q9="FFW")+(T9="FFW")))) -> 1 | K9: BORRACHEIROS | M9: 2 | N9: 13 | P9: 13 | Q9: 9 | S9: 13 | T9: 10
A10: Bo3 | B10: Group Stage | C10: Swiss Stage 0-1 | D10: =D6+1 -> 46219 | E10: 0.41666667 | F10: =E10+Data!$A$13 -> 0.625 | G10: paiN Academy | H10: FFW | J10: FFL | K10: Blitzkrieg | M10: FFW | N10: FFL | P10: FFW | Q10: FFL | V10: Blitzkrieg forfeits the match for not being able to provide a full roster for the match
A11: Bo3 | B11: Group Stage | C11: Swiss Stage 0-1 | E11: 0.54166667 | F11: =E11+Data!$A$13 -> 0.75 | G11: GUARA | H11: =IF(M11="", "", IF(COUNT(M11:N11, P11:Q11, S11:T11) > 0, (IF(ISNUMBER(M11)*ISNUMBER(N11), M11>N11, M11="FFW")) + (IF(ISNUMBER(P11)*ISNUMBER(Q11), P11>Q11, P11="FFW")) + (IF(ISNUMBER(S11)*ISNUMBER(T11), S11>T11, S11="FFW")), IFS((M11="FFW")+(P11="FFW")+(S11="FFW")>=2, "FFW", (M11="FFL")+(P11="FFL")+(S11="FFL")>=2, "FFL", TRUE, (M11="FFW")+(P11="FFW")+(S11="FFW")))) -> 1 | J11: =IF(M11="", "", IF(COUNT(M11:N11, P11:Q11, S11:T11) > 0, (IF(ISNUMBER(M11)*ISNUMBER(N11), M11<N11, N11="FFW")) + (IF(ISNUMBER(P11)*ISNUMBER(Q11), P11<Q11, Q11="FFW")) + (IF(ISNUMBER(S11)*ISNUMBER(T11), S11<T11, T11="FFW")), IFS((N11="FFW")+(Q11="FFW")+(T11="FFW")>=2, "FFW", (N11="FFL")+(Q11="FFL")+(T11="FFL")>=2, "FFL", TRUE, (N11="FFW")+(Q11="FFW")+(T11="FFW")))) -> 2 | K11: METANOIA Wolves | M11: 13 | N11: 6 | P11: 7 | Q11: 13 | S11: 8 | T11: 13
A12: Bo3 | B12: Group Stage | C12: Swiss Stage 0-1 | E12: 0.66666667 | F12: =E12+Data!$A$13 -> 0.875 | G12: Red Feet | H12: =IF(M12="", "", IF(COUNT(M12:N12, P12:Q12, S12:T12) > 0, (IF(ISNUMBER(M12)*ISNUMBER(N12), M12>N12, M12="FFW")) + (IF(ISNUMBER(P12)*ISNUMBER(Q12), P12>Q12, P12="FFW")) + (IF(ISNUMBER(S12)*ISNUMBER(T12), S12>T12, S12="FFW")), IFS((M12="FFW")+(P12="FFW")+(S12="FFW")>=2, "FFW", (M12="FFL")+(P12="FFL")+(S12="FFL")>=2, "FFL", TRUE, (M12="FFW")+(P12="FFW")+(S12="FFW")))) -> FFW | J12: =IF(M12="", "", IF(COUNT(M12:N12, P12:Q12, S12:T12) > 0, (IF(ISNUMBER(M12)*ISNUMBER(N12), M12<N12, N12="FFW")) + (IF(ISNUMBER(P12)*ISNUMBER(Q12), P12<Q12, Q12="FFW")) + (IF(ISNUMBER(S12)*ISNUMBER(T12), S12<T12, T12="FFW")), IFS((N12="FFW")+(Q12="FFW")+(T12="FFW")>=2, "FFW", (N12="FFL")+(Q12="FFL")+(T12="FFL")>=2, "FFL", TRUE, (N12="FFW")+(Q12="FFW")+(T12="FFW")))) -> FFL | K12: Vasco | M12: FFW | N12: FFL | P12: FFW | Q12: FFL | V12: Vasco forfeits the match for being unable to provide a full roster
A13: Bo3 | B13: Group Stage | C13: Swiss Stage 0-1 | E13: 0.79166667 | F13: =E13+Data!$A$13 -> 1 | G13: BORRACHEIROS | H13: FFW | J13: FFL | K13: ex-KRU | M13: FFW | N13: FFL | P13: FFW | Q13: FFL | V13: EX-KRU withdraw from the tournament as they lost VRS core.
A14: Bo3 | B14: Group Stage | C14: Swiss Stage 1-0 | D14: =D10+1 -> 46220 | E14: 0.41666667 | F14: =E14+Data!$A$13 -> 0.625 | G14: GameHunters | H14: =IF(M14="", "", IF(COUNT(M14:N14, P14:Q14, S14:T14) > 0, (IF(ISNUMBER(M14)*ISNUMBER(N14), M14>N14, M14="FFW")) + (IF(ISNUMBER(P14)*ISNUMBER(Q14), P14>Q14, P14="FFW")) + (IF(ISNUMBER(S14)*ISNUMBER(T14), S14>T14, S14="FFW")), IFS((M14="FFW")+(P14="FFW")+(S14="FFW")>=2, "FFW", (M14="FFL")+(P14="FFL")+(S14="FFL")>=2, "FFL", TRUE, (M14="FFW")+(P14="FFW")+(S14="FFW")))) -> 2 | J14: =IF(M14="", "", IF(COUNT(M14:N14, P14:Q14, S14:T14) > 0, (IF(ISNUMBER(M14)*ISNUMBER(N14), M14<N14, N14="FFW")) + (IF(ISNUMBER(P14)*ISNUMBER(Q14), P14<Q14, Q14="FFW")) + (IF(ISNUMBER(S14)*ISNUMBER(T14), S14<T14, T14="FFW")), IFS((N14="FFW")+(Q14="FFW")+(T14="FFW")>=2, "FFW", (N14="FFL")+(Q14="FFL")+(T14="FFL")>=2, "FFL", TRUE, (N14="FFW")+(Q14="FFW")+(T14="FFW")))) -> 1 | K14: ALKA | M14: 7 | N14: 13 | P14: 16 | Q14: 13 | S14: 13 | T14: 7
A15: Bo3 | B15: Group Stage | C15: Swiss Stage 1-0 | E15: 0.54166667 | F15: =E15+Data!$A$13 -> 0.75 | G15: Patins da Ferrari | H15: =IF(M15="", "", IF(COUNT(M15:N15, P15:Q15, S15:T15) > 0, (IF(ISNUMBER(M15)*ISNUMBER(N15), M15>N15, M15="FFW")) + (IF(ISNUMBER(P15)*ISNUMBER(Q15), P15>Q15, P15="FFW")) + (IF(ISNUMBER(S15)*ISNUMBER(T15), S15>T15, S15="FFW")), IFS((M15="FFW")+(P15="FFW")+(S15="FFW")>=2, "FFW", (M15="FFL")+(P15="FFL")+(S15="FFL")>=2, "FFL", TRUE, (M15="FFW")+(P15="FFW")+(S15="FFW")))) | J15: =IF(M15="", "", IF(COUNT(M15:N15, P15:Q15, S15:T15) > 0, (IF(ISNUMBER(M15)*ISNUMBER(N15), M15<N15, N15="FFW")) + (IF(ISNUMBER(P15)*ISNUMBER(Q15), P15<Q15, Q15="FFW")) + (IF(ISNUMBER(S15)*ISNUMBER(T15), S15<T15, T15="FFW")), IFS((N15="FFW")+(Q15="FFW")+(T15="FFW")>=2, "FFW", (N15="FFL")+(Q15="FFL")+(T15="FFL")>=2, "FFL", TRUE, (N15="FFW")+(Q15="FFW")+(T15="FFW")))) | K15: GREMIO
A16: Bo3 | B16: Group Stage | C16: Swiss Stage 1-0 | E16: 0.66666667 | F16: =E16+Data!$A$13 -> 0.875 | G16: ODDIK | H16: =IF(M16="", "", IF(COUNT(M16:N16, P16:Q16, S16:T16) > 0, (IF(ISNUMBER(M16)*ISNUMBER(N16), M16>N16, M16="FFW")) + (IF(ISNUMBER(P16)*ISNUMBER(Q16), P16>Q16, P16="FFW")) + (IF(ISNUMBER(S16)*ISNUMBER(T16), S16>T16, S16="FFW")), IFS((M16="FFW")+(P16="FFW")+(S16="FFW")>=2, "FFW", (M16="FFL")+(P16="FFL")+(S16="FFL")>=2, "FFL", TRUE, (M16="FFW")+(P16="FFW")+(S16="FFW")))) | J16: =IF(M16="", "", IF(COUNT(M16:N16, P16:Q16, S16:T16) > 0, (IF(ISNUMBER(M16)*ISNUMBER(N16), M16<N16, N16="FFW")) + (IF(ISNUMBER(P16)*ISNUMBER(Q16), P16<Q16, Q16="FFW")) + (IF(ISNUMBER(S16)*ISNUMBER(T16), S16<T16, T16="FFW")), IFS((N16="FFW")+(Q16="FFW")+(T16="FFW")>=2, "FFW", (N16="FFL")+(Q16="FFL")+(T16="FFL")>=2, "FFL", TRUE, (N16="FFW")+(Q16="FFW")+(T16="FFW")))) | K16: Procyon
A17: Bo3 | B17: Group Stage | C17: Swiss Stage 1-0 | E17: 0.79166667 | F17: =E17+Data!$A$13 -> 1 | G17: BESTIA Academy | H17: =IF(M17="", "", IF(COUNT(M17:N17, P17:Q17, S17:T17) > 0, (IF(ISNUMBER(M17)*ISNUMBER(N17), M17>N17, M17="FFW")) + (IF(ISNUMBER(P17)*ISNUMBER(Q17), P17>Q17, P17="FFW")) + (IF(ISNUMBER(S17)*ISNUMBER(T17), S17>T17, S17="FFW")), IFS((M17="FFW")+(P17="FFW")+(S17="FFW")>=2, "FFW", (M17="FFL")+(P17="FFL")+(S17="FFL")>=2, "FFL", TRUE, (M17="FFW")+(P17="FFW")+(S17="FFW")))) | J17: =IF(M17="", "", IF(COUNT(M17:N17, P17:Q17, S17:T17) > 0, (IF(ISNUMBER(M17)*ISNUMBER(N17), M17<N17, N17="FFW")) + (IF(ISNUMBER(P17)*ISNUMBER(Q17), P17<Q17, Q17="FFW")) + (IF(ISNUMBER(S17)*ISNUMBER(T17), S17<T17, T17="FFW")), IFS((N17="FFW")+(Q17="FFW")+(T17="FFW")>=2, "FFW", (N17="FFL")+(Q17="FFL")+(T17="FFL")>=2, "FFL", TRUE, (N17="FFW")+(Q17="FFW")+(T17="FFW")))) | K17: MAGICOS
A18: Bo3 | B18: Group Stage | C18: Swiss Stage 0-2 | D18: =D14+1 -> 46221 | E18: 0.41666667 | F18: =E18+Data!$A$13 -> 0.625 | H18: =IF(M18="", "", IF(COUNT(M18:N18, P18:Q18, S18:T18) > 0, (IF(ISNUMBER(M18)*ISNUMBER(N18), M18>N18, M18="FFW")) + (IF(ISNUMBER(P18)*ISNUMBER(Q18), P18>Q18, P18="FFW")) + (IF(ISNUMBER(S18)*ISNUMBER(T18), S18>T18, S18="FFW")), IFS((M18="FFW")+(P18="FFW")+(S18="FFW")>=2, "FFW", (M18="FFL")+(P18="FFL")+(S18="FFL")>=2, "FFL", TRUE, (M18="FFW")+(P18="FFW")+(S18="FFW")))) | J18: =IF(M18="", "", IF(COUNT(M18:N18, P18:Q18, S18:T18) > 0, (IF(ISNUMBER(M18)*ISNUMBER(N18), M18<N18, N18="FFW")) + (IF(ISNUMBER(P18)*ISNUMBER(Q18), P18<Q18, Q18="FFW")) + (IF(ISNUMBER(S18)*ISNUMBER(T18), S18<T18, T18="FFW")), IFS((N18="FFW")+(Q18="FFW")+(T18="FFW")>=2, "FFW", (N18="FFL")+(Q18="FFL")+(T18="FFL")>=2, "FFL", TRUE, (N18="FFW")+(Q18="FFW")+(T18="FFW"))))
A19: Bo3 | B19: Group Stage | C19: Swiss Stage 0-2 | E19: 0.54166667 | F19: =E19+Data!$A$13 -> 0.75 | H19: =IF(M19="", "", IF(COUNT(M19:N19, P19:Q19, S19:T19) > 0, (IF(ISNUMBER(M19)*ISNUMBER(N19), M19>N19, M19="FFW")) + (IF(ISNUMBER(P19)*ISNUMBER(Q19), P19>Q19, P19="FFW")) + (IF(ISNUMBER(S19)*ISNUMBER(T19), S19>T19, S19="FFW")), IFS((M19="FFW")+(P19="FFW")+(S19="FFW")>=2, "FFW", (M19="FFL")+(P19="FFL")+(S19="FFL")>=2, "FFL", TRUE, (M19="FFW")+(P19="FFW")+(S19="FFW")))) | J19: =IF(M19="", "", IF(COUNT(M19:N19, P19:Q19, S19:T19) > 0, (IF(ISNUMBER(M19)*ISNUMBER(N19), M19<N19, N19="FFW")) + (IF(ISNUMBER(P19)*ISNUMBER(Q19), P19<Q19, Q19="FFW")) + (IF(ISNUMBER(S19)*ISNUMBER(T19), S19<T19, T19="FFW")), IFS((N19="FFW")+(Q19="FFW")+(T19="FFW")>=2, "FFW", (N19="FFL")+(Q19="FFL")+(T19="FFL")>=2, "FFL", TRUE, (N19="FFW")+(Q19="FFW")+(T19="FFW"))))
A20: Bo3 | B20: Group Stage | C20: Swiss Stage 1-1 | E20: 0.66666667 | F20: =E20+Data!$A$13 -> 0.875 | H20: =IF(M20="", "", IF(COUNT(M20:N20, P20:Q20, S20:T20) > 0, (IF(ISNUMBER(M20)*ISNUMBER(N20), M20>N20, M20="FFW")) + (IF(ISNUMBER(P20)*ISNUMBER(Q20), P20>Q20, P20="FFW")) + (IF(ISNUMBER(S20)*ISNUMBER(T20), S20>T20, S20="FFW")), IFS((M20="FFW")+(P20="FFW")+(S20="FFW")>=2, "FFW", (M20="FFL")+(P20="FFL")+(S20="FFL")>=2, "FFL", TRUE, (M20="FFW")+(P20="FFW")+(S20="FFW")))) | J20: =IF(M20="", "", IF(COUNT(M20:N20, P20:Q20, S20:T20) > 0, (IF(ISNUMBER(M20)*ISNUMBER(N20), M20<N20, N20="FFW")) + (IF(ISNUMBER(P20)*ISNUMBER(Q20), P20<Q20, Q20="FFW")) + (IF(ISNUMBER(S20)*ISNUMBER(T20), S20<T20, T20="FFW")), IFS((N20="FFW")+(Q20="FFW")+(T20="FFW")>=2, "FFW", (N20="FFL")+(Q20="FFL")+(T20="FFL")>=2, "FFL", TRUE, (N20="FFW")+(Q20="FFW")+(T20="FFW"))))
A21: Bo3 | B21: Group Stage | C21: Swiss Stage 1-1 | E21: 0.79166667 | F21: =E21+Data!$A$13 -> 1 | H21: =IF(M21="", "", IF(COUNT(M21:N21, P21:Q21, S21:T21) > 0, (IF(ISNUMBER(M21)*ISNUMBER(N21), M21>N21, M21="FFW")) + (IF(ISNUMBER(P21)*ISNUMBER(Q21), P21>Q21, P21="FFW")) + (IF(ISNUMBER(S21)*ISNUMBER(T21), S21>T21, S21="FFW")), IFS((M21="FFW")+(P21="FFW")+(S21="FFW")>=2, "FFW", (M21="FFL")+(P21="FFL")+(S21="FFL")>=2, "FFL", TRUE, (M21="FFW")+(P21="FFW")+(S21="FFW")))) | J21: =IF(M21="", "", IF(COUNT(M21:N21, P21:Q21, S21:T21) > 0, (IF(ISNUMBER(M21)*ISNUMBER(N21), M21<N21, N21="FFW")) + (IF(ISNUMBER(P21)*ISNUMBER(Q21), P21<Q21, Q21="FFW")) + (IF(ISNUMBER(S21)*ISNUMBER(T21), S21<T21, T21="FFW")), IFS((N21="FFW")+(Q21="FFW")+(T21="FFW")>=2, "FFW", (N21="FFL")+(Q21="FFL")+(T21="FFL")>=2, "FFL", TRUE, (N21="FFW")+(Q21="FFW")+(T21="FFW"))))
A22: Bo3 | B22: Group Stage | C22: Swiss Stage 1-1 | D22: =D18+1 -> 46222 | E22: 0.41666667 | F22: =E22+Data!$A$13 -> 0.625 | H22: =IF(M22="", "", IF(COUNT(M22:N22, P22:Q22, S22:T22) > 0, (IF(ISNUMBER(M22)*ISNUMBER(N22), M22>N22, M22="FFW")) + (IF(ISNUMBER(P22)*ISNUMBER(Q22), P22>Q22, P22="FFW")) + (IF(ISNUMBER(S22)*ISNUMBER(T22), S22>T22, S22="FFW")), IFS((M22="FFW")+(P22="FFW")+(S22="FFW")>=2, "FFW", (M22="FFL")+(P22="FFL")+(S22="FFL")>=2, "FFL", TRUE, (M22="FFW")+(P22="FFW")+(S22="FFW")))) | J22: =IF(M22="", "", IF(COUNT(M22:N22, P22:Q22, S22:T22) > 0, (IF(ISNUMBER(M22)*ISNUMBER(N22), M22<N22, N22="FFW")) + (IF(ISNUMBER(P22)*ISNUMBER(Q22), P22<Q22, Q22="FFW")) + (IF(ISNUMBER(S22)*ISNUMBER(T22), S22<T22, T22="FFW")), IFS((N22="FFW")+(Q22="FFW")+(T22="FFW")>=2, "FFW", (N22="FFL")+(Q22="FFL")+(T22="FFL")>=2, "FFL", TRUE, (N22="FFW")+(Q22="FFW")+(T22="FFW"))))
A23: Bo3 | B23: Group Stage | C23: Swiss Stage 1-1 | E23: 0.54166667 | F23: =E23+Data!$A$13 -> 0.75 | H23: =IF(M23="", "", IF(COUNT(M23:N23, P23:Q23, S23:T23) > 0, (IF(ISNUMBER(M23)*ISNUMBER(N23), M23>N23, M23="FFW")) + (IF(ISNUMBER(P23)*ISNUMBER(Q23), P23>Q23, P23="FFW")) + (IF(ISNUMBER(S23)*ISNUMBER(T23), S23>T23, S23="FFW")), IFS((M23="FFW")+(P23="FFW")+(S23="FFW")>=2, "FFW", (M23="FFL")+(P23="FFL")+(S23="FFL")>=2, "FFL", TRUE, (M23="FFW")+(P23="FFW")+(S23="FFW")))) | J23: =IF(M23="", "", IF(COUNT(M23:N23, P23:Q23, S23:T23) > 0, (IF(ISNUMBER(M23)*ISNUMBER(N23), M23<N23, N23="FFW")) + (IF(ISNUMBER(P23)*ISNUMBER(Q23), P23<Q23, Q23="FFW")) + (IF(ISNUMBER(S23)*ISNUMBER(T23), S23<T23, T23="FFW")), IFS((N23="FFW")+(Q23="FFW")+(T23="FFW")>=2, "FFW", (N23="FFL")+(Q23="FFL")+(T23="FFL")>=2, "FFL", TRUE, (N23="FFW")+(Q23="FFW")+(T23="FFW"))))
A24: Bo3 | B24: Group Stage | C24: Swiss Stage 2-0 | E24: 0.66666667 | F24: =E24+Data!$A$13 -> 0.875 | H24: =IF(M24="", "", IF(COUNT(M24:N24, P24:Q24, S24:T24) > 0, (IF(ISNUMBER(M24)*ISNUMBER(N24), M24>N24, M24="FFW")) + (IF(ISNUMBER(P24)*ISNUMBER(Q24), P24>Q24, P24="FFW")) + (IF(ISNUMBER(S24)*ISNUMBER(T24), S24>T24, S24="FFW")), IFS((M24="FFW")+(P24="FFW")+(S24="FFW")>=2, "FFW", (M24="FFL")+(P24="FFL")+(S24="FFL")>=2, "FFL", TRUE, (M24="FFW")+(P24="FFW")+(S24="FFW")))) | J24: =IF(M24="", "", IF(COUNT(M24:N24, P24:Q24, S24:T24) > 0, (IF(ISNUMBER(M24)*ISNUMBER(N24), M24<N24, N24="FFW")) + (IF(ISNUMBER(P24)*ISNUMBER(Q24), P24<Q24, Q24="FFW")) + (IF(ISNUMBER(S24)*ISNUMBER(T24), S24<T24, T24="FFW")), IFS((N24="FFW")+(Q24="FFW")+(T24="FFW")>=2, "FFW", (N24="FFL")+(Q24="FFL")+(T24="FFL")>=2, "FFL", TRUE, (N24="FFW")+(Q24="FFW")+(T24="FFW"))))
A25: Bo3 | B25: Group Stage | C25: Swiss Stage 2-0 | E25: 0.79166667 | F25: =E25+Data!$A$13 -> 1 | H25: =IF(M25="", "", IF(COUNT(M25:N25, P25:Q25, S25:T25) > 0, (IF(ISNUMBER(M25)*ISNUMBER(N25), M25>N25, M25="FFW")) + (IF(ISNUMBER(P25)*ISNUMBER(Q25), P25>Q25, P25="FFW")) + (IF(ISNUMBER(S25)*ISNUMBER(T25), S25>T25, S25="FFW")), IFS((M25="FFW")+(P25="FFW")+(S25="FFW")>=2, "FFW", (M25="FFL")+(P25="FFL")+(S25="FFL")>=2, "FFL", TRUE, (M25="FFW")+(P25="FFW")+(S25="FFW")))) | J25: =IF(M25="", "", IF(COUNT(M25:N25, P25:Q25, S25:T25) > 0, (IF(ISNUMBER(M25)*ISNUMBER(N25), M25<N25, N25="FFW")) + (IF(ISNUMBER(P25)*ISNUMBER(Q25), P25<Q25, Q25="FFW")) + (IF(ISNUMBER(S25)*ISNUMBER(T25), S25<T25, T25="FFW")), IFS((N25="FFW")+(Q25="FFW")+(T25="FFW")>=2, "FFW", (N25="FFL")+(Q25="FFL")+(T25="FFL")>=2, "FFL", TRUE, (N25="FFW")+(Q25="FFW")+(T25="FFW"))))
A26: Bo3 | B26: Group Stage | C26: Swiss Stage 1-2 | D26: =D22+1 -> 46223 | E26: 0.54166667 | F26: =E26+Data!$A$13 -> 0.75 | H26: =IF(M26="", "", IF(COUNT(M26:N26, P26:Q26, S26:T26) > 0, (IF(ISNUMBER(M26)*ISNUMBER(N26), M26>N26, M26="FFW")) + (IF(ISNUMBER(P26)*ISNUMBER(Q26), P26>Q26, P26="FFW")) + (IF(ISNUMBER(S26)*ISNUMBER(T26), S26>T26, S26="FFW")), IFS((M26="FFW")+(P26="FFW")+(S26="FFW")>=2, "FFW", (M26="FFL")+(P26="FFL")+(S26="FFL")>=2, "FFL", TRUE, (M26="FFW")+(P26="FFW")+(S26="FFW")))) | J26: =IF(M26="", "", IF(COUNT(M26:N26, P26:Q26, S26:T26) > 0, (IF(ISNUMBER(M26)*ISNUMBER(N26), M26<N26, N26="FFW")) + (IF(ISNUMBER(P26)*ISNUMBER(Q26), P26<Q26, Q26="FFW")) + (IF(ISNUMBER(S26)*ISNUMBER(T26), S26<T26, T26="FFW")), IFS((N26="FFW")+(Q26="FFW")+(T26="FFW")>=2, "FFW", (N26="FFL")+(Q26="FFL")+(T26="FFL")>=2, "FFL", TRUE, (N26="FFW")+(Q26="FFW")+(T26="FFW"))))
A27: Bo3 | B27: Group Stage | C27: Swiss Stage 1-2 | E27: 0.66666667 | F27: =E27+Data!$A$13 -> 0.875 | H27: =IF(M27="", "", IF(COUNT(M27:N27, P27:Q27, S27:T27) > 0, (IF(ISNUMBER(M27)*ISNUMBER(N27), M27>N27, M27="FFW")) + (IF(ISNUMBER(P27)*ISNUMBER(Q27), P27>Q27, P27="FFW")) + (IF(ISNUMBER(S27)*ISNUMBER(T27), S27>T27, S27="FFW")), IFS((M27="FFW")+(P27="FFW")+(S27="FFW")>=2, "FFW", (M27="FFL")+(P27="FFL")+(S27="FFL")>=2, "FFL", TRUE, (M27="FFW")+(P27="FFW")+(S27="FFW")))) | J27: =IF(M27="", "", IF(COUNT(M27:N27, P27:Q27, S27:T27) > 0, (IF(ISNUMBER(M27)*ISNUMBER(N27), M27<N27, N27="FFW")) + (IF(ISNUMBER(P27)*ISNUMBER(Q27), P27<Q27, Q27="FFW")) + (IF(ISNUMBER(S27)*ISNUMBER(T27), S27<T27, T27="FFW")), IFS((N27="FFW")+(Q27="FFW")+(T27="FFW")>=2, "FFW", (N27="FFL")+(Q27="FFL")+(T27="FFL")>=2, "FFL", TRUE, (N27="FFW")+(Q27="FFW")+(T27="FFW"))))
A28: Bo3 | B28: Group Stage | C28: Swiss Stage 1-2 | E28: 0.79166667 | F28: =E28+Data!$A$13 -> 1 | H28: =IF(M28="", "", IF(COUNT(M28:N28, P28:Q28, S28:T28) > 0, (IF(ISNUMBER(M28)*ISNUMBER(N28), M28>N28, M28="FFW")) + (IF(ISNUMBER(P28)*ISNUMBER(Q28), P28>Q28, P28="FFW")) + (IF(ISNUMBER(S28)*ISNUMBER(T28), S28>T28, S28="FFW")), IFS((M28="FFW")+(P28="FFW")+(S28="FFW")>=2, "FFW", (M28="FFL")+(P28="FFL")+(S28="FFL")>=2, "FFL", TRUE, (M28="FFW")+(P28="FFW")+(S28="FFW")))) | J28: =IF(M28="", "", IF(COUNT(M28:N28, P28:Q28, S28:T28) > 0, (IF(ISNUMBER(M28)*ISNUMBER(N28), M28<N28, N28="FFW")) + (IF(ISNUMBER(P28)*ISNUMBER(Q28), P28<Q28, Q28="FFW")) + (IF(ISNUMBER(S28)*ISNUMBER(T28), S28<T28, T28="FFW")), IFS((N28="FFW")+(Q28="FFW")+(T28="FFW")>=2, "FFW", (N28="FFL")+(Q28="FFL")+(T28="FFL")>=2, "FFL", TRUE, (N28="FFW")+(Q28="FFW")+(T28="FFW"))))
A29: Bo3 | B29: Group Stage | C29: Swiss Stage 2-1 | D29: =D26+1 -> 46224 | E29: 0.54166667 | F29: =E29+Data!$A$13 -> 0.75 | H29: =IF(M29="", "", IF(COUNT(M29:N29, P29:Q29, S29:T29) > 0, (IF(ISNUMBER(M29)*ISNUMBER(N29), M29>N29, M29="FFW")) + (IF(ISNUMBER(P29)*ISNUMBER(Q29), P29>Q29, P29="FFW")) + (IF(ISNUMBER(S29)*ISNUMBER(T29), S29>T29, S29="FFW")), IFS((M29="FFW")+(P29="FFW")+(S29="FFW")>=2, "FFW", (M29="FFL")+(P29="FFL")+(S29="FFL")>=2, "FFL", TRUE, (M29="FFW")+(P29="FFW")+(S29="FFW")))) | J29: =IF(M29="", "", IF(COUNT(M29:N29, P29:Q29, S29:T29) > 0, (IF(ISNUMBER(M29)*ISNUMBER(N29), M29<N29, N29="FFW")) + (IF(ISNUMBER(P29)*ISNUMBER(Q29), P29<Q29, Q29="FFW")) + (IF(ISNUMBER(S29)*ISNUMBER(T29), S29<T29, T29="FFW")), IFS((N29="FFW")+(Q29="FFW")+(T29="FFW")>=2, "FFW", (N29="FFL")+(Q29="FFL")+(T29="FFL")>=2, "FFL", TRUE, (N29="FFW")+(Q29="FFW")+(T29="FFW"))))
A30: Bo3 | B30: Group Stage | C30: Swiss Stage 2-1 | E30: 0.66666667 | F30: =E30+Data!$A$13 -> 0.875 | H30: =IF(M30="", "", IF(COUNT(M30:N30, P30:Q30, S30:T30) > 0, (IF(ISNUMBER(M30)*ISNUMBER(N30), M30>N30, M30="FFW")) + (IF(ISNUMBER(P30)*ISNUMBER(Q30), P30>Q30, P30="FFW")) + (IF(ISNUMBER(S30)*ISNUMBER(T30), S30>T30, S30="FFW")), IFS((M30="FFW")+(P30="FFW")+(S30="FFW")>=2, "FFW", (M30="FFL")+(P30="FFL")+(S30="FFL")>=2, "FFL", TRUE, (M30="FFW")+(P30="FFW")+(S30="FFW")))) | J30: =IF(M30="", "", IF(COUNT(M30:N30, P30:Q30, S30:T30) > 0, (IF(ISNUMBER(M30)*ISNUMBER(N30), M30<N30, N30="FFW")) + (IF(ISNUMBER(P30)*ISNUMBER(Q30), P30<Q30, Q30="FFW")) + (IF(ISNUMBER(S30)*ISNUMBER(T30), S30<T30, T30="FFW")), IFS((N30="FFW")+(Q30="FFW")+(T30="FFW")>=2, "FFW", (N30="FFL")+(Q30="FFL")+(T30="FFL")>=2, "FFL", TRUE, (N30="FFW")+(Q30="FFW")+(T30="FFW"))))
A31: Bo3 | B31: Group Stage | C31: Swiss Stage 2-1 | E31: 0.79166667 | F31: =E31+Data!$A$13 -> 1 | H31: =IF(M31="", "", IF(COUNT(M31:N31, P31:Q31, S31:T31) > 0, (IF(ISNUMBER(M31)*ISNUMBER(N31), M31>N31, M31="FFW")) + (IF(ISNUMBER(P31)*ISNUMBER(Q31), P31>Q31, P31="FFW")) + (IF(ISNUMBER(S31)*ISNUMBER(T31), S31>T31, S31="FFW")), IFS((M31="FFW")+(P31="FFW")+(S31="FFW")>=2, "FFW", (M31="FFL")+(P31="FFL")+(S31="FFL")>=2, "FFL", TRUE, (M31="FFW")+(P31="FFW")+(S31="FFW")))) | J31: =IF(M31="", "", IF(COUNT(M31:N31, P31:Q31, S31:T31) > 0, (IF(ISNUMBER(M31)*ISNUMBER(N31), M31<N31, N31="FFW")) + (IF(ISNUMBER(P31)*ISNUMBER(Q31), P31<Q31, Q31="FFW")) + (IF(ISNUMBER(S31)*ISNUMBER(T31), S31<T31, T31="FFW")), IFS((N31="FFW")+(Q31="FFW")+(T31="FFW")>=2, "FFW", (N31="FFL")+(Q31="FFL")+(T31="FFL")>=2, "FFL", TRUE, (N31="FFW")+(Q31="FFW")+(T31="FFW"))))
A32: Bo3 | B32: Group Stage | C32: Swiss Stage 2-2 | D32: =D29+1 -> 46225 | E32: 0.54166667 | F32: =E32+Data!$A$13 -> 0.75 | H32: =IF(M32="", "", IF(COUNT(M32:N32, P32:Q32, S32:T32) > 0, (IF(ISNUMBER(M32)*ISNUMBER(N32), M32>N32, M32="FFW")) + (IF(ISNUMBER(P32)*ISNUMBER(Q32), P32>Q32, P32="FFW")) + (IF(ISNUMBER(S32)*ISNUMBER(T32), S32>T32, S32="FFW")), IFS((M32="FFW")+(P32="FFW")+(S32="FFW")>=2, "FFW", (M32="FFL")+(P32="FFL")+(S32="FFL")>=2, "FFL", TRUE, (M32="FFW")+(P32="FFW")+(S32="FFW")))) | J32: =IF(M32="", "", IF(COUNT(M32:N32, P32:Q32, S32:T32) > 0, (IF(ISNUMBER(M32)*ISNUMBER(N32), M32<N32, N32="FFW")) + (IF(ISNUMBER(P32)*ISNUMBER(Q32), P32<Q32, Q32="FFW")) + (IF(ISNUMBER(S32)*ISNUMBER(T32), S32<T32, T32="FFW")), IFS((N32="FFW")+(Q32="FFW")+(T32="FFW")>=2, "FFW", (N32="FFL")+(Q32="FFL")+(T32="FFL")>=2, "FFL", TRUE, (N32="FFW")+(Q32="FFW")+(T32="FFW"))))
A33: Bo3 | B33: Group Stage | C33: Swiss Stage 2-2 | E33: 0.66666667 | F33: =E33+Data!$A$13 -> 0.875 | H33: =IF(M33="", "", IF(COUNT(M33:N33, P33:Q33, S33:T33) > 0, (IF(ISNUMBER(M33)*ISNUMBER(N33), M33>N33, M33="FFW")) + (IF(ISNUMBER(P33)*ISNUMBER(Q33), P33>Q33, P33="FFW")) + (IF(ISNUMBER(S33)*ISNUMBER(T33), S33>T33, S33="FFW")), IFS((M33="FFW")+(P33="FFW")+(S33="FFW")>=2, "FFW", (M33="FFL")+(P33="FFL")+(S33="FFL")>=2, "FFL", TRUE, (M33="FFW")+(P33="FFW")+(S33="FFW")))) | J33: =IF(M33="", "", IF(COUNT(M33:N33, P33:Q33, S33:T33) > 0, (IF(ISNUMBER(M33)*ISNUMBER(N33), M33<N33, N33="FFW")) + (IF(ISNUMBER(P33)*ISNUMBER(Q33), P33<Q33, Q33="FFW")) + (IF(ISNUMBER(S33)*ISNUMBER(T33), S33<T33, T33="FFW")), IFS((N33="FFW")+(Q33="FFW")+(T33="FFW")>=2, "FFW", (N33="FFL")+(Q33="FFL")+(T33="FFL")>=2, "FFL", TRUE, (N33="FFW")+(Q33="FFW")+(T33="FFW"))))
A34: Bo3 | B34: Group Stage | C34: Swiss Stage 2-2 | E34: 0.79166667 | F34: =E34+Data!$A$13 -> 1 | H34: =IF(M34="", "", IF(COUNT(M34:N34, P34:Q34, S34:T34) > 0, (IF(ISNUMBER(M34)*ISNUMBER(N34), M34>N34, M34="FFW")) + (IF(ISNUMBER(P34)*ISNUMBER(Q34), P34>Q34, P34="FFW")) + (IF(ISNUMBER(S34)*ISNUMBER(T34), S34>T34, S34="FFW")), IFS((M34="FFW")+(P34="FFW")+(S34="FFW")>=2, "FFW", (M34="FFL")+(P34="FFL")+(S34="FFL")>=2, "FFL", TRUE, (M34="FFW")+(P34="FFW")+(S34="FFW")))) | J34: =IF(M34="", "", IF(COUNT(M34:N34, P34:Q34, S34:T34) > 0, (IF(ISNUMBER(M34)*ISNUMBER(N34), M34<N34, N34="FFW")) + (IF(ISNUMBER(P34)*ISNUMBER(Q34), P34<Q34, Q34="FFW")) + (IF(ISNUMBER(S34)*ISNUMBER(T34), S34<T34, T34="FFW")), IFS((N34="FFW")+(Q34="FFW")+(T34="FFW")>=2, "FFW", (N34="FFL")+(Q34="FFL")+(T34="FFL")>=2, "FFL", TRUE, (N34="FFW")+(Q34="FFW")+(T34="FFW"))))
A35: Bo3 | B35: Playoffs | C35: Round of 16 | D35: =D32+1 -> 46226 | E35: 0.41666667 | F35: =E35+Data!$A$13 -> 0.625 | H35: =IF(M35="", "", IF(COUNT(M35:N35, P35:Q35, S35:T35) > 0, (IF(ISNUMBER(M35)*ISNUMBER(N35), M35>N35, M35="FFW")) + (IF(ISNUMBER(P35)*ISNUMBER(Q35), P35>Q35, P35="FFW")) + (IF(ISNUMBER(S35)*ISNUMBER(T35), S35>T35, S35="FFW")), IFS((M35="FFW")+(P35="FFW")+(S35="FFW")>=2, "FFW", (M35="FFL")+(P35="FFL")+(S35="FFL")>=2, "FFL", TRUE, (M35="FFW")+(P35="FFW")+(S35="FFW")))) | J35: =IF(M35="", "", IF(COUNT(M35:N35, P35:Q35, S35:T35) > 0, (IF(ISNUMBER(M35)*ISNUMBER(N35), M35<N35, N35="FFW")) + (IF(ISNUMBER(P35)*ISNUMBER(Q35), P35<Q35, Q35="FFW")) + (IF(ISNUMBER(S35)*ISNUMBER(T35), S35<T35, T35="FFW")), IFS((N35="FFW")+(Q35="FFW")+(T35="FFW")>=2, "FFW", (N35="FFL")+(Q35="FFL")+(T35="FFL")>=2, "FFL", TRUE, (N35="FFW")+(Q35="FFW")+(T35="FFW"))))
A36: Bo3 | B36: Playoffs | C36: Round of 16 | E36: 0.54166667 | F36: =E36+Data!$A$13 -> 0.75 | H36: =IF(M36="", "", IF(COUNT(M36:N36, P36:Q36, S36:T36) > 0, (IF(ISNUMBER(M36)*ISNUMBER(N36), M36>N36, M36="FFW")) + (IF(ISNUMBER(P36)*ISNUMBER(Q36), P36>Q36, P36="FFW")) + (IF(ISNUMBER(S36)*ISNUMBER(T36), S36>T36, S36="FFW")), IFS((M36="FFW")+(P36="FFW")+(S36="FFW")>=2, "FFW", (M36="FFL")+(P36="FFL")+(S36="FFL")>=2, "FFL", TRUE, (M36="FFW")+(P36="FFW")+(S36="FFW")))) | J36: =IF(M36="", "", IF(COUNT(M36:N36, P36:Q36, S36:T36) > 0, (IF(ISNUMBER(M36)*ISNUMBER(N36), M36<N36, N36="FFW")) + (IF(ISNUMBER(P36)*ISNUMBER(Q36), P36<Q36, Q36="FFW")) + (IF(ISNUMBER(S36)*ISNUMBER(T36), S36<T36, T36="FFW")), IFS((N36="FFW")+(Q36="FFW")+(T36="FFW")>=2, "FFW", (N36="FFL")+(Q36="FFL")+(T36="FFL")>=2, "FFL", TRUE, (N36="FFW")+(Q36="FFW")+(T36="FFW"))))
A37: Bo3 | B37: Playoffs | C37: Round of 16 | E37: 0.66666667 | F37: =E37+Data!$A$13 -> 0.875 | H37: =IF(M37="", "", IF(COUNT(M37:N37, P37:Q37, S37:T37) > 0, (IF(ISNUMBER(M37)*ISNUMBER(N37), M37>N37, M37="FFW")) + (IF(ISNUMBER(P37)*ISNUMBER(Q37), P37>Q37, P37="FFW")) + (IF(ISNUMBER(S37)*ISNUMBER(T37), S37>T37, S37="FFW")), IFS((M37="FFW")+(P37="FFW")+(S37="FFW")>=2, "FFW", (M37="FFL")+(P37="FFL")+(S37="FFL")>=2, "FFL", TRUE, (M37="FFW")+(P37="FFW")+(S37="FFW")))) | J37: =IF(M37="", "", IF(COUNT(M37:N37, P37:Q37, S37:T37) > 0, (IF(ISNUMBER(M37)*ISNUMBER(N37), M37<N37, N37="FFW")) + (IF(ISNUMBER(P37)*ISNUMBER(Q37), P37<Q37, Q37="FFW")) + (IF(ISNUMBER(S37)*ISNUMBER(T37), S37<T37, T37="FFW")), IFS((N37="FFW")+(Q37="FFW")+(T37="FFW")>=2, "FFW", (N37="FFL")+(Q37="FFL")+(T37="FFL")>=2, "FFL", TRUE, (N37="FFW")+(Q37="FFW")+(T37="FFW"))))
A38: Bo3 | B38: Playoffs | C38: Round of 16 | E38: 0.79166667 | F38: =E38+Data!$A$13 -> 1 | H38: =IF(M38="", "", IF(COUNT(M38:N38, P38:Q38, S38:T38) > 0, (IF(ISNUMBER(M38)*ISNUMBER(N38), M38>N38, M38="FFW")) + (IF(ISNUMBER(P38)*ISNUMBER(Q38), P38>Q38, P38="FFW")) + (IF(ISNUMBER(S38)*ISNUMBER(T38), S38>T38, S38="FFW")), IFS((M38="FFW")+(P38="FFW")+(S38="FFW")>=2, "FFW", (M38="FFL")+(P38="FFL")+(S38="FFL")>=2, "FFL", TRUE, (M38="FFW")+(P38="FFW")+(S38="FFW")))) | J38: =IF(M38="", "", IF(COUNT(M38:N38, P38:Q38, S38:T38) > 0, (IF(ISNUMBER(M38)*ISNUMBER(N38), M38<N38, N38="FFW")) + (IF(ISNUMBER(P38)*ISNUMBER(Q38), P38<Q38, Q38="FFW")) + (IF(ISNUMBER(S38)*ISNUMBER(T38), S38<T38, T38="FFW")), IFS((N38="FFW")+(Q38="FFW")+(T38="FFW")>=2, "FFW", (N38="FFL")+(Q38="FFL")+(T38="FFL")>=2, "FFL", TRUE, (N38="FFW")+(Q38="FFW")+(T38="FFW"))))
A39: Bo3 | B39: Playoffs | C39: Round of 16 | D39: =D35+1 -> 46227 | E39: 0.41666667 | F39: =E39+Data!$A$13 -> 0.625 | H39: =IF(M39="", "", IF(COUNT(M39:N39, P39:Q39, S39:T39) > 0, (IF(ISNUMBER(M39)*ISNUMBER(N39), M39>N39, M39="FFW")) + (IF(ISNUMBER(P39)*ISNUMBER(Q39), P39>Q39, P39="FFW")) + (IF(ISNUMBER(S39)*ISNUMBER(T39), S39>T39, S39="FFW")), IFS((M39="FFW")+(P39="FFW")+(S39="FFW")>=2, "FFW", (M39="FFL")+(P39="FFL")+(S39="FFL")>=2, "FFL", TRUE, (M39="FFW")+(P39="FFW")+(S39="FFW")))) | J39: =IF(M39="", "", IF(COUNT(M39:N39, P39:Q39, S39:T39) > 0, (IF(ISNUMBER(M39)*ISNUMBER(N39), M39<N39, N39="FFW")) + (IF(ISNUMBER(P39)*ISNUMBER(Q39), P39<Q39, Q39="FFW")) + (IF(ISNUMBER(S39)*ISNUMBER(T39), S39<T39, T39="FFW")), IFS((N39="FFW")+(Q39="FFW")+(T39="FFW")>=2, "FFW", (N39="FFL")+(Q39="FFL")+(T39="FFL")>=2, "FFL", TRUE, (N39="FFW")+(Q39="FFW")+(T39="FFW"))))
A40: Bo3 | B40: Playoffs | C40: Round of 16 | E40: 0.54166667 | F40: =E40+Data!$A$13 -> 0.75 | H40: =IF(M40="", "", IF(COUNT(M40:N40, P40:Q40, S40:T40) > 0, (IF(ISNUMBER(M40)*ISNUMBER(N40), M40>N40, M40="FFW")) + (IF(ISNUMBER(P40)*ISNUMBER(Q40), P40>Q40, P40="FFW")) + (IF(ISNUMBER(S40)*ISNUMBER(T40), S40>T40, S40="FFW")), IFS((M40="FFW")+(P40="FFW")+(S40="FFW")>=2, "FFW", (M40="FFL")+(P40="FFL")+(S40="FFL")>=2, "FFL", TRUE, (M40="FFW")+(P40="FFW")+(S40="FFW")))) | J40: =IF(M40="", "", IF(COUNT(M40:N40, P40:Q40, S40:T40) > 0, (IF(ISNUMBER(M40)*ISNUMBER(N40), M40<N40, N40="FFW")) + (IF(ISNUMBER(P40)*ISNUMBER(Q40), P40<Q40, Q40="FFW")) + (IF(ISNUMBER(S40)*ISNUMBER(T40), S40<T40, T40="FFW")), IFS((N40="FFW")+(Q40="FFW")+(T40="FFW")>=2, "FFW", (N40="FFL")+(Q40="FFL")+(T40="FFL")>=2, "FFL", TRUE, (N40="FFW")+(Q40="FFW")+(T40="FFW"))))
...

Sheet Data
A1: Invite | B1: Stage | C1: Match | D1: Best Of
A2: Europe VRS | B2: Playoffs | C2: Group A_Opener | D2: Bo1
A3: Global VRS | B3: Group Stage | C3: Group B_Opener | D3: Bo3
A4: South America VRS | B4: Play-Ins | C4: Group A_Winner Match | D4: Bo5
A5: North America VRS | C5: Group A_Loser Match
A6: Oceania VRS | C6: Group B_Winner Match
A7: Wildcard Slot | C7: Group B_Loser Match
A8: Open Qualifier Slot | C8: Group A_Decider
C9: Group B_Decider
C10: Group C_Opener
C11: Group D_Opener
A12: Timezone | C12: Group C_Winner Match
A13: 0.20833333 | C13: Group D_Winner Match
C14: Group C_Loser Match
C15: Group D_Loser Match
C16: Group C_Decider
C17: Group D_Decider
C18: Play-ins Decider
C19: Swiss Stage 0-0
C20: Swiss Stage 0-1
C21: Swiss Stage 1-0
C22: Swiss Stage 0-2
C23: Swiss Stage 1-1
C24: Swiss Stage 2-0
C25: Swiss Stage 1-2
... C31: Grand Final
