Workbook

Sheet Tournament Information
A1: =IFERROR(__xludf.DUMMYFUNCTION("if('Make Public'!C7=""Yes"",importrange('Make Public'!B3,""Tournament Information!A1:n""),""TBD"")"),"")
B2: =IFERROR(__xludf.DUMMYFUNCTION("""COMPUTED_VALUE"""),"Format") -> Format | D2: =IFERROR(__xludf.DUMMYFUNCTION("""COMPUTED_VALUE"""),"Quick Facts") -> Quick Facts | G2: =IFERROR(__xludf.DUMMYFUNCTION("""COMPUTED_VALUE"""),"Prize Money") -> Prize Money | K2: =IFERROR(__xludf.DUMMYFUNCTION("""COMPUTED_VALUE"""),"FAQ") -> FAQ
B3: =IFERROR(__xludf.DUMMYFUNCTION("""COMPUTED_VALUE"""),"Stage 1: Group Stage") -> Stage 1: Group Stage | D3: =IFERROR(__xludf.DUMMYFUNCTION("""COMPUTED_VALUE"""),"Tournament Days (without breaks)") -> Tournament Days (without breaks) | E3: =IFERROR(__xludf.DUMMYFUNCTION("""COMPUTED_VALUE"""),12.0) -> 12 | G3: =IFERROR(__xludf.DUMMYFUNCTION("""COMPUTED_VALUE"""),"#") -> # | H3: =IFERROR(__xludf.DUMMYFUNCTION("""COMPUTED_VALUE"""),"Prize") -> Prize | I3: =IFERROR(__xludf.DUMMYFUNCTION("""COMPUTED_VALUE"""),"Team") -> Team
B4: =IFERROR(__xludf.DUMMYFUNCTION("""COMPUTED_VALUE"""),"24 teams (24 Qualified)") -> 24 teams (24 Qualified) | D4: =IFERROR(__xludf.DUMMYFUNCTION("""COMPUTED_VALUE"""),"Tournament Days (with breaks)") -> Tournament Days (with breaks) | E4: =IFERROR(__xludf.DUMMYFUNCTION("""COMPUTED_VALUE"""),13.0) -> 13 | G4: =IFERROR(__xludf.DUMMYFUNCTION("""COMPUTED_VALUE"""),"Total:") -> Total: | H4: =IFERROR(__xludf.DUMMYFUNCTION("""COMPUTED_VALUE"""),2000000.0) -> 2000000 | K4: =IFERROR(__xludf.DUMMYFUNCTION("""COMPUTED_VALUE"""),"Match Breaks") -> Match Breaks | N4: =IFERROR(__xludf.DUMMYFUNCTION("""COMPUTED_VALUE"""),"Draft Procedure") -> Draft Procedure
G5: =IFERROR(__xludf.DUMMYFUNCTION("""COMPUTED_VALUE"""),1.0) -> 1 | H5: =IFERROR(__xludf.DUMMYFUNCTION("""COMPUTED_VALUE"""),750000.0) -> 750000 | K5: =IFERROR(__xludf.DUMMYFUNCTION("""COMPUTED_VALUE"""),"Break between maps") -> Break between maps | L5: =IFERROR(__xludf.DUMMYFUNCTION("""COMPUTED_VALUE"""),"15 minutes") -> 15 minutes | N5: =IFERROR(__xludf.DUMMYFUNCTION("""COMPUTED_VALUE"""),"This example assumes Radiant is the startng team. Invert teams if Dire is the starting team.") -> This example assumes Radiant is the startng team. Invert teams if Dire is the starting team.
B6: =IFERROR(__xludf.DUMMYFUNCTION("""COMPUTED_VALUE"""),"4 Group of 6 Teams") -> 4 Group of 6 Teams | D6: =IFERROR(__xludf.DUMMYFUNCTION("""COMPUTED_VALUE"""),"Players Arrival Date") -> Players Arrival Date | E6: =IFERROR(__xludf.DUMMYFUNCTION("""COMPUTED_VALUE"""),46208.0) -> 46208 | G6: =IFERROR(__xludf.DUMMYFUNCTION("""COMPUTED_VALUE"""),2.0) -> 2 | H6: =IFERROR(__xludf.DUMMYFUNCTION("""COMPUTED_VALUE"""),340000.0) -> 340000 | K6: =IFERROR(__xludf.DUMMYFUNCTION("""COMPUTED_VALUE"""),"Break between matches") -> Break between matches | L6: =IFERROR(__xludf.DUMMYFUNCTION("""COMPUTED_VALUE"""),"40 minutes") -> 40 minutes
B7: =IFERROR(__xludf.DUMMYFUNCTION("""COMPUTED_VALUE"""),"Round Robin Format") -> Round Robin Format | D7: =IFERROR(__xludf.DUMMYFUNCTION("""COMPUTED_VALUE"""),"Media Day") -> Media Day | E7: =IFERROR(__xludf.DUMMYFUNCTION("""COMPUTED_VALUE"""),46209.0) -> 46209 | G7: =IFERROR(__xludf.DUMMYFUNCTION("""COMPUTED_VALUE"""),3.0) -> 3 | H7: =IFERROR(__xludf.DUMMYFUNCTION("""COMPUTED_VALUE"""),200000.0) -> 200000 | N7: =IFERROR(__xludf.DUMMYFUNCTION("""COMPUTED_VALUE"""),"Ban") -> Ban
B8: =IFERROR(__xludf.DUMMYFUNCTION("""COMPUTED_VALUE"""),"Bo2") -> Bo2 | D8: =IFERROR(__xludf.DUMMYFUNCTION("""COMPUTED_VALUE"""),"Tournament Dates") -> Tournament Dates | E8: =IFERROR(__xludf.DUMMYFUNCTION("""COMPUTED_VALUE"""),"July 7 - 19") -> July 7 - 19 | G8: =IFERROR(__xludf.DUMMYFUNCTION("""COMPUTED_VALUE"""),4.0) -> 4 | H8: =IFERROR(__xludf.DUMMYFUNCTION("""COMPUTED_VALUE"""),120000.0) -> 120000 | K8: =IFERROR(__xludf.DUMMYFUNCTION("""COMPUTED_VALUE"""),"Pauses") -> Pauses | N8: =IFERROR(__xludf.DUMMYFUNCTION("""COMPUTED_VALUE"""),"Ban") -> Ban
B9: =IFERROR(__xludf.DUMMYFUNCTION("""COMPUTED_VALUE"""),"1st per group qualify to Playoffs") -> 1st per group qualify to Playoffs | D9: =IFERROR(__xludf.DUMMYFUNCTION("""COMPUTED_VALUE"""),"Playoffs Dates") -> Playoffs Dates | E9: =IFERROR(__xludf.DUMMYFUNCTION("""COMPUTED_VALUE"""),"July 16 - 19") -> July 16 - 19 | G9: =IFERROR(__xludf.DUMMYFUNCTION("""COMPUTED_VALUE"""),"5-8") -> 5-8 | H9: =IFERROR(__xludf.DUMMYFUNCTION("""COMPUTED_VALUE"""),70000.0) -> 70000 | I9: =IFERROR(__xludf.DUMMYFUNCTION("""COMPUTED_VALUE"""),"Nigma Galaxy") -> Nigma Galaxy | K9: =IFERROR(__xludf.DUMMYFUNCTION("""COMPUTED_VALUE"""),"Pauses should only be for technical reasons") -> Pauses should only be for technical reasons | N9: =IFERROR(__xludf.DUMMYFUNCTION("""COMPUTED_VALUE"""),"Ban") -> Ban
B10: =IFERROR(__xludf.DUMMYFUNCTION("""COMPUTED_VALUE"""),"2nd-4th per group qualify to Survival") -> 2nd-4th per group qualify to Survival | G10: =IFERROR(__xludf.DUMMYFUNCTION("""COMPUTED_VALUE"""),"5-8") -> 5-8 | H10: =IFERROR(__xludf.DUMMYFUNCTION("""COMPUTED_VALUE"""),70000.0) -> 70000 | I10: =IFERROR(__xludf.DUMMYFUNCTION("""COMPUTED_VALUE"""),"Team Falcons") -> Team Falcons | N10: =IFERROR(__xludf.DUMMYFUNCTION("""COMPUTED_VALUE"""),"Ban") -> Ban
B11: =IFERROR(__xludf.DUMMYFUNCTION("""COMPUTED_VALUE"""),"5th-6th per group eliminated") -> 5th-6th per group eliminated | D11: =IFERROR(__xludf.DUMMYFUNCTION("""COMPUTED_VALUE"""),"Roster Submission Deadline") -> Roster Submission Deadline | E11: =IFERROR(__xludf.DUMMYFUNCTION("""COMPUTED_VALUE"""),46182.0) -> 46182 | G11: =IFERROR(__xludf.DUMMYFUNCTION("""COMPUTED_VALUE"""),"5-8") -> 5-8 | H11: =IFERROR(__xludf.DUMMYFUNCTION("""COMPUTED_VALUE"""),70000.0) -> 70000 | I11: =IFERROR(__xludf.DUMMYFUNCTION("""COMPUTED_VALUE"""),"Rune Eaters") -> Rune Eaters | K11: =IFERROR(__xludf.DUMMYFUNCTION("""COMPUTED_VALUE"""),"Seeding") -> Seeding | N11: =IFERROR(__xludf.DUMMYFUNCTION("""COMPUTED_VALUE"""),"Ban") -> Ban
B12: =IFERROR(__xludf.DUMMYFUNCTION("""COMPUTED_VALUE"""),"Stage 2: Survival") -> Stage 2: Survival | D12: =IFERROR(__xludf.DUMMYFUNCTION("""COMPUTED_VALUE"""),"Seeding Date") -> Seeding Date | E12: =IFERROR(__xludf.DUMMYFUNCTION("""COMPUTED_VALUE"""),"June 19 (latest)") -> June 19 (latest) | G12: =IFERROR(__xludf.DUMMYFUNCTION("""COMPUTED_VALUE"""),"5-8") -> 5-8 | H12: =IFERROR(__xludf.DUMMYFUNCTION("""COMPUTED_VALUE"""),70000.0) -> 70000 | I12: =IFERROR(__xludf.DUMMYFUNCTION("""COMPUTED_VALUE"""),"Team Spirit") -> Team Spirit | K12: =IFERROR(__xludf.DUMMYFUNCTION("""COMPUTED_VALUE"""),"Group Stage") -> Group Stage | N12: =IFERROR(__xludf.DUMMYFUNCTION("""COMPUTED_VALUE"""),"Ban") -> Ban
B13: =IFERROR(__xludf.DUMMYFUNCTION("""COMPUTED_VALUE"""),"12 teams (12 qualified)") -> 12 teams (12 qualified) | G13: =IFERROR(__xludf.DUMMYFUNCTION("""COMPUTED_VALUE"""),"9-12") -> 9-12 | H13: =IFERROR(__xludf.DUMMYFUNCTION("""COMPUTED_VALUE"""),40000.0) -> 40000 | I13: =IFERROR(__xludf.DUMMYFUNCTION("""COMPUTED_VALUE"""),"1W") -> 1W | K13: =IFERROR(__xludf.DUMMYFUNCTION("""COMPUTED_VALUE"""),"The EPT Leaderboard Teams must be divided evenly between the 4 groups, and there cannot be more than 1 team from each four ranks (between 1-4, 5-8, etc) in any single Group.") -> The EPT Leaderboard Teams must be divided evenly between the 4 groups, and there cannot be more than 1 team from each four ranks (between 1-4, 5-8, etc) in any single Group. | N13: =IFERROR(__xludf.DUMMYFUNCTION("""COMPUTED_VALUE"""),"Ban") -> Ban
D14: =IFERROR(__xludf.DUMMYFUNCTION("""COMPUTED_VALUE"""),"Total number of teams") -> Total number of teams | E14: =IFERROR(__xludf.DUMMYFUNCTION("""COMPUTED_VALUE"""),24.0) -> 24 | G14: =IFERROR(__xludf.DUMMYFUNCTION("""COMPUTED_VALUE"""),"9-12") -> 9-12 | H14: =IFERROR(__xludf.DUMMYFUNCTION("""COMPUTED_VALUE"""),40000.0) -> 40000 | I14: =IFERROR(__xludf.DUMMYFUNCTION("""COMPUTED_VALUE"""),"LGD Gaming") -> LGD Gaming | N14: =IFERROR(__xludf.DUMMYFUNCTION("""COMPUTED_VALUE"""),"Pick") -> Pick
B15: =IFERROR(__xludf.DUMMYFUNCTION("""COMPUTED_VALUE"""),"Partially populated Single Elimination") -> Partially populated Single Elimination | D15: =IFERROR(__xludf.DUMMYFUNCTION("""COMPUTED_VALUE"""),"Players per team") -> Players per team | E15: =IFERROR(__xludf.DUMMYFUNCTION("""COMPUTED_VALUE"""),5.0) -> 5 | G15: =IFERROR(__xludf.DUMMYFUNCTION("""COMPUTED_VALUE"""),"9-12") -> 9-12 | H15: =IFERROR(__xludf.DUMMYFUNCTION("""COMPUTED_VALUE"""),40000.0) -> 40000 | I15: =IFERROR(__xludf.DUMMYFUNCTION("""COMPUTED_VALUE"""),"Team Liquid") -> Team Liquid | N15: =IFERROR(__xludf.DUMMYFUNCTION("""COMPUTED_VALUE"""),"Pick") -> Pick
B16: =IFERROR(__xludf.DUMMYFUNCTION("""COMPUTED_VALUE"""),"4th vs 3rd from groups, winner vs 2nd") -> 4th vs 3rd from groups, winner vs 2nd | D16: =IFERROR(__xludf.DUMMYFUNCTION("""COMPUTED_VALUE"""),"Total number of players") -> Total number of players | E16: =IFERROR(__xludf.DUMMYFUNCTION("""COMPUTED_VALUE"""),120.0) -> 120 | G16: =IFERROR(__xludf.DUMMYFUNCTION("""COMPUTED_VALUE"""),"9-12") -> 9-12 | H16: =IFERROR(__xludf.DUMMYFUNCTION("""COMPUTED_VALUE"""),40000.0) -> 40000 | I16: =IFERROR(__xludf.DUMMYFUNCTION("""COMPUTED_VALUE"""),"Aurora Gaming") -> Aurora Gaming | K16: =IFERROR(__xludf.DUMMYFUNCTION("""COMPUTED_VALUE"""),"After all the teams with EPT Points have been seeded, the teams who qualified without attaining EPT points will be seeded using a GLICKO2 rating that considers all professional games.") -> After all the teams with EPT Points have been seeded, the teams who qualified without attaining EPT points will be seeded using a GLICKO2 rating that considers all professional games. | N16: =IFERROR(__xludf.DUMMYFUNCTION("""COMPUTED_VALUE"""),"Ban") -> Ban
B17: =IFERROR(__xludf.DUMMYFUNCTION("""COMPUTED_VALUE"""),"Bo3") -> Bo3 | D17: =IFERROR(__xludf.DUMMYFUNCTION("""COMPUTED_VALUE"""),"Total number of matches") -> Total number of matches | E17: =IFERROR(__xludf.DUMMYFUNCTION("""COMPUTED_VALUE"""),"76 - 88") -> 76 - 88 | G17: =IFERROR(__xludf.DUMMYFUNCTION("""COMPUTED_VALUE"""),"13-16") -> 13-16 | H17: =IFERROR(__xludf.DUMMYFUNCTION("""COMPUTED_VALUE"""),20000.0) -> 20000 | N17: =IFERROR(__xludf.DUMMYFUNCTION("""COMPUTED_VALUE"""),"Ban") -> Ban
B18: =IFERROR(__xludf.DUMMYFUNCTION("""COMPUTED_VALUE"""),"Top 4 qualify to Playoffs") -> Top 4 qualify to Playoffs | G18: =IFERROR(__xludf.DUMMYFUNCTION("""COMPUTED_VALUE"""),"13-16") -> 13-16 | H18: =IFERROR(__xludf.DUMMYFUNCTION("""COMPUTED_VALUE"""),20000.0) -> 20000 | I18: =IFERROR(__xludf.DUMMYFUNCTION("""COMPUTED_VALUE"""),"LGD Gaming") -> LGD Gaming | N18: =IFERROR(__xludf.DUMMYFUNCTION("""COMPUTED_VALUE"""),"Ban") -> Ban
B19: =IFERROR(__xludf.DUMMYFUNCTION("""COMPUTED_VALUE"""),"Stage 3: Playoffs") -> Stage 3: Playoffs | D19: =IFERROR(__xludf.DUMMYFUNCTION("""COMPUTED_VALUE"""),"Platform") -> Platform | E19: =IFERROR(__xludf.DUMMYFUNCTION("""COMPUTED_VALUE"""),"PC") -> PC | G19: =IFERROR(__xludf.DUMMYFUNCTION("""COMPUTED_VALUE"""),"13-16") -> 13-16 | H19: =IFERROR(__xludf.DUMMYFUNCTION("""COMPUTED_VALUE"""),20000.0) -> 20000 | I19: =IFERROR(__xludf.DUMMYFUNCTION("""COMPUTED_VALUE"""),"Xtreme Gaming") -> Xtreme Gaming | K19: =IFERROR(__xludf.DUMMYFUNCTION("""COMPUTED_VALUE"""),"Playoffs") -> Playoffs | N19: =IFERROR(__xludf.DUMMYFUNCTION("""COMPUTED_VALUE"""),"Pick") -> Pick
B20: =IFERROR(__xludf.DUMMYFUNCTION("""COMPUTED_VALUE"""),"8 teams (4 from Group Stage, 4 from Survival)") -> 8 teams (4 from Group Stage, 4 from Survival) | D20: =IFERROR(__xludf.DUMMYFUNCTION("""COMPUTED_VALUE"""),"Game Mode") -> Game Mode | E20: =IFERROR(__xludf.DUMMYFUNCTION("""COMPUTED_VALUE"""),"Captain's Mode") -> Captain's Mode | G20: =IFERROR(__xludf.DUMMYFUNCTION("""COMPUTED_VALUE"""),"13-16") -> 13-16 | H20: =IFERROR(__xludf.DUMMYFUNCTION("""COMPUTED_VALUE"""),20000.0) -> 20000 | I20: =IFERROR(__xludf.DUMMYFUNCTION("""COMPUTED_VALUE"""),"Virtus.pro") -> Virtus.pro | K20: =IFERROR(__xludf.DUMMYFUNCTION("""COMPUTED_VALUE"""),"The playoffs consists of a seeded Single Elim bracket. 3rd and 4th from each group advances to the Ro16, 2nd to Ro12 and 1st to Ro8.") -> The playoffs consists of a seeded Single Elim bracket. 3rd and 4th from each group advances to the Ro16, 2nd to Ro12 and 1st to Ro8. | N20: =IFERROR(__xludf.DUMMYFUNCTION("""COMPUTED_VALUE"""),"Pick") -> Pick
G21: =IFERROR(__xludf.DUMMYFUNCTION("""COMPUTED_VALUE"""),"17-20") -> 17-20 | H21: =IFERROR(__xludf.DUMMYFUNCTION("""COMPUTED_VALUE"""),10000.0) -> 10000 | I21: =IFERROR(__xludf.DUMMYFUNCTION("""COMPUTED_VALUE"""),"OG Esports") -> OG Esports | N21: =IFERROR(__xludf.DUMMYFUNCTION("""COMPUTED_VALUE"""),"Pick") -> Pick
B22: =IFERROR(__xludf.DUMMYFUNCTION("""COMPUTED_VALUE"""),"Single Elimination Bracket") -> Single Elimination Bracket | D22: =IFERROR(__xludf.DUMMYFUNCTION("""COMPUTED_VALUE"""),"Total Winnings") -> Total Winnings | E22: =IFERROR(__xludf.DUMMYFUNCTION("""COMPUTED_VALUE"""),"$2,000,000") -> $2,000,000 | G22: =IFERROR(__xludf.DUMMYFUNCTION("""COMPUTED_VALUE"""),"17-20") -> 17-20 | H22: =IFERROR(__xludf.DUMMYFUNCTION("""COMPUTED_VALUE"""),10000.0) -> 10000 | I22: =IFERROR(__xludf.DUMMYFUNCTION("""COMPUTED_VALUE"""),"REKONIX") -> REKONIX | N22: =IFERROR(__xludf.DUMMYFUNCTION("""COMPUTED_VALUE"""),"Pick") -> Pick
B23: =IFERROR(__xludf.DUMMYFUNCTION("""COMPUTED_VALUE"""),"Bo3, Bo5 Final") -> Bo3, Bo5 Final | G23: =IFERROR(__xludf.DUMMYFUNCTION("""COMPUTED_VALUE"""),"17-20") -> 17-20 | H23: =IFERROR(__xludf.DUMMYFUNCTION("""COMPUTED_VALUE"""),10000.0) -> 10000 | I23: =IFERROR(__xludf.DUMMYFUNCTION("""COMPUTED_VALUE"""),"Level UP") -> Level UP | K23: =IFERROR(__xludf.DUMMYFUNCTION("""COMPUTED_VALUE"""),"Each playoff ‘arm’ will be seeded to avoid teams from the same group rematching before the semi final stage") -> Each playoff ‘arm’ will be seeded to avoid teams from the same group rematching before the semi final stage | N23: =IFERROR(__xludf.DUMMYFUNCTION("""COMPUTED_VALUE"""),"Pick") -> Pick
D24: =IFERROR(__xludf.DUMMYFUNCTION("""COMPUTED_VALUE"""),"Rulebook link") -> Rulebook link | E24: =IFERROR(__xludf.DUMMYFUNCTION("""COMPUTED_VALUE"""),"https://drive.google.com/file/d/17XHc5gA-ozmcES-RNsjmM6IfXDBNfE45/view?usp=sharing") -> https://drive.google.com/file/d/17XHc5gA-ozmcES-RNsjmM6IfXDBNfE45/view?usp=sharing | G24: =IFERROR(__xludf.DUMMYFUNCTION("""COMPUTED_VALUE"""),"17-20") -> 17-20 | H24: =IFERROR(__xludf.DUMMYFUNCTION("""COMPUTED_VALUE"""),10000.0) -> 10000 | I24: =IFERROR(__xludf.DUMMYFUNCTION("""COMPUTED_VALUE"""),"GamerLegion") -> GamerLegion | N24: =IFERROR(__xludf.DUMMYFUNCTION("""COMPUTED_VALUE"""),"Pick") -> Pick
G25: =IFERROR(__xludf.DUMMYFUNCTION("""COMPUTED_VALUE"""),"21-24") -> 21-24 | H25: =IFERROR(__xludf.DUMMYFUNCTION("""COMPUTED_VALUE"""),7500.0) -> 7500 | I25: =IFERROR(__xludf.DUMMYFUNCTION("""COMPUTED_VALUE"""),"IC x Insanity") -> IC x Insanity | N25: =IFERROR(__xludf.DUMMYFUNCTION("""COMPUTED_VALUE"""),"Ban") -> Ban
D26: =IFERROR(__xludf.DUMMYFUNCTION("""COMPUTED_VALUE"""),"Qualifier Links") -> Qualifier Links | G26: =IFERROR(__xludf.DUMMYFUNCTION("""COMPUTED_VALUE"""),"21-24") -> 21-24 | H26: =IFERROR(__xludf.DUMMYFUNCTION("""COMPUTED_VALUE"""),7500.0) -> 7500 | I26: =IFERROR(__xludf.DUMMYFUNCTION("""COMPUTED_VALUE"""),"Team Nemesis") -> Team Nemesis | K26: =IFERROR(__xludf.DUMMYFUNCTION("""COMPUTED_VALUE"""),"The exact placement of each team within the bracket will be randomly drawn keeping to this rule.") -> The exact placement of each team within the bracket will be randomly drawn keeping to this rule. | N26: =IFERROR(__xludf.DUMMYFUNCTION("""COMPUTED_VALUE"""),"Ban") -> Ban
D27: =IFERROR(__xludf.DUMMYFUNCTION("""COMPUTED_VALUE"""),"SA - Open Qualifier") -> SA - Open Qualifier | E27: =IFERROR(__xludf.DUMMYFUNCTION("""COMPUTED_VALUE"""),"https://www.faceit.com/en/championship/65e7db1f-a6a2-4b3c-a74f-f16ae2484d58/") -> https://www.faceit.com/en/championship/65e7db1f-a6a2-4b3c-a74f-f16ae2484d58/ | G27: =IFERROR(__xludf.DUMMYFUNCTION("""COMPUTED_VALUE"""),"21-24") -> 21-24 | H27: =IFERROR(__xludf.DUMMYFUNCTION("""COMPUTED_VALUE"""),7500.0) -> 7500 | I27: =IFERROR(__xludf.DUMMYFUNCTION("""COMPUTED_VALUE"""),"L1 TEAM") -> L1 TEAM | N27: =IFERROR(__xludf.DUMMYFUNCTION("""COMPUTED_VALUE"""),"Ban") -> Ban
D28: =IFERROR(__xludf.DUMMYFUNCTION("""COMPUTED_VALUE"""),"SA- Closed Qualifier") -> SA- Closed Qualifier | E28: =IFERROR(__xludf.DUMMYFUNCTION("""COMPUTED_VALUE"""),"https://www.faceit.com/en/championship/e8c2cab6-1cce-4de0-9c61-ee4f6a1cce9b/") -> https://www.faceit.com/en/championship/e8c2cab6-1cce-4de0-9c61-ee4f6a1cce9b/ | G28: =IFERROR(__xludf.DUMMYFUNCTION("""COMPUTED_VALUE"""),"21-24") -> 21-24 | H28: =IFERROR(__xludf.DUMMYFUNCTION("""COMPUTED_VALUE"""),7500.0) -> 7500 | I28: =IFERROR(__xludf.DUMMYFUNCTION("""COMPUTED_VALUE"""),"Poor Rangers") -> Poor Rangers | N28: =IFERROR(__xludf.DUMMYFUNCTION("""COMPUTED_VALUE"""),"Ban") -> Ban
D29: =IFERROR(__xludf.DUMMYFUNCTION("""COMPUTED_VALUE"""),"NA - Open Qualifier 1") -> NA - Open Qualifier 1 | E29: =IFERROR(__xludf.DUMMYFUNCTION("""COMPUTED_VALUE"""),"https://www.faceit.com/en/championship/409ecf90-e12b-4284-8f1d-35a3ed2f1eea/") -> https://www.faceit.com/en/championship/409ecf90-e12b-4284-8f1d-35a3ed2f1eea/ | N29: =IFERROR(__xludf.DUMMYFUNCTION("""COMPUTED_VALUE"""),"Pick") -> Pick
D30: =IFERROR(__xludf.DUMMYFUNCTION("""COMPUTED_VALUE"""),"NA - Open Qualifier 2") -> NA - Open Qualifier 2 | E30: =IFERROR(__xludf.DUMMYFUNCTION("""COMPUTED_VALUE"""),"https://www.faceit.com/en/championship/f2ea6f52-fcfa-496b-a9b1-b026c78e193b/Dota%202%20at%20ROAD%20TO%20EWC%2026:%20Online%20Qualifier%201%20-%20North%20America") -> https://www.faceit.com/en/championship/f2ea6f52-fcfa-496b-a9b1-b026c78e193b/Dota%202%20at%20ROAD%20TO%20EWC%2026:%20Online%20Qualifier%201%20-%20North%20America | N30: =IFERROR(__xludf.DUMMYFUNCTION("""COMPUTED_VALUE"""),"Pick") -> Pick
D31: =IFERROR(__xludf.DUMMYFUNCTION("""COMPUTED_VALUE"""),"NA - Closed Qualifier") -> NA - Closed Qualifier | E31: =IFERROR(__xludf.DUMMYFUNCTION("""COMPUTED_VALUE"""),"https://www.faceit.com/en/championship/d2fec2d1-2df4-4f37-8760-bba9d9a7be22/") -> https://www.faceit.com/en/championship/d2fec2d1-2df4-4f37-8760-bba9d9a7be22/
D32: =IFERROR(__xludf.DUMMYFUNCTION("""COMPUTED_VALUE"""),"WEU - Open Qualifier") -> WEU - Open Qualifier | E32: =IFERROR(__xludf.DUMMYFUNCTION("""COMPUTED_VALUE"""),"https://www.faceit.com/en/championship/093a60db-df2d-4542-b192-c214ff6ee073/") -> https://www.faceit.com/en/championship/093a60db-df2d-4542-b192-c214ff6ee073/
D33: =IFERROR(__xludf.DUMMYFUNCTION("""COMPUTED_VALUE"""),"WEU - Closed Qualifier") -> WEU - Closed Qualifier | E33: =IFERROR(__xludf.DUMMYFUNCTION("""COMPUTED_VALUE"""),"https://www.faceit.com/en/championship/1960e405-2704-46cb-bcda-ace91e27f67f") -> https://www.faceit.com/en/championship/1960e405-2704-46cb-bcda-ace91e27f67f
D34: =IFERROR(__xludf.DUMMYFUNCTION("""COMPUTED_VALUE"""),"EEU - Open Qualifier") -> EEU - Open Qualifier | E34: =IFERROR(__xludf.DUMMYFUNCTION("""COMPUTED_VALUE"""),"https://www.faceit.com/en/championship/66ba9f27-6766-445f-a059-dcf3aa0d448e/Dota%202%20at%20ROAD%20TO%20EWC%2026:%20Online%20Qualifier%20-%20Eastern%20Europe") -> https://www.faceit.com/en/championship/66ba9f27-6766-445f-a059-dcf3aa0d448e/Dota%202%20at%20ROAD%20TO%20EWC%2026:%20Online%20Qualifier%20-%20Eastern%20Europe
D35: =IFERROR(__xludf.DUMMYFUNCTION("""COMPUTED_VALUE"""),"EEU - Closed Qualifier") -> EEU - Closed Qualifier | E35: =IFERROR(__xludf.DUMMYFUNCTION("""COMPUTED_VALUE"""),"https://www.faceit.com/en/championship/555758a1-fec6-40a5-820f-122b2561fa2e/Dota%202%20at%20ROAD%20TO%20EWC%2026:%20Closed%20Qualifier%20-%20Eastern%20Europe") -> https://www.faceit.com/en/championship/555758a1-fec6-40a5-820f-122b2561fa2e/Dota%202%20at%20ROAD%20TO%20EWC%2026:%20Closed%20Qualifier%20-%20Eastern%20Europe
D36: =IFERROR(__xludf.DUMMYFUNCTION("""COMPUTED_VALUE"""),"MESWA - Open Qualifier 1") -> MESWA - Open Qualifier 1 | E36: =IFERROR(__xludf.DUMMYFUNCTION("""COMPUTED_VALUE"""),"https://www.faceit.com/en/championship/a7b64254-1f65-4e0a-831d-1f96f00d8cc0/Dota%202%20at%20ROAD%20TO%20EWC%2026:%20Online%20Qualifier%20-%20Middle%20East%20Southwest%20Asia") -> https://www.faceit.com/en/championship/a7b64254-1f65-4e0a-831d-1f96f00d8cc0/Dota%202%20at%20ROAD%20TO%20EWC%2026:%20Online%20Qualifier%20-%20Middle%20East%20Southwest%20Asia
D37: =IFERROR(__xludf.DUMMYFUNCTION("""COMPUTED_VALUE"""),"MESWA - Open Qualifier 2") -> MESWA - Open Qualifier 2 | E37: =IFERROR(__xludf.DUMMYFUNCTION("""COMPUTED_VALUE"""),"https://www.faceit.com/en/championship/e78f2327-bdbb-45ae-a44d-fbca0aac8320/Dota%202%20at%20ROAD%20TO%20EWC%2026:%20Online%20Qualifier%201%20-%20Middle%20East%20Southwest%20Asia") -> https://www.faceit.com/en/championship/e78f2327-bdbb-45ae-a44d-fbca0aac8320/Dota%202%20at%20ROAD%20TO%20EWC%2026:%20Online%20Qualifier%201%20-%20Middle%20East%20Southwest%20Asia
D38: =IFERROR(__xludf.DUMMYFUNCTION("""COMPUTED_VALUE"""),"MESWA - Closed Qualifier") -> MESWA - Closed Qualifier | E38: =IFERROR(__xludf.DUMMYFUNCTION("""COMPUTED_VALUE"""),"https://www.faceit.com/en/championship/b5f19e21-6851-4a56-9866-00ae926b2a8c/Dota%202%20at%20ROAD%20TO%20EWC%2026:%20Closed%20Qualifier%20-%20Middle%20East%20Southwest%20Asia") -> https://www.faceit.com/en/championship/b5f19e21-6851-4a56-9866-00ae926b2a8c/Dota%202%20at%20ROAD%20TO%20EWC%2026:%20Closed%20Qualifier%20-%20Middle%20East%20Southwest%20Asia
D39: =IFERROR(__xludf.DUMMYFUNCTION("""COMPUTED_VALUE"""),"SEA - Open Qualifier") -> SEA - Open Qualifier | E39: =IFERROR(__xludf.DUMMYFUNCTION("""COMPUTED_VALUE"""),"https://www.faceit.com/en/championship/33492990-ee9b-4287-bf64-f7ad1e3cda28/Dota%202%20at%20ROAD%20TO%20EWC%2026:%20Online%20Qualifier%20-%20Southeast%20Asia") -> https://www.faceit.com/en/championship/33492990-ee9b-4287-bf64-f7ad1e3cda28/Dota%202%20at%20ROAD%20TO%20EWC%2026:%20Online%20Qualifier%20-%20Southeast%20Asia
D40: =IFERROR(__xludf.DUMMYFUNCTION("""COMPUTED_VALUE"""),"SEA - Closed Qualifier") -> SEA - Closed Qualifier | E40: =IFERROR(__xludf.DUMMYFUNCTION("""COMPUTED_VALUE"""),"https://www.faceit.com/en/championship/3870d67b-8913-4dfb-9b5b-e8c5782cac60/Dota%202%20at%20ROAD%20TO%20EWC%2026:%20Closed%20Qualifier%20-%20Southeast%20Asia") -> https://www.faceit.com/en/championship/3870d67b-8913-4dfb-9b5b-e8c5782cac60/Dota%202%20at%20ROAD%20TO%20EWC%2026:%20Closed%20Qualifier%20-%20Southeast%20Asia

Sheet Schedule
A1: =IFERROR(__xludf.DUMMYFUNCTION("if('Make Public'!C8=""Yes"",importrange('Make Public'!B3,""Schedule!A1:p6""),""TBD"")"),"") | N1: =IFERROR(__xludf.DUMMYFUNCTION("""COMPUTED_VALUE"""),"Phase 1") -> Phase 1 | O1: =IFERROR(__xludf.DUMMYFUNCTION("""COMPUTED_VALUE"""),"Phase 2") -> Phase 2 | P1: =IFERROR(__xludf.DUMMYFUNCTION("""COMPUTED_VALUE"""),"Playoffs") -> Playoffs
N2: =IFERROR(__xludf.DUMMYFUNCTION("""COMPUTED_VALUE"""),"Group Stage 4x6 Teams RR") -> Group Stage 4x6 Teams RR | O2: =IFERROR(__xludf.DUMMYFUNCTION("""COMPUTED_VALUE"""),"Survival 1x12 Teams SE") -> Survival 1x12 Teams SE | P2: =IFERROR(__xludf.DUMMYFUNCTION("""COMPUTED_VALUE"""),"Playoffs 1x8 Teams SE") -> Playoffs 1x8 Teams SE
B4: =IFERROR(__xludf.DUMMYFUNCTION("""COMPUTED_VALUE"""),"Tournament Day #") -> Tournament Day # | D4: =IFERROR(__xludf.DUMMYFUNCTION("""COMPUTED_VALUE"""),"Date") -> Date | E4: =IFERROR(__xludf.DUMMYFUNCTION("""COMPUTED_VALUE"""),"Stage") -> Stage | F4: =IFERROR(__xludf.DUMMYFUNCTION("""COMPUTED_VALUE"""),"Stream") -> Stream | G4: =IFERROR(__xludf.DUMMYFUNCTION("""COMPUTED_VALUE"""),"Best of X") -> Best of X | H4: =IFERROR(__xludf.DUMMYFUNCTION("""COMPUTED_VALUE"""),"Start Time") -> Start Time | N4: =IFERROR(__xludf.DUMMYFUNCTION("""COMPUTED_VALUE"""),"Round") -> Round | O4: =IFERROR(__xludf.DUMMYFUNCTION("""COMPUTED_VALUE"""),"Match") -> Match | P4: =IFERROR(__xludf.DUMMYFUNCTION("""COMPUTED_VALUE"""),"Comment") -> Comment
H5: =IFERROR(__xludf.DUMMYFUNCTION("""COMPUTED_VALUE"""),"- PUBLIC- - CEST-") -> - PUBLIC- - CEST- | I5: =IFERROR(__xludf.DUMMYFUNCTION("""COMPUTED_VALUE"""),"- PUBLIC- - CEST -") -> - PUBLIC- - CEST - | J5: =IFERROR(__xludf.DUMMYFUNCTION("""COMPUTED_VALUE"""),"- PUBLIC- - EDT -") -> - PUBLIC- - EDT - | K5: =IFERROR(__xludf.DUMMYFUNCTION("""COMPUTED_VALUE"""),"- PUBLIC- - BRT -") -> - PUBLIC- - BRT - | L5: =IFERROR(__xludf.DUMMYFUNCTION("""COMPUTED_VALUE"""),"- PUBLIC- - CST -") -> - PUBLIC- - CST - | M5: =IFERROR(__xludf.DUMMYFUNCTION("""COMPUTED_VALUE"""),"- PUBLIC- - AEST-") -> - PUBLIC- - AEST-
I6: =IFERROR(__xludf.DUMMYFUNCTION("""COMPUTED_VALUE"""),-1.0) -> -1 | J6: =IFERROR(__xludf.DUMMYFUNCTION("""COMPUTED_VALUE"""),-7.0) -> -7 | K6: =IFERROR(__xludf.DUMMYFUNCTION("""COMPUTED_VALUE"""),"-6") -> -6 | L6: =IFERROR(__xludf.DUMMYFUNCTION("""COMPUTED_VALUE"""),"+5") -> +5 | M6: =IFERROR(__xludf.DUMMYFUNCTION("""COMPUTED_VALUE"""),"+7") -> +7
A7: =IFERROR(__xludf.DUMMYFUNCTION("if('Make Public'!C8=""Yes"",importrange('Make Public'!B3,""Schedule!A7:H""),""TBD"")"),"") | B7: =IFERROR(__xludf.DUMMYFUNCTION("""COMPUTED_VALUE"""),1.0) -> 1 | C7: =IFERROR(__xludf.DUMMYFUNCTION("""COMPUTED_VALUE"""),46210.0) -> 46210 | D7: =IFERROR(__xludf.DUMMYFUNCTION("""COMPUTED_VALUE"""),46210.0) -> 46210 | E7: =IFERROR(__xludf.DUMMYFUNCTION("""COMPUTED_VALUE"""),"MS3") -> MS3 | F7: =IFERROR(__xludf.DUMMYFUNCTION("""COMPUTED_VALUE"""),"Stream A") -> Stream A | G7: =IFERROR(__xludf.DUMMYFUNCTION("""COMPUTED_VALUE"""),"Bo2") -> Bo2 | H7: =IFERROR(__xludf.DUMMYFUNCTION("""COMPUTED_VALUE"""),0.4756944444444444) -> 0.47569444 | N7: =IFERROR(__xludf.DUMMYFUNCTION("IF( 'Make Public'!C8<>""Yes"", ""TBD"", ARRAYFORMULA( IF( IMPORTRANGE('Make Public'!B3,""Schedule!R7:R"")=""YES"", IMPORTRANGE('Make Public'!B3,""Schedule!N7:P""), """" ) ) )"),"Groupstage - Group A - Round Robin R1 #1") -> Groupstage - Group A - Round Robin R1 #1 | O7: =IFERROR(__xludf.DUMMYFUNCTION("""COMPUTED_VALUE"""),"Team Falcons vs. BB Team") -> Team Falcons vs. BB Team
C8: =IFERROR(__xludf.DUMMYFUNCTION("""COMPUTED_VALUE"""),46210.0) -> 46210 | E8: =IFERROR(__xludf.DUMMYFUNCTION("""COMPUTED_VALUE"""),"SS3") -> SS3 | F8: =IFERROR(__xludf.DUMMYFUNCTION("""COMPUTED_VALUE"""),"Stream B") -> Stream B | G8: =IFERROR(__xludf.DUMMYFUNCTION("""COMPUTED_VALUE"""),"Bo2") -> Bo2 | H8: =IFERROR(__xludf.DUMMYFUNCTION("""COMPUTED_VALUE"""),0.48263888888888884) -> 0.48263889 | N8: =IFERROR(__xludf.DUMMYFUNCTION("""COMPUTED_VALUE"""),"Groupstage - Group A - Round Robin R1 #2") -> Groupstage - Group A - Round Robin R1 #2 | O8: =IFERROR(__xludf.DUMMYFUNCTION("""COMPUTED_VALUE"""),"Poor Rangers vs. GamerLegion") -> Poor Rangers vs. GamerLegion
C9: =IFERROR(__xludf.DUMMYFUNCTION("""COMPUTED_VALUE"""),46210.0) -> 46210 | E9: =IFERROR(__xludf.DUMMYFUNCTION("""COMPUTED_VALUE"""),"SS2") -> SS2 | F9: =IFERROR(__xludf.DUMMYFUNCTION("""COMPUTED_VALUE"""),"Stream C") -> Stream C | G9: =IFERROR(__xludf.DUMMYFUNCTION("""COMPUTED_VALUE"""),"Bo2") -> Bo2 | H9: =IFERROR(__xludf.DUMMYFUNCTION("""COMPUTED_VALUE"""),0.4861111111111111) -> 0.48611111 | N9: =IFERROR(__xludf.DUMMYFUNCTION("""COMPUTED_VALUE"""),"Groupstage - Group A - Round Robin R1 #3") -> Groupstage - Group A - Round Robin R1 #3 | O9: =IFERROR(__xludf.DUMMYFUNCTION("""COMPUTED_VALUE"""),"Rune Eaters vs. Xtreme Gaming") -> Rune Eaters vs. Xtreme Gaming
C10: =IFERROR(__xludf.DUMMYFUNCTION("""COMPUTED_VALUE"""),46210.0) -> 46210 | E10: =IFERROR(__xludf.DUMMYFUNCTION("""COMPUTED_VALUE"""),"MS3") -> MS3 | F10: =IFERROR(__xludf.DUMMYFUNCTION("""COMPUTED_VALUE"""),"Stream A") -> Stream A | G10: =IFERROR(__xludf.DUMMYFUNCTION("""COMPUTED_VALUE"""),"Bo2") -> Bo2 | H10: =IFERROR(__xludf.DUMMYFUNCTION("""COMPUTED_VALUE"""),0.6006944444444444) -> 0.60069444 | N10: =IFERROR(__xludf.DUMMYFUNCTION("""COMPUTED_VALUE"""),"Groupstage - Group B - Round Robin R1 #1") -> Groupstage - Group B - Round Robin R1 #1 | O10: =IFERROR(__xludf.DUMMYFUNCTION("""COMPUTED_VALUE"""),"Team Liquid vs. PTime") -> Team Liquid vs. PTime
C11: =IFERROR(__xludf.DUMMYFUNCTION("""COMPUTED_VALUE"""),46210.0) -> 46210 | E11: =IFERROR(__xludf.DUMMYFUNCTION("""COMPUTED_VALUE"""),"SS3") -> SS3 | F11: =IFERROR(__xludf.DUMMYFUNCTION("""COMPUTED_VALUE"""),"Stream B") -> Stream B | G11: =IFERROR(__xludf.DUMMYFUNCTION("""COMPUTED_VALUE"""),"Bo2") -> Bo2 | H11: =IFERROR(__xludf.DUMMYFUNCTION("""COMPUTED_VALUE"""),0.5972222222222222) -> 0.59722222 | N11: =IFERROR(__xludf.DUMMYFUNCTION("""COMPUTED_VALUE"""),"Groupstage - Group B - Round Robin R1 #2") -> Groupstage - Group B - Round Robin R1 #2 | O11: =IFERROR(__xludf.DUMMYFUNCTION("""COMPUTED_VALUE"""),"L1 TEAM vs. Nigma Galaxy") -> L1 TEAM vs. Nigma Galaxy
C12: =IFERROR(__xludf.DUMMYFUNCTION("""COMPUTED_VALUE"""),46210.0) -> 46210 | E12: =IFERROR(__xludf.DUMMYFUNCTION("""COMPUTED_VALUE"""),"SS2") -> SS2 | F12: =IFERROR(__xludf.DUMMYFUNCTION("""COMPUTED_VALUE"""),"Stream C") -> Stream C | G12: =IFERROR(__xludf.DUMMYFUNCTION("""COMPUTED_VALUE"""),"Bo2") -> Bo2 | H12: =IFERROR(__xludf.DUMMYFUNCTION("""COMPUTED_VALUE"""),0.6180555555555555) -> 0.61805556 | N12: =IFERROR(__xludf.DUMMYFUNCTION("""COMPUTED_VALUE"""),"Groupstage - Group B - Round Robin R1 #3") -> Groupstage - Group B - Round Robin R1 #3 | O12: =IFERROR(__xludf.DUMMYFUNCTION("""COMPUTED_VALUE"""),"Level UP vs. Aurora Gaming") -> Level UP vs. Aurora Gaming
C13: =IFERROR(__xludf.DUMMYFUNCTION("""COMPUTED_VALUE"""),46210.0) -> 46210 | E13: =IFERROR(__xludf.DUMMYFUNCTION("""COMPUTED_VALUE"""),"MS3") -> MS3 | F13: =IFERROR(__xludf.DUMMYFUNCTION("""COMPUTED_VALUE"""),"Stream A") -> Stream A | G13: =IFERROR(__xludf.DUMMYFUNCTION("""COMPUTED_VALUE"""),"Bo2") -> Bo2 | H13: =IFERROR(__xludf.DUMMYFUNCTION("""COMPUTED_VALUE"""),0.7118055555555555) -> 0.71180556 | N13: =IFERROR(__xludf.DUMMYFUNCTION("""COMPUTED_VALUE"""),"Groupstage - Group C - Round Robin R1 #1") -> Groupstage - Group C - Round Robin R1 #1 | O13: =IFERROR(__xludf.DUMMYFUNCTION("""COMPUTED_VALUE"""),"Team Spirit vs. MOUZ") -> Team Spirit vs. MOUZ
C14: =IFERROR(__xludf.DUMMYFUNCTION("""COMPUTED_VALUE"""),46210.0) -> 46210 | E14: =IFERROR(__xludf.DUMMYFUNCTION("""COMPUTED_VALUE"""),"SS3") -> SS3 | F14: =IFERROR(__xludf.DUMMYFUNCTION("""COMPUTED_VALUE"""),"Stream B") -> Stream B | G14: =IFERROR(__xludf.DUMMYFUNCTION("""COMPUTED_VALUE"""),"Bo2") -> Bo2 | H14: =IFERROR(__xludf.DUMMYFUNCTION("""COMPUTED_VALUE"""),0.7013888888888888) -> 0.70138889 | N14: =IFERROR(__xludf.DUMMYFUNCTION("""COMPUTED_VALUE"""),"Groupstage - Group C - Round Robin R1 #2") -> Groupstage - Group C - Round Robin R1 #2 | O14: =IFERROR(__xludf.DUMMYFUNCTION("""COMPUTED_VALUE"""),"REKONIX vs. Vici Gaming") -> REKONIX vs. Vici Gaming
C15: =IFERROR(__xludf.DUMMYFUNCTION("""COMPUTED_VALUE"""),46210.0) -> 46210 | E15: =IFERROR(__xludf.DUMMYFUNCTION("""COMPUTED_VALUE"""),"SS2") -> SS2 | F15: =IFERROR(__xludf.DUMMYFUNCTION("""COMPUTED_VALUE"""),"Stream C") -> Stream C | G15: =IFERROR(__xludf.DUMMYFUNCTION("""COMPUTED_VALUE"""),"Bo2") -> Bo2 | H15: =IFERROR(__xludf.DUMMYFUNCTION("""COMPUTED_VALUE"""),0.7256944444444444) -> 0.72569444 | N15: =IFERROR(__xludf.DUMMYFUNCTION("""COMPUTED_VALUE"""),"Groupstage - Group C - Round Robin R1 #3") -> Groupstage - Group C - Round Robin R1 #3 | O15: =IFERROR(__xludf.DUMMYFUNCTION("""COMPUTED_VALUE"""),"Team Nemesis vs. PVISION") -> Team Nemesis vs. PVISION
C16: =IFERROR(__xludf.DUMMYFUNCTION("""COMPUTED_VALUE"""),46210.0) -> 46210 | E16: =IFERROR(__xludf.DUMMYFUNCTION("""COMPUTED_VALUE"""),"MS3") -> MS3 | F16: =IFERROR(__xludf.DUMMYFUNCTION("""COMPUTED_VALUE"""),"Stream A") -> Stream A | G16: =IFERROR(__xludf.DUMMYFUNCTION("""COMPUTED_VALUE"""),"Bo2") -> Bo2 | H16: =IFERROR(__xludf.DUMMYFUNCTION("""COMPUTED_VALUE"""),0.8680555555555555) -> 0.86805556 | N16: =IFERROR(__xludf.DUMMYFUNCTION("""COMPUTED_VALUE"""),"Groupstage - Group D - Round Robin R1 #1") -> Groupstage - Group D - Round Robin R1 #1 | O16: =IFERROR(__xludf.DUMMYFUNCTION("""COMPUTED_VALUE"""),"Team Yandex vs. OG Esports") -> Team Yandex vs. OG Esports
C17: =IFERROR(__xludf.DUMMYFUNCTION("""COMPUTED_VALUE"""),46210.0) -> 46210 | E17: =IFERROR(__xludf.DUMMYFUNCTION("""COMPUTED_VALUE"""),"SS3") -> SS3 | F17: =IFERROR(__xludf.DUMMYFUNCTION("""COMPUTED_VALUE"""),"Stream B") -> Stream B | G17: =IFERROR(__xludf.DUMMYFUNCTION("""COMPUTED_VALUE"""),"Bo2") -> Bo2 | H17: =IFERROR(__xludf.DUMMYFUNCTION("""COMPUTED_VALUE"""),0.8263888888888888) -> 0.82638889 | N17: =IFERROR(__xludf.DUMMYFUNCTION("""COMPUTED_VALUE"""),"Groupstage - Group D - Round Robin R1 #2") -> Groupstage - Group D - Round Robin R1 #2 | O17: =IFERROR(__xludf.DUMMYFUNCTION("""COMPUTED_VALUE"""),"LGD Gaming vs. Virtus.pro") -> LGD Gaming vs. Virtus.pro
C18: =IFERROR(__xludf.DUMMYFUNCTION("""COMPUTED_VALUE"""),46210.0) -> 46210 | E18: =IFERROR(__xludf.DUMMYFUNCTION("""COMPUTED_VALUE"""),"SS2") -> SS2 | F18: =IFERROR(__xludf.DUMMYFUNCTION("""COMPUTED_VALUE"""),"Stream C") -> Stream C | G18: =IFERROR(__xludf.DUMMYFUNCTION("""COMPUTED_VALUE"""),"Bo2") -> Bo2 | H18: =IFERROR(__xludf.DUMMYFUNCTION("""COMPUTED_VALUE"""),0.84375) -> 0.84375 | N18: =IFERROR(__xludf.DUMMYFUNCTION("""COMPUTED_VALUE"""),"Groupstage - Group D - Round Robin R1 #3") -> Groupstage - Group D - Round Robin R1 #3 | O18: =IFERROR(__xludf.DUMMYFUNCTION("""COMPUTED_VALUE"""),"IC x Insanity vs. 1W") -> IC x Insanity vs. 1W
C19: =IFERROR(__xludf.DUMMYFUNCTION("""COMPUTED_VALUE"""),46210.0) -> 46210 | H19: =IFERROR(__xludf.DUMMYFUNCTION("""COMPUTED_VALUE"""),0.9513888888888888) -> 0.95138889
B20: =IFERROR(__xludf.DUMMYFUNCTION("""COMPUTED_VALUE"""),2.0) -> 2 | C20: =IFERROR(__xludf.DUMMYFUNCTION("""COMPUTED_VALUE"""),46211.0) -> 46211 | D20: =IFERROR(__xludf.DUMMYFUNCTION("""COMPUTED_VALUE"""),46211.0) -> 46211 | E20: =IFERROR(__xludf.DUMMYFUNCTION("""COMPUTED_VALUE"""),"MS3") -> MS3 | F20: =IFERROR(__xludf.DUMMYFUNCTION("""COMPUTED_VALUE"""),"Stream A") -> Stream A | G20: =IFERROR(__xludf.DUMMYFUNCTION("""COMPUTED_VALUE"""),"Bo2") -> Bo2 | H20: =IFERROR(__xludf.DUMMYFUNCTION("""COMPUTED_VALUE"""),0.46527777777777773) -> 0.46527778 | N20: =IFERROR(__xludf.DUMMYFUNCTION("""COMPUTED_VALUE"""),"Groupstage - Group A - Round Robin R2 #1") -> Groupstage - Group A - Round Robin R2 #1 | O20: =IFERROR(__xludf.DUMMYFUNCTION("""COMPUTED_VALUE"""),"GamerLegion vs. Xtreme Gaming") -> GamerLegion vs. Xtreme Gaming
C21: =IFERROR(__xludf.DUMMYFUNCTION("""COMPUTED_VALUE"""),46211.0) -> 46211 | E21: =IFERROR(__xludf.DUMMYFUNCTION("""COMPUTED_VALUE"""),"SS3") -> SS3 | F21: =IFERROR(__xludf.DUMMYFUNCTION("""COMPUTED_VALUE"""),"Stream B") -> Stream B | G21: =IFERROR(__xludf.DUMMYFUNCTION("""COMPUTED_VALUE"""),"Bo2") -> Bo2 | H21: =IFERROR(__xludf.DUMMYFUNCTION("""COMPUTED_VALUE"""),0.4618055555555555) -> 0.46180556 | N21: =IFERROR(__xludf.DUMMYFUNCTION("""COMPUTED_VALUE"""),"Groupstage - Group A - Round Robin R2 #2") -> Groupstage - Group A - Round Robin R2 #2 | O21: =IFERROR(__xludf.DUMMYFUNCTION("""COMPUTED_VALUE"""),"Poor Rangers vs. BB Team") -> Poor Rangers vs. BB Team
C22: =IFERROR(__xludf.DUMMYFUNCTION("""COMPUTED_VALUE"""),46211.0) -> 46211 | E22: =IFERROR(__xludf.DUMMYFUNCTION("""COMPUTED_VALUE"""),"SS2") -> SS2 | F22: =IFERROR(__xludf.DUMMYFUNCTION("""COMPUTED_VALUE"""),"Stream C") -> Stream C | G22: =IFERROR(__xludf.DUMMYFUNCTION("""COMPUTED_VALUE"""),"Bo2") -> Bo2 | H22: =IFERROR(__xludf.DUMMYFUNCTION("""COMPUTED_VALUE"""),0.4583333333333333) -> 0.45833333 | N22: =IFERROR(__xludf.DUMMYFUNCTION("""COMPUTED_VALUE"""),"Groupstage - Group A - Round Robin R2 #3") -> Groupstage - Group A - Round Robin R2 #3 | O22: =IFERROR(__xludf.DUMMYFUNCTION("""COMPUTED_VALUE"""),"Team Falcons vs. Rune Eaters") -> Team Falcons vs. Rune Eaters
C23: =IFERROR(__xludf.DUMMYFUNCTION("""COMPUTED_VALUE"""),46211.0) -> 46211 | E23: =IFERROR(__xludf.DUMMYFUNCTION("""COMPUTED_VALUE"""),"MS3") -> MS3 | F23: =IFERROR(__xludf.DUMMYFUNCTION("""COMPUTED_VALUE"""),"Stream A") -> Stream A | G23: =IFERROR(__xludf.DUMMYFUNCTION("""COMPUTED_VALUE"""),"Bo2") -> Bo2 | H23: =IFERROR(__xludf.DUMMYFUNCTION("""COMPUTED_VALUE"""),0.6041666666666666) -> 0.60416667 | N23: =IFERROR(__xludf.DUMMYFUNCTION("""COMPUTED_VALUE"""),"Groupstage - Group B - Round Robin R2 #1") -> Groupstage - Group B - Round Robin R2 #1 | O23: =IFERROR(__xludf.DUMMYFUNCTION("""COMPUTED_VALUE"""),"Nigma Galaxy vs. Aurora Gaming") -> Nigma Galaxy vs. Aurora Gaming
C24: =IFERROR(__xludf.DUMMYFUNCTION("""COMPUTED_VALUE"""),46211.0) -> 46211 | E24: =IFERROR(__xludf.DUMMYFUNCTION("""COMPUTED_VALUE"""),"SS3") -> SS3 | F24: =IFERROR(__xludf.DUMMYFUNCTION("""COMPUTED_VALUE"""),"Stream B") -> Stream B | G24: =IFERROR(__xludf.DUMMYFUNCTION("""COMPUTED_VALUE"""),"Bo2") -> Bo2 | H24: =IFERROR(__xludf.DUMMYFUNCTION("""COMPUTED_VALUE"""),0.5729166666666666) -> 0.57291667 | N24: =IFERROR(__xludf.DUMMYFUNCTION("""COMPUTED_VALUE"""),"Groupstage - Group B - Round Robin R2 #2") -> Groupstage - Group B - Round Robin R2 #2 | O24: =IFERROR(__xludf.DUMMYFUNCTION("""COMPUTED_VALUE"""),"L1 TEAM vs. PTime") -> L1 TEAM vs. PTime
C25: =IFERROR(__xludf.DUMMYFUNCTION("""COMPUTED_VALUE"""),46211.0) -> 46211 | E25: =IFERROR(__xludf.DUMMYFUNCTION("""COMPUTED_VALUE"""),"SS2") -> SS2 | F25: =IFERROR(__xludf.DUMMYFUNCTION("""COMPUTED_VALUE"""),"Stream C") -> Stream C | G25: =IFERROR(__xludf.DUMMYFUNCTION("""COMPUTED_VALUE"""),"Bo2") -> Bo2 | H25: =IFERROR(__xludf.DUMMYFUNCTION("""COMPUTED_VALUE"""),0.579861111111111) -> 0.57986111 | N25: =IFERROR(__xludf.DUMMYFUNCTION("""COMPUTED_VALUE"""),"Groupstage - Group B - Round Robin R2 #3") -> Groupstage - Group B - Round Robin R2 #3 | O25: =IFERROR(__xludf.DUMMYFUNCTION("""COMPUTED_VALUE"""),"Team Liquid vs. Level UP") -> Team Liquid vs. Level UP
C26: =IFERROR(__xludf.DUMMYFUNCTION("""COMPUTED_VALUE"""),46211.0) -> 46211 | E26: =IFERROR(__xludf.DUMMYFUNCTION("""COMPUTED_VALUE"""),"MS3") -> MS3 | F26: =IFERROR(__xludf.DUMMYFUNCTION("""COMPUTED_VALUE"""),"Stream A") -> Stream A | G26: =IFERROR(__xludf.DUMMYFUNCTION("""COMPUTED_VALUE"""),"Bo2") -> Bo2 | H26: =IFERROR(__xludf.DUMMYFUNCTION("""COMPUTED_VALUE"""),0.7430555555555555) -> 0.74305556 | N26: =IFERROR(__xludf.DUMMYFUNCTION("""COMPUTED_VALUE"""),"Groupstage - Group C - Round Robin R2 #1") -> Groupstage - Group C - Round Robin R2 #1 | O26: =IFERROR(__xludf.DUMMYFUNCTION("""COMPUTED_VALUE"""),"Vici Gaming vs. PVISION") -> Vici Gaming vs. PVISION
C27: =IFERROR(__xludf.DUMMYFUNCTION("""COMPUTED_VALUE"""),46211.0) -> 46211 | E27: =IFERROR(__xludf.DUMMYFUNCTION("""COMPUTED_VALUE"""),"SS3") -> SS3 | F27: =IFERROR(__xludf.DUMMYFUNCTION("""COMPUTED_VALUE"""),"Stream B") -> Stream B | G27: =IFERROR(__xludf.DUMMYFUNCTION("""COMPUTED_VALUE"""),"Bo2") -> Bo2 | H27: =IFERROR(__xludf.DUMMYFUNCTION("""COMPUTED_VALUE"""),0.6840277777777778) -> 0.68402778 | N27: =IFERROR(__xludf.DUMMYFUNCTION("""COMPUTED_VALUE"""),"Groupstage - Group C - Round Robin R2 #2") -> Groupstage - Group C - Round Robin R2 #2 | O27: =IFERROR(__xludf.DUMMYFUNCTION("""COMPUTED_VALUE"""),"REKONIX vs. MOUZ") -> REKONIX vs. MOUZ
C28: =IFERROR(__xludf.DUMMYFUNCTION("""COMPUTED_VALUE"""),46211.0) -> 46211 | E28: =IFERROR(__xludf.DUMMYFUNCTION("""COMPUTED_VALUE"""),"SS2") -> SS2 | F28: =IFERROR(__xludf.DUMMYFUNCTION("""COMPUTED_VALUE"""),"Stream C") -> Stream C | G28: =IFERROR(__xludf.DUMMYFUNCTION("""COMPUTED_VALUE"""),"Bo2") -> Bo2 | H28: =IFERROR(__xludf.DUMMYFUNCTION("""COMPUTED_VALUE"""),0.6979166666666666) -> 0.69791667 | N28: =IFERROR(__xludf.DUMMYFUNCTION("""COMPUTED_VALUE"""),"Groupstage - Group C - Round Robin R2 #3") -> Groupstage - Group C - Round Robin R2 #3 | O28: =IFERROR(__xludf.DUMMYFUNCTION("""COMPUTED_VALUE"""),"Team Spirit vs. Team Nemesis") -> Team Spirit vs. Team Nemesis
C29: =IFERROR(__xludf.DUMMYFUNCTION("""COMPUTED_VALUE"""),46211.0) -> 46211 | E29: =IFERROR(__xludf.DUMMYFUNCTION("""COMPUTED_VALUE"""),"MS3") -> MS3 | F29: =IFERROR(__xludf.DUMMYFUNCTION("""COMPUTED_VALUE"""),"Stream A") -> Stream A | G29: =IFERROR(__xludf.DUMMYFUNCTION("""COMPUTED_VALUE"""),"Bo2") -> Bo2 | H29: =IFERROR(__xludf.DUMMYFUNCTION("""COMPUTED_VALUE"""),0.8576388888888888) -> 0.85763889 | N29: =IFERROR(__xludf.DUMMYFUNCTION("""COMPUTED_VALUE"""),"Groupstage - Group D - Round Robin R2 #1") -> Groupstage - Group D - Round Robin R2 #1 | O29: =IFERROR(__xludf.DUMMYFUNCTION("""COMPUTED_VALUE"""),"Virtus.pro vs. 1W") -> Virtus.pro vs. 1W
C30: =IFERROR(__xludf.DUMMYFUNCTION("""COMPUTED_VALUE"""),46211.0) -> 46211 | E30: =IFERROR(__xludf.DUMMYFUNCTION("""COMPUTED_VALUE"""),"SS3") -> SS3 | F30: =IFERROR(__xludf.DUMMYFUNCTION("""COMPUTED_VALUE"""),"Stream B") -> Stream B | G30: =IFERROR(__xludf.DUMMYFUNCTION("""COMPUTED_VALUE"""),"Bo2") -> Bo2 | H30: =IFERROR(__xludf.DUMMYFUNCTION("""COMPUTED_VALUE"""),0.8020833333333333) -> 0.80208333 | N30: =IFERROR(__xludf.DUMMYFUNCTION("""COMPUTED_VALUE"""),"Groupstage - Group D - Round Robin R2 #2") -> Groupstage - Group D - Round Robin R2 #2 | O30: =IFERROR(__xludf.DUMMYFUNCTION("""COMPUTED_VALUE"""),"LGD Gaming vs. OG Esports") -> LGD Gaming vs. OG Esports
C31: =IFERROR(__xludf.DUMMYFUNCTION("""COMPUTED_VALUE"""),46211.0) -> 46211 | E31: =IFERROR(__xludf.DUMMYFUNCTION("""COMPUTED_VALUE"""),"SS2") -> SS2 | F31: =IFERROR(__xludf.DUMMYFUNCTION("""COMPUTED_VALUE"""),"Stream C") -> Stream C | G31: =IFERROR(__xludf.DUMMYFUNCTION("""COMPUTED_VALUE"""),"Bo2") -> Bo2 | H31: =IFERROR(__xludf.DUMMYFUNCTION("""COMPUTED_VALUE"""),0.8229166666666666) -> 0.82291667 | N31: =IFERROR(__xludf.DUMMYFUNCTION("""COMPUTED_VALUE"""),"Groupstage - Group D - Round Robin R2 #3") -> Groupstage - Group D - Round Robin R2 #3 | O31: =IFERROR(__xludf.DUMMYFUNCTION("""COMPUTED_VALUE"""),"Team Yandex vs. IC x Insanity") -> Team Yandex vs. IC x Insanity
C32: =IFERROR(__xludf.DUMMYFUNCTION("""COMPUTED_VALUE"""),46211.0) -> 46211 | H32: =IFERROR(__xludf.DUMMYFUNCTION("""COMPUTED_VALUE"""),0.9409722222222222) -> 0.94097222
B33: =IFERROR(__xludf.DUMMYFUNCTION("""COMPUTED_VALUE"""),3.0) -> 3 | C33: =IFERROR(__xludf.DUMMYFUNCTION("""COMPUTED_VALUE"""),46212.0) -> 46212 | D33: =IFERROR(__xludf.DUMMYFUNCTION("""COMPUTED_VALUE"""),46212.0) -> 46212 | E33: =IFERROR(__xludf.DUMMYFUNCTION("""COMPUTED_VALUE"""),"MS3") -> MS3 | F33: =IFERROR(__xludf.DUMMYFUNCTION("""COMPUTED_VALUE"""),"Stream A") -> Stream A | G33: =IFERROR(__xludf.DUMMYFUNCTION("""COMPUTED_VALUE"""),"Bo2") -> Bo2 | H33: =IFERROR(__xludf.DUMMYFUNCTION("""COMPUTED_VALUE"""),0.5451388888888888) -> 0.54513889 | N33: =IFERROR(__xludf.DUMMYFUNCTION("""COMPUTED_VALUE"""),"Groupstage - Group A - Round Robin R3 #1") -> Groupstage - Group A - Round Robin R3 #1 | O33: =IFERROR(__xludf.DUMMYFUNCTION("""COMPUTED_VALUE"""),"GamerLegion vs. Team Falcons") -> GamerLegion vs. Team Falcons
C34: =IFERROR(__xludf.DUMMYFUNCTION("""COMPUTED_VALUE"""),46212.0) -> 46212 | E34: =IFERROR(__xludf.DUMMYFUNCTION("""COMPUTED_VALUE"""),"SS3") -> SS3 | F34: =IFERROR(__xludf.DUMMYFUNCTION("""COMPUTED_VALUE"""),"Stream B") -> Stream B | G34: =IFERROR(__xludf.DUMMYFUNCTION("""COMPUTED_VALUE"""),"Bo2") -> Bo2 | H34: =IFERROR(__xludf.DUMMYFUNCTION("""COMPUTED_VALUE"""),0.4583333333333333) -> 0.45833333 | N34: =IFERROR(__xludf.DUMMYFUNCTION("""COMPUTED_VALUE"""),"Groupstage - Group A - Round Robin R3 #2") -> Groupstage - Group A - Round Robin R3 #2 | O34: =IFERROR(__xludf.DUMMYFUNCTION("""COMPUTED_VALUE"""),"Poor Rangers vs. Xtreme Gaming") -> Poor Rangers vs. Xtreme Gaming
C35: =IFERROR(__xludf.DUMMYFUNCTION("""COMPUTED_VALUE"""),46212.0) -> 46212 | E35: =IFERROR(__xludf.DUMMYFUNCTION("""COMPUTED_VALUE"""),"SS2") -> SS2 | F35: =IFERROR(__xludf.DUMMYFUNCTION("""COMPUTED_VALUE"""),"Stream C") -> Stream C | G35: =IFERROR(__xludf.DUMMYFUNCTION("""COMPUTED_VALUE"""),"Bo2") -> Bo2 | H35: =IFERROR(__xludf.DUMMYFUNCTION("""COMPUTED_VALUE"""),0.7222222222222222) -> 0.72222222 | N35: =IFERROR(__xludf.DUMMYFUNCTION("""COMPUTED_VALUE"""),"Groupstage - Group A - Round Robin R3 #3") -> Groupstage - Group A - Round Robin R3 #3 | O35: =IFERROR(__xludf.DUMMYFUNCTION("""COMPUTED_VALUE"""),"BB Team vs. Rune Eaters") -> BB Team vs. Rune Eaters
C36: =IFERROR(__xludf.DUMMYFUNCTION("""COMPUTED_VALUE"""),46212.0) -> 46212 | E36: =IFERROR(__xludf.DUMMYFUNCTION("""COMPUTED_VALUE"""),"MS3") -> MS3 | F36: =IFERROR(__xludf.DUMMYFUNCTION("""COMPUTED_VALUE"""),"Stream A") -> Stream A | G36: =IFERROR(__xludf.DUMMYFUNCTION("""COMPUTED_VALUE"""),"Bo2") -> Bo2 | H36: =IFERROR(__xludf.DUMMYFUNCTION("""COMPUTED_VALUE"""),0.6631944444444444) -> 0.66319444 | N36: =IFERROR(__xludf.DUMMYFUNCTION("""COMPUTED_VALUE"""),"Groupstage - Group B - Round Robin R3 #1") -> Groupstage - Group B - Round Robin R3 #1 | O36: =IFERROR(__xludf.DUMMYFUNCTION("""COMPUTED_VALUE"""),"Nigma Galaxy vs. Team Liquid") -> Nigma Galaxy vs. Team Liquid
C37: =IFERROR(__xludf.DUMMYFUNCTION("""COMPUTED_VALUE"""),46212.0) -> 46212 | E37: =IFERROR(__xludf.DUMMYFUNCTION("""COMPUTED_VALUE"""),"SS3") -> SS3 | F37: =IFERROR(__xludf.DUMMYFUNCTION("""COMPUTED_VALUE"""),"Stream B") -> Stream B | G37: =IFERROR(__xludf.DUMMYFUNCTION("""COMPUTED_VALUE"""),"Bo2") -> Bo2 | H37: =IFERROR(__xludf.DUMMYFUNCTION("""COMPUTED_VALUE"""),0.5625) -> 0.5625 | N37: =IFERROR(__xludf.DUMMYFUNCTION("""COMPUTED_VALUE"""),"Groupstage - Group B - Round Robin R3 #2") -> Groupstage - Group B - Round Robin R3 #2 | O37: =IFERROR(__xludf.DUMMYFUNCTION("""COMPUTED_VALUE"""),"L1 TEAM vs. Aurora Gaming") -> L1 TEAM vs. Aurora Gaming
C38: =IFERROR(__xludf.DUMMYFUNCTION("""COMPUTED_VALUE"""),46212.0) -> 46212 | E38: =IFERROR(__xludf.DUMMYFUNCTION("""COMPUTED_VALUE"""),"SS2") -> SS2 | F38: =IFERROR(__xludf.DUMMYFUNCTION("""COMPUTED_VALUE"""),"Stream C") -> Stream C | G38: =IFERROR(__xludf.DUMMYFUNCTION("""COMPUTED_VALUE"""),"Bo2") -> Bo2 | H38: =IFERROR(__xludf.DUMMYFUNCTION("""COMPUTED_VALUE"""),0.8263888888888888) -> 0.82638889 | N38: =IFERROR(__xludf.DUMMYFUNCTION("""COMPUTED_VALUE"""),"Groupstage - Group B - Round Robin R3 #3") -> Groupstage - Group B - Round Robin R3 #3 | O38: =IFERROR(__xludf.DUMMYFUNCTION("""COMPUTED_VALUE"""),"PTime vs. Level UP") -> PTime vs. Level UP
C39: =IFERROR(__xludf.DUMMYFUNCTION("""COMPUTED_VALUE"""),46212.0) -> 46212 | E39: =IFERROR(__xludf.DUMMYFUNCTION("""COMPUTED_VALUE"""),"MS3") -> MS3 | F39: =IFERROR(__xludf.DUMMYFUNCTION("""COMPUTED_VALUE"""),"Stream A") -> Stream A | G39: =IFERROR(__xludf.DUMMYFUNCTION("""COMPUTED_VALUE"""),"Bo2") -> Bo2 | H39: =IFERROR(__xludf.DUMMYFUNCTION("""COMPUTED_VALUE"""),0.767361111111111) -> 0.76736111 | N39: =IFERROR(__xludf.DUMMYFUNCTION("""COMPUTED_VALUE"""),"Groupstage - Group C - Round Robin R3 #1") -> Groupstage - Group C - Round Robin R3 #1 | O39: =IFERROR(__xludf.DUMMYFUNCTION("""COMPUTED_VALUE"""),"Vici Gaming vs. Team Spirit") -> Vici Gaming vs. Team Spirit
C40: =IFERROR(__xludf.DUMMYFUNCTION("""COMPUTED_VALUE"""),46212.0) -> 46212 | E40: =IFERROR(__xludf.DUMMYFUNCTION("""COMPUTED_VALUE"""),"SS3") -> SS3 | F40: =IFERROR(__xludf.DUMMYFUNCTION("""COMPUTED_VALUE"""),"Stream B") -> Stream B | G40: =IFERROR(__xludf.DUMMYFUNCTION("""COMPUTED_VALUE"""),"Bo2") -> Bo2 | H40: =IFERROR(__xludf.DUMMYFUNCTION("""COMPUTED_VALUE"""),0.6666666666666666) -> 0.66666667 | N40: =IFERROR(__xludf.DUMMYFUNCTION("""COMPUTED_VALUE"""),"Groupstage - Group C - Round Robin R3 #2") -> Groupstage - Group C - Round Robin R3 #2 | O40: =IFERROR(__xludf.DUMMYFUNCTION("""COMPUTED_VALUE"""),"MOUZ vs. Team Nemesis") -> MOUZ vs. Team Nemesis
C41: =IFERROR(__xludf.DUMMYFUNCTION("""COMPUTED_VALUE"""),46212.0) -> 46212 | E41: =IFERROR(__xludf.DUMMYFUNCTION("""COMPUTED_VALUE"""),"SS2") -> SS2 | F41: =IFERROR(__xludf.DUMMYFUNCTION("""COMPUTED_VALUE"""),"Stream C") -> Stream C | G41: =IFERROR(__xludf.DUMMYFUNCTION("""COMPUTED_VALUE"""),"Bo2") -> Bo2 | H41: =IFERROR(__xludf.DUMMYFUNCTION("""COMPUTED_VALUE"""),0.9305555555555555) -> 0.93055556 | N41: =IFERROR(__xludf.DUMMYFUNCTION("""COMPUTED_VALUE"""),"Groupstage - Group C - Round Robin R3 #3") -> Groupstage - Group C - Round Robin R3 #3 | O41: =IFERROR(__xludf.DUMMYFUNCTION("""COMPUTED_VALUE"""),"REKONIX vs. PVISION") -> REKONIX vs. PVISION
...

Sheet Schedule - Bronze Bracket
N1: Phase 1 | O1: Phase 2 | P1: Playoffs
B4: Tournament Day # | D4: Date | E4: Week | F4: Stream | G4: Best of X | H4: Start Time | N4: Round | O4: Match | P4: Comment
H5: - PUBLIC- - AST - | I5: - PUBLIC- - CEST - | J5: - PUBLIC- - EDT - | K5: - PUBLIC- - BRT - | L5: - PUBLIC- - CST - | M5: - PUBLIC- - AEST-
I6: -1 | J6: -7 | K6: -6 | L6: +5 | M6: +7
B7: 1 | C7: {=iferror( vlookup( row(D7:D110), if( len(D7:D110), { row(D7:D110), D7:D110 } ), 2, true ) ,"")} -> #REF! | E7: {=IF( F7="End", "", IFERROR( INDEX(stage!$C$2:$D$100, MATCH(C7, stage!$B$2:$B$100, 0), IF(OR(F7="Stream A", F7="A End"), 1, 2) ), "" ) )} | F7: Stream A | G7: Bo2 | H7: 0.5 | N7: Group A - Round Robin R1 #1
E8: {=IF( F8="End", "", IFERROR( INDEX(stage!$C$2:$D$100, MATCH(C8, stage!$B$2:$B$100, 0), IF(OR(F8="Stream A", F8="A End"), 1, 2) ), "" ) )} | F8: Stream B | G8: Bo2 | H8: =H7 -> 0.5 | N8: Group A - Round Robin R1 #2
E9: {=IF( F9="End", "", IFERROR( INDEX(stage!$C$2:$D$100, MATCH(C9, stage!$B$2:$B$100, 0), IF(OR(F9="Stream A", F9="A End"), 1, 2) ), "" ) )} | F9: Stream C | G9: Bo2 | H9: =H7 -> 0.5 | N9: Group A - Round Robin R1 #3
E10: {=IF( F10="End", "", IFERROR( INDEX(stage!$C$2:$D$100, MATCH(C10, stage!$B$2:$B$100, 0), IF(OR(F10="Stream A", F10="A End"), 1, 2) ), "" ) )} | F10: Stream A | G10: Bo2 | H10: =H7+"02:30:00" -> 0.60416667 | N10: Group B - Round Robin R1 #1
E11: {=IF( F11="End", "", IFERROR( INDEX(stage!$C$2:$D$100, MATCH(C11, stage!$B$2:$B$100, 0), IF(OR(F11="Stream A", F11="A End"), 1, 2) ), "" ) )} | F11: Stream B | G11: Bo2 | H11: =H10 -> 0.60416667 | N11: Group B - Round Robin R1 #2
E12: {=IF( F12="End", "", IFERROR( INDEX(stage!$C$2:$D$100, MATCH(C12, stage!$B$2:$B$100, 0), IF(OR(F12="Stream A", F12="A End"), 1, 2) ), "" ) )} | F12: Stream C | G12: Bo2 | H12: =H11 -> 0.60416667 | N12: Group B - Round Robin R1 #3
E13: {=IF( F13="End", "", IFERROR( INDEX(stage!$C$2:$D$100, MATCH(C13, stage!$B$2:$B$100, 0), IF(OR(F13="Stream A", F13="A End"), 1, 2) ), "" ) )} | F13: Stream A | G13: Bo2 | H13: =H10+"02:30:00" -> 0.70833333 | N13: Group C - Round Robin R1 #1
E14: {=IF( F14="End", "", IFERROR( INDEX(stage!$C$2:$D$100, MATCH(C14, stage!$B$2:$B$100, 0), IF(OR(F14="Stream A", F14="A End"), 1, 2) ), "" ) )} | F14: Stream B | G14: Bo2 | H14: =H13 -> 0.70833333 | N14: Group C - Round Robin R1 #2
E15: {=IF( F15="End", "", IFERROR( INDEX(stage!$C$2:$D$100, MATCH(C15, stage!$B$2:$B$100, 0), IF(OR(F15="Stream A", F15="A End"), 1, 2) ), "" ) )} | F15: Stream C | G15: Bo2 | H15: =H14 -> 0.70833333 | N15: Group C - Round Robin R1 #3
E16: {=IF( F16="End", "", IFERROR( INDEX(stage!$C$2:$D$100, MATCH(C16, stage!$B$2:$B$100, 0), IF(OR(F16="Stream A", F16="A End"), 1, 2) ), "" ) )} | F16: Stream A | G16: Bo2 | H16: =H13+"02:30:00" -> 0.8125 | N16: Group D - Round Robin R1 #1
E17: {=IF( F17="End", "", IFERROR( INDEX(stage!$C$2:$D$100, MATCH(C17, stage!$B$2:$B$100, 0), IF(OR(F17="Stream A", F17="A End"), 1, 2) ), "" ) )} | F17: Stream B | G17: Bo2 | H17: =H16 -> 0.8125 | N17: Group D - Round Robin R1 #2
E18: {=IF( F18="End", "", IFERROR( INDEX(stage!$C$2:$D$100, MATCH(C18, stage!$B$2:$B$100, 0), IF(OR(F18="Stream A", F18="A End"), 1, 2) ), "" ) )} | F18: Stream C | G18: Bo2 | H18: =H17 -> 0.8125 | N18: Group D - Round Robin R1 #3
E19: {=IF( F19="End", "", IFERROR( INDEX(stage!$C$2:$D$100, MATCH(C19, stage!$B$2:$B$100, 0), IF(OR(F19="Stream A", F19="A End"), 1, 2) ), "" ) )} | H19: =H16+"02:00:00" -> 0.89583333
B20: 2 | E20: {=IF( F20="End", "", IFERROR( INDEX(stage!$C$2:$D$100, MATCH(C20, stage!$B$2:$B$100, 0), IF(OR(F20="Stream A", F20="A End"), 1, 2) ), "" ) )} | F20: Stream A | G20: Bo2 | H20: 0.5 | N20: Group A - Round Robin R2 #1
E21: {=IF( F21="End", "", IFERROR( INDEX(stage!$C$2:$D$100, MATCH(C21, stage!$B$2:$B$100, 0), IF(OR(F21="Stream A", F21="A End"), 1, 2) ), "" ) )} | F21: Stream B | G21: Bo2 | H21: =H20 -> 0.5 | N21: Group A - Round Robin R2 #2
E22: {=IF( F22="End", "", IFERROR( INDEX(stage!$C$2:$D$100, MATCH(C22, stage!$B$2:$B$100, 0), IF(OR(F22="Stream A", F22="A End"), 1, 2) ), "" ) )} | F22: Stream C | G22: Bo2 | H22: =H20 -> 0.5 | N22: Group A - Round Robin R2 #3
E23: {=IF( F23="End", "", IFERROR( INDEX(stage!$C$2:$D$100, MATCH(C23, stage!$B$2:$B$100, 0), IF(OR(F23="Stream A", F23="A End"), 1, 2) ), "" ) )} | F23: Stream A | G23: Bo2 | H23: =H20+"02:30:00" -> 0.60416667 | N23: Group B - Round Robin R2 #1
E24: {=IF( F24="End", "", IFERROR( INDEX(stage!$C$2:$D$100, MATCH(C24, stage!$B$2:$B$100, 0), IF(OR(F24="Stream A", F24="A End"), 1, 2) ), "" ) )} | F24: Stream B | G24: Bo2 | H24: =H23 -> 0.60416667 | N24: Group B - Round Robin R2 #2
E25: {=IF( F25="End", "", IFERROR( INDEX(stage!$C$2:$D$100, MATCH(C25, stage!$B$2:$B$100, 0), IF(OR(F25="Stream A", F25="A End"), 1, 2) ), "" ) )} | F25: Stream C | G25: Bo2 | H25: =H24 -> 0.60416667 | N25: Group B - Round Robin R2 #3
E26: {=IF( F26="End", "", IFERROR( INDEX(stage!$C$2:$D$100, MATCH(C26, stage!$B$2:$B$100, 0), IF(OR(F26="Stream A", F26="A End"), 1, 2) ), "" ) )} | F26: Stream A | G26: Bo2 | H26: =H23+"02:30:00" -> 0.70833333 | N26: Group C - Round Robin R2 #1
E27: {=IF( F27="End", "", IFERROR( INDEX(stage!$C$2:$D$100, MATCH(C27, stage!$B$2:$B$100, 0), IF(OR(F27="Stream A", F27="A End"), 1, 2) ), "" ) )} | F27: Stream B | G27: Bo2 | H27: =H26 -> 0.70833333 | N27: Group C - Round Robin R2 #2
E28: {=IF( F28="End", "", IFERROR( INDEX(stage!$C$2:$D$100, MATCH(C28, stage!$B$2:$B$100, 0), IF(OR(F28="Stream A", F28="A End"), 1, 2) ), "" ) )} | F28: Stream C | G28: Bo2 | H28: =H27 -> 0.70833333 | N28: Group C - Round Robin R2 #3
E29: {=IF( F29="End", "", IFERROR( INDEX(stage!$C$2:$D$100, MATCH(C29, stage!$B$2:$B$100, 0), IF(OR(F29="Stream A", F29="A End"), 1, 2) ), "" ) )} | F29: Stream A | G29: Bo2 | H29: =H26+"02:30:00" -> 0.8125 | N29: Group D - Round Robin R2 #1
E30: {=IF( F30="End", "", IFERROR( INDEX(stage!$C$2:$D$100, MATCH(C30, stage!$B$2:$B$100, 0), IF(OR(F30="Stream A", F30="A End"), 1, 2) ), "" ) )} | F30: Stream B | G30: Bo2 | H30: =H29 -> 0.8125 | N30: Group D - Round Robin R2 #2
E31: {=IF( F31="End", "", IFERROR( INDEX(stage!$C$2:$D$100, MATCH(C31, stage!$B$2:$B$100, 0), IF(OR(F31="Stream A", F31="A End"), 1, 2) ), "" ) )} | F31: Stream C | G31: Bo2 | H31: =H30 -> 0.8125 | N31: Group D - Round Robin R2 #3
E32: {=IF( F32="End", "", IFERROR( INDEX(stage!$C$2:$D$100, MATCH(C32, stage!$B$2:$B$100, 0), IF(OR(F32="Stream A", F32="A End"), 1, 2) ), "" ) )} | H32: =H29+"02:00:00" -> 0.89583333
B33: 3 | E33: {=IF( F33="End", "", IFERROR( INDEX(stage!$C$2:$D$100, MATCH(C33, stage!$B$2:$B$100, 0), IF(OR(F33="Stream A", F33="A End"), 1, 2) ), "" ) )} | F33: Stream A | G33: Bo2 | H33: 0.5 | N33: Group A - Round Robin R3 #1
E34: {=IF( F34="End", "", IFERROR( INDEX(stage!$C$2:$D$100, MATCH(C34, stage!$B$2:$B$100, 0), IF(OR(F34="Stream A", F34="A End"), 1, 2) ), "" ) )} | F34: Stream B | G34: Bo2 | H34: =H33 -> 0.5 | N34: Group A - Round Robin R3 #2
E35: {=IF( F35="End", "", IFERROR( INDEX(stage!$C$2:$D$100, MATCH(C35, stage!$B$2:$B$100, 0), IF(OR(F35="Stream A", F35="A End"), 1, 2) ), "" ) )} | F35: Stream C | G35: Bo2 | H35: =H33 -> 0.5 | N35: Group A - Round Robin R3 #3
E36: {=IF( F36="End", "", IFERROR( INDEX(stage!$C$2:$D$100, MATCH(C36, stage!$B$2:$B$100, 0), IF(OR(F36="Stream A", F36="A End"), 1, 2) ), "" ) )} | F36: Stream A | G36: Bo2 | H36: =H33+"02:30:00" -> 0.60416667 | N36: Group B - Round Robin R3 #1
E37: {=IF( F37="End", "", IFERROR( INDEX(stage!$C$2:$D$100, MATCH(C37, stage!$B$2:$B$100, 0), IF(OR(F37="Stream A", F37="A End"), 1, 2) ), "" ) )} | F37: Stream B | G37: Bo2 | H37: =H36 -> 0.60416667 | N37: Group B - Round Robin R3 #2
E38: {=IF( F38="End", "", IFERROR( INDEX(stage!$C$2:$D$100, MATCH(C38, stage!$B$2:$B$100, 0), IF(OR(F38="Stream A", F38="A End"), 1, 2) ), "" ) )} | F38: Stream C | G38: Bo2 | H38: =H37 -> 0.60416667 | N38: Group B - Round Robin R3 #3
E39: {=IF( F39="End", "", IFERROR( INDEX(stage!$C$2:$D$100, MATCH(C39, stage!$B$2:$B$100, 0), IF(OR(F39="Stream A", F39="A End"), 1, 2) ), "" ) )} | F39: Stream A | G39: Bo2 | H39: =H36+"02:30:00" -> 0.70833333 | N39: Group C - Round Robin R3 #1
E40: {=IF( F40="End", "", IFERROR( INDEX(stage!$C$2:$D$100, MATCH(C40, stage!$B$2:$B$100, 0), IF(OR(F40="Stream A", F40="A End"), 1, 2) ), "" ) )} | F40: Stream B | G40: Bo2 | H40: =H39 -> 0.70833333 | N40: Group C - Round Robin R3 #2
E41: {=IF( F41="End", "", IFERROR( INDEX(stage!$C$2:$D$100, MATCH(C41, stage!$B$2:$B$100, 0), IF(OR(F41="Stream A", F41="A End"), 1, 2) ), "" ) )} | F41: Stream C | G41: Bo2 | H41: =H40 -> 0.70833333 | N41: Group C - Round Robin R3 #3
E42: {=IF( F42="End", "", IFERROR( INDEX(stage!$C$2:$D$100, MATCH(C42, stage!$B$2:$B$100, 0), IF(OR(F42="Stream A", F42="A End"), 1, 2) ), "" ) )} | F42: Stream A | G42: Bo2 | H42: =H39+"02:30:00" -> 0.8125 | N42: Group D - Round Robin R3 #1
...

Sheet Schedule SE32
N1: Phase 1 | O1: Phase 2 | P1: Playoffs
B4: Tournament Day # | D4: Date | E4: Week | F4: Stream | G4: Best of X | H4: Start Time | N4: Round | O4: Match | P4: Comment
H5: - PUBLIC- - AST - | I5: - PUBLIC- - CEST - | J5: - PUBLIC- - EDT - | K5: - PUBLIC- - BRT - | L5: - PUBLIC- - CST - | M5: - PUBLIC- - AEST-
I6: -1 | J6: -7 | K6: -6 | L6: +5 | M6: +7
B7: 1 | C7: {=iferror( vlookup( row(D7:D126), if( len(D7:D126), { row(D7:D126), D7:D126 } ), 2, true ) ,"")} | E7: {=IF( F7="End", "", IFERROR( INDEX(stage!$C$2:$D$100, MATCH(C7, stage!$B$2:$B$100, 0), IF(OR(F7="Stream A", F7="A End"), 1, 2) ), "" ) )} | F7: Stream A | H7: 0 | N7: Ro32
E8: {=IF( F8="End", "", IFERROR( INDEX(stage!$C$2:$D$100, MATCH(C8, stage!$B$2:$B$100, 0), IF(OR(F8="Stream A", F8="A End"), 1, 2) ), "" ) )} | F8: Stream B | H8: =H7 -> 0 | N8: Ro32
E9: {=IF( F9="End", "", IFERROR( INDEX(stage!$C$2:$D$100, MATCH(C9, stage!$B$2:$B$100, 0), IF(OR(F9="Stream A", F9="A End"), 1, 2) ), "" ) )} | F9: Stream A | H9: =H7+"03:30:00" -> 0.14583333 | N9: Ro32
E10: {=IF( F10="End", "", IFERROR( INDEX(stage!$C$2:$D$100, MATCH(C10, stage!$B$2:$B$100, 0), IF(OR(F10="Stream A", F10="A End"), 1, 2) ), "" ) )} | F10: Stream B | H10: =H9 -> 0.14583333 | N10: Ro32
E11: {=IF( F11="End", "", IFERROR( INDEX(stage!$C$2:$D$100, MATCH(C11, stage!$B$2:$B$100, 0), IF(OR(F11="Stream A", F11="A End"), 1, 2) ), "" ) )} | H11: =H9+"03:00:00" -> 0.27083333
B12: 2 | E12: {=IF( F12="End", "", IFERROR( INDEX(stage!$C$2:$D$100, MATCH(C12, stage!$B$2:$B$100, 0), IF(OR(F12="Stream A", F12="A End"), 1, 2) ), "" ) )} | F12: Stream A | H12: 0 | N12: Ro32
E13: {=IF( F13="End", "", IFERROR( INDEX(stage!$C$2:$D$100, MATCH(C13, stage!$B$2:$B$100, 0), IF(OR(F13="Stream A", F13="A End"), 1, 2) ), "" ) )} | F13: Stream B | H13: =H12 -> 0 | N13: Ro32
E14: {=IF( F14="End", "", IFERROR( INDEX(stage!$C$2:$D$100, MATCH(C14, stage!$B$2:$B$100, 0), IF(OR(F14="Stream A", F14="A End"), 1, 2) ), "" ) )} | F14: Stream A | H14: =H12+"03:30:00" -> 0.14583333 | N14: Ro32
E15: {=IF( F15="End", "", IFERROR( INDEX(stage!$C$2:$D$100, MATCH(C15, stage!$B$2:$B$100, 0), IF(OR(F15="Stream A", F15="A End"), 1, 2) ), "" ) )} | F15: Stream B | H15: =H14 -> 0.14583333 | N15: Ro32
E16: {=IF( F16="End", "", IFERROR( INDEX(stage!$C$2:$D$100, MATCH(C16, stage!$B$2:$B$100, 0), IF(OR(F16="Stream A", F16="A End"), 1, 2) ), "" ) )} | H16: =H14+"03:00:00" -> 0.27083333
B17: 3 | E17: {=IF( F17="End", "", IFERROR( INDEX(stage!$C$2:$D$100, MATCH(C17, stage!$B$2:$B$100, 0), IF(OR(F17="Stream A", F17="A End"), 1, 2) ), "" ) )} | F17: Stream A | H17: 0 | N17: Ro32
E18: {=IF( F18="End", "", IFERROR( INDEX(stage!$C$2:$D$100, MATCH(C18, stage!$B$2:$B$100, 0), IF(OR(F18="Stream A", F18="A End"), 1, 2) ), "" ) )} | F18: Stream B | H18: =H17 -> 0 | N18: Ro32
E19: {=IF( F19="End", "", IFERROR( INDEX(stage!$C$2:$D$100, MATCH(C19, stage!$B$2:$B$100, 0), IF(OR(F19="Stream A", F19="A End"), 1, 2) ), "" ) )} | F19: Stream A | H19: =H17+"03:30:00" -> 0.14583333 | N19: Ro32
E20: {=IF( F20="End", "", IFERROR( INDEX(stage!$C$2:$D$100, MATCH(C20, stage!$B$2:$B$100, 0), IF(OR(F20="Stream A", F20="A End"), 1, 2) ), "" ) )} | F20: Stream B | H20: =H19 -> 0.14583333 | N20: Ro32
E21: {=IF( F21="End", "", IFERROR( INDEX(stage!$C$2:$D$100, MATCH(C21, stage!$B$2:$B$100, 0), IF(OR(F21="Stream A", F21="A End"), 1, 2) ), "" ) )} | H21: =H19+"03:00:00" -> 0.27083333
