Workbook
Name gamedata: data!$P$2:$BL$17
Name qualteams: qualdata!$N$2:$N$17
Name swissdata: qualdata!$P$2:$BR$17
Name qualgamedata: qualdata!$P$2:$BL$17
Name qualheader: qualdata!$P$1:$BR$1
Name teams: data!$N$2:$N$17
Name swissdata: data!$P$2:$BR$17
Name header: data!$P$1:$BR$1

Sheet Schedule
C1: Date | I1: Time CEST | N1: Team 1 | AB1: Score | AF1: Team 2 | AU1: Format | AZ1: Round | BS1: Caster | CE1: DEMO
C5: Contenders Swiss Stage
C9: Schedule has not yet been finalized and is not publicly available. Once it is created and officially approved, each participating team will receive a notification.
C12: 20.07 | I12: 0.47916667 | N12: {=xlookup(P12,qualdata!$N$2:$N$17,qualdata!$O$2:$O$17,"")} | P12: ='Contender Schedule'!V5 -> Team 1 (Group 1) | AB12: ='Contender Schedule'!AH5 | AD12: ='Contender Schedule'!AJ5 | AF12: ='Contender Schedule'!AL5 -> Team 16 (Group 1) | AR12: {=xlookup(AF12,qualdata!$N$2:$N$17,qualdata!$O$2:$O$17,"")} | AU12: Bo3 | AZ12: Contender Round 1 | BS12: TBA | CE12: Link
C14: 20.07 | I14: 0.60416667 | N14: {=xlookup(P14,qualdata!$N$2:$N$17,qualdata!$O$2:$O$17,"")} | P14: ='Contender Schedule'!V7 -> Team 2 (Group 1) | AB14: ='Contender Schedule'!AH7 | AD14: ='Contender Schedule'!AJ7 | AF14: ='Contender Schedule'!AL7 -> Team 15 (Group 1) | AR14: {=xlookup(AF14,qualdata!$N$2:$N$17,qualdata!$O$2:$O$17,"")} | AU14: Bo3 | AZ14: Contender Round 1 | BS14: TBA | CE14: Link
C16: 20.07 | I16: 0.72916667 | N16: {=xlookup(P16,qualdata!$N$2:$N$17,qualdata!$O$2:$O$17,"")} | P16: ='Contender Schedule'!V9 -> Team 3 (Group 1) | AB16: ='Contender Schedule'!AH9 | AD16: ='Contender Schedule'!AJ9 | AF16: ='Contender Schedule'!AL9 -> Team 14 (Group 1) | AR16: {=xlookup(AF16,qualdata!$N$2:$N$17,qualdata!$O$2:$O$17,"")} | AU16: Bo3 | AZ16: Contender Round 1 | BS16: TBA | CE16: Link
C18: 20.07 | I18: 0.85416667 | N18: {=xlookup(P18,qualdata!$N$2:$N$17,qualdata!$O$2:$O$17,"")} | P18: ='Contender Schedule'!V11 -> Team 4 (Group 1) | AB18: ='Contender Schedule'!AH11 | AD18: ='Contender Schedule'!AJ11 | AF18: ='Contender Schedule'!AL11 -> Team 13 (Group 1) | AR18: {=xlookup(AF18,qualdata!$N$2:$N$17,qualdata!$O$2:$O$17,"")} | AU18: Bo3 | AZ18: Contender Round 1 | BS18: TBA | CE18: Link
C20: 21.07 | I20: 0.47916667 | N20: {=xlookup(P20,qualdata!$N$2:$N$17,qualdata!$O$2:$O$17,"")} | P20: ='Contender Schedule'!V13 -> Team 5 (Group 1) | AB20: ='Contender Schedule'!AH13 | AD20: ='Contender Schedule'!AJ13 | AF20: ='Contender Schedule'!AL13 -> Team 12 (Group 1) | AR20: {=xlookup(AF20,qualdata!$N$2:$N$17,qualdata!$O$2:$O$17,"")} | AU20: Bo3 | AZ20: Contender Round 1 | BS20: TBA | CE20: Link
C22: 21.07 | I22: 0.60416667 | N22: {=xlookup(P22,qualdata!$N$2:$N$17,qualdata!$O$2:$O$17,"")} | P22: ='Contender Schedule'!V15 -> Team 6 (Group 1) | AB22: ='Contender Schedule'!AH15 | AD22: ='Contender Schedule'!AJ15 | AF22: ='Contender Schedule'!AL15 -> Team 11 (Group 1) | AR22: {=xlookup(AF22,qualdata!$N$2:$N$17,qualdata!$O$2:$O$17,"")} | AU22: Bo3 | AZ22: Contender Round 1 | BS22: TBA | CE22: Link
C24: 21.07 | I24: 0.72916667 | N24: {=xlookup(P24,qualdata!$N$2:$N$17,qualdata!$O$2:$O$17,"")} | P24: ='Contender Schedule'!V17 -> Team 7 (Group 1) | AB24: ='Contender Schedule'!AH17 | AD24: ='Contender Schedule'!AJ17 | AF24: ='Contender Schedule'!AL17 -> Team 10 (Group 1) | AR24: {=xlookup(AF24,qualdata!$N$2:$N$17,qualdata!$O$2:$O$17,"")} | AU24: Bo3 | AZ24: Contender Round 1 | BS24: TBA | CE24: Link
C26: 21.07 | I26: 0.85416667 | N26: {=xlookup(P26,qualdata!$N$2:$N$17,qualdata!$O$2:$O$17,"")} | P26: ='Contender Schedule'!V19 -> Team 8 (Group 1) | AB26: ='Contender Schedule'!AH19 | AD26: ='Contender Schedule'!AJ19 | AF26: ='Contender Schedule'!AL19 -> Team 9 (Group 1) | AR26: {=xlookup(AF26,qualdata!$N$2:$N$17,qualdata!$O$2:$O$17,"")} | AU26: Bo3 | AZ26: Contender Round 1 | BS26: TBA | CE26: Link
C30: 22.o7 | I30: 0.47916667 | N30: {=xlookup(P30,qualdata!$N$2:$N$17,qualdata!$O$2:$O$17,"")} | P30: ='Contender Schedule'!V23 | AB30: ='Contender Schedule'!AH23 | AD30: ='Contender Schedule'!AJ23 | AF30: ='Contender Schedule'!AL23 | AR30: {=xlookup(AF30,qualdata!$N$2:$N$17,qualdata!$O$2:$O$17,"")} | AU30: Bo3 | AZ30: Contender Round 2 High | BS30: TBA | CE30: Link
C32: 22.o7 | I32: 0.60416667 | N32: {=xlookup(P32,qualdata!$N$2:$N$17,qualdata!$O$2:$O$17,"")} | P32: ='Contender Schedule'!V25 | AB32: ='Contender Schedule'!AH25 | AD32: ='Contender Schedule'!AJ25 | AF32: ='Contender Schedule'!AL25 | AR32: {=xlookup(AF32,qualdata!$N$2:$N$17,qualdata!$O$2:$O$17,"")} | AU32: Bo3 | AZ32: Contender Round 2 High | BS32: TBA | CE32: Link
C34: 22.o7 | I34: 0.72916667 | N34: {=xlookup(P34,qualdata!$N$2:$N$17,qualdata!$O$2:$O$17,"")} | P34: ='Contender Schedule'!V27 | AB34: ='Contender Schedule'!AH27 | AD34: ='Contender Schedule'!AJ27 | AF34: ='Contender Schedule'!AL27 | AR34: {=xlookup(AF34,qualdata!$N$2:$N$17,qualdata!$O$2:$O$17,"")} | AU34: Bo3 | AZ34: Contender Round 2 High | BS34: TBA | CE34: Link
C36: 22.o7 | I36: 0.85416667 | N36: {=xlookup(P36,qualdata!$N$2:$N$17,qualdata!$O$2:$O$17,"")} | P36: ='Contender Schedule'!V29 | AB36: ='Contender Schedule'!AH29 | AD36: ='Contender Schedule'!AJ29 | AF36: ='Contender Schedule'!AL29 | AR36: {=xlookup(AF36,qualdata!$N$2:$N$17,qualdata!$O$2:$O$17,"")} | AU36: Bo3 | AZ36: Contender Round 2 High | BS36: TBA | CE36: Link
C39: 23.07 | I39: 0.47916667 | N39: {=xlookup(P39,qualdata!$N$2:$N$17,qualdata!$O$2:$O$17,"")} | P39: ='Contender Schedule'!V32 | AB39: ='Contender Schedule'!AH32 | AD39: ='Contender Schedule'!AJ32 | AF39: ='Contender Schedule'!AL32 | AR39: {=xlookup(AF39,qualdata!$N$2:$N$17,qualdata!$O$2:$O$17,"")} | AU39: Bo3 | AZ39: Contender Round 2 Low | BS39: TBA | CE39: Link
C41: 23.07 | I41: 0.60416667 | N41: {=xlookup(P41,qualdata!$N$2:$N$17,qualdata!$O$2:$O$17,"")} | P41: ='Contender Schedule'!V34 | AB41: ='Contender Schedule'!AH34 | AD41: ='Contender Schedule'!AJ34 | AF41: ='Contender Schedule'!AL34 | AR41: {=xlookup(AF41,qualdata!$N$2:$N$17,qualdata!$O$2:$O$17,"")} | AU41: Bo3 | AZ41: Contender Round 2 Low | BS41: TBA | CE41: Link
C43: 23.07 | I43: 0.72916667 | N43: {=xlookup(P43,qualdata!$N$2:$N$17,qualdata!$O$2:$O$17,"")} | P43: ='Contender Schedule'!V36 | AB43: ='Contender Schedule'!AH36 | AD43: ='Contender Schedule'!AJ36 | AF43: ='Contender Schedule'!AL36 | AR43: {=xlookup(AF43,qualdata!$N$2:$N$17,qualdata!$O$2:$O$17,"")} | AU43: Bo3 | AZ43: Contender Round 2 Low | BS43: TBA | CE43: Link
C45: 23.07 | I45: 0.85416667 | N45: {=xlookup(P45,qualdata!$N$2:$N$17,qualdata!$O$2:$O$17,"")} | P45: ='Contender Schedule'!V38 | AB45: ='Contender Schedule'!AH38 | AD45: ='Contender Schedule'!AJ38 | AF45: ='Contender Schedule'!AL38 | AR45: {=xlookup(AF45,qualdata!$N$2:$N$17,qualdata!$O$2:$O$17,"")} | AU45: Bo3 | AZ45: Contender Round 2 Low | BS45: TBA | CE45: Link
C49: 24.07 | I49: 0.47916667 | N49: {=xlookup(P49,qualdata!$N$2:$N$17,qualdata!$O$2:$O$17,"")} | P49: ='Contender Schedule'!V42 | AB49: ='Contender Schedule'!AH42 | AD49: ='Contender Schedule'!AJ42 | AF49: ='Contender Schedule'!AL42 | AR49: {=xlookup(AF49,qualdata!$N$2:$N$17,qualdata!$O$2:$O$17,"")} | AU49: Bo3 | AZ49: Contender Round 3 High | BS49: TBA | CE49: Link
C51: 24.07 | I51: 0.60416667 | N51: {=xlookup(P51,qualdata!$N$2:$N$17,qualdata!$O$2:$O$17,"")} | P51: ='Contender Schedule'!V44 | AB51: ='Contender Schedule'!AH44 | AD51: ='Contender Schedule'!AJ44 | AF51: ='Contender Schedule'!AL44 | AR51: {=xlookup(AF51,qualdata!$N$2:$N$17,qualdata!$O$2:$O$17,"")} | AU51: Bo3 | AZ51: Contender Round 3 High | BS51: TBA | CE51: Link
C54: 25.07 | I54: 0.47916667 | N54: {=xlookup(P54,qualdata!$N$2:$N$17,qualdata!$O$2:$O$17,"")} | P54: ='Contender Schedule'!V47 | AB54: ='Contender Schedule'!AH47 | AD54: ='Contender Schedule'!AJ47 | AF54: ='Contender Schedule'!AL47 | AR54: {=xlookup(AF54,qualdata!$N$2:$N$17,qualdata!$O$2:$O$17,"")} | AU54: Bo3 | AZ54: Contender Round 3 mid | BS54: TBA | CE54: Link
C56: 25.07 | I56: 0.60416667 | N56: {=xlookup(P56,qualdata!$N$2:$N$17,qualdata!$O$2:$O$17,"")} | P56: ='Contender Schedule'!V49 | AB56: ='Contender Schedule'!AH49 | AD56: ='Contender Schedule'!AJ49 | AF56: ='Contender Schedule'!AL49 | AR56: {=xlookup(AF56,qualdata!$N$2:$N$17,qualdata!$O$2:$O$17,"")} | AU56: Bo3 | AZ56: Contender Round 3 mid | BS56: TBA | CE56: Link
C58: 25.07 | I58: 0.72916667 | N58: {=xlookup(P58,qualdata!$N$2:$N$17,qualdata!$O$2:$O$17,"")} | P58: ='Contender Schedule'!V51 | AB58: ='Contender Schedule'!AH51 | AD58: ='Contender Schedule'!AJ51 | AF58: ='Contender Schedule'!AL51 | AR58: {=xlookup(AF58,qualdata!$N$2:$N$17,qualdata!$O$2:$O$17,"")} | AU58: Bo3 | AZ58: Contender Round 3 mid | BS58: TBA | CE58: Link
C60: 25.07 | I60: 0.85416667 | N60: {=xlookup(P60,qualdata!$N$2:$N$17,qualdata!$O$2:$O$17,"")} | P60: ='Contender Schedule'!V53 | AB60: ='Contender Schedule'!AH53 | AD60: ='Contender Schedule'!AJ53 | AF60: ='Contender Schedule'!AL53 | AR60: {=xlookup(AF60,qualdata!$N$2:$N$17,qualdata!$O$2:$O$17,"")} | AU60: Bo3 | AZ60: Contender Round 3 mid | BS60: TBA | CE60: Link
C63: 24.07 | I63: 0.72916667 | N63: {=xlookup(P63,qualdata!$N$2:$N$17,qualdata!$O$2:$O$17,"")} | P63: ='Contender Schedule'!V56 | AB63: ='Contender Schedule'!AH56 | AD63: ='Contender Schedule'!AJ56 | AF63: ='Contender Schedule'!AL56 | AR63: {=xlookup(AF63,qualdata!$N$2:$N$17,qualdata!$O$2:$O$17,"")} | AU63: Bo3 | AZ63: Contender Round 3 low (elimination) | BS63: TBA | CE63: Link
C65: 24.07 | I65: 0.85416667 | N65: {=xlookup(P65,qualdata!$N$2:$N$17,qualdata!$O$2:$O$17,"")} | P65: ='Contender Schedule'!V58 | AB65: ='Contender Schedule'!AH58 | AD65: ='Contender Schedule'!AJ58 | AF65: ='Contender Schedule'!AL58 | AR65: {=xlookup(AF65,qualdata!$N$2:$N$17,qualdata!$O$2:$O$17,"")} | AU65: Bo3 | AZ65: Contender Round 3 low (elimination) | BS65: TBA | CE65: Link
... C88: 28.07 | I88: 0.85416667 | N88: {=xlookup(P88,qualdata!$N$2:$N$17,qualdata!$O$2:$O$17,"")} | P88: ='Contender Schedule'!V81 | AB88: ='Contender Schedule'!AH81 | AD88: ='Contender Schedule'!AJ81 | AF88: ='Contender Schedule'!AL81 | AR88: {=xlookup(AF88,qualdata!$N$2:$N$17,qualdata!$O$2:$O$17,"")} | AU88: Bo3 | AZ88: Contender Round 5 (elimination) | BS88: TBA | CE88: Link
C91: Main Swiss Stage
A95: 1 | C95: 29.07 | I95: 0.47916667 | N95: {=xlookup(P95,data!$N$2:$N$17,data!$O$2:$O$17,"")} | P95: {=xlookup(A95,matchups!$I:$I,matchups!$B:$B,"")} -> Team 1 (Group 2) | AB95: {=xlookup(A95,matchups!$I:$I,matchups!$D:$D,"")} | AD95: {=xlookup(A95,matchups!$I:$I,matchups!$E:$E,"")} | AF95: {=xlookup(A95,matchups!$I:$I,matchups!$C:$C,"")} -> TBD | AR95: {=xlookup(AF95,data!$N$2:$N$17,data!$O$2:$O$17,"")} | AU95: Bo3 | AZ95: Swiss Round 1 | BS95: TBA | CE95: Link
A97: =A95+1 -> 2 | C97: 29.07 | I97: 0.60416667 | N97: {=xlookup(P97,data!$N$2:$N$17,data!$O$2:$O$17,"")} | P97: {=xlookup(A97,matchups!$I:$I,matchups!$B:$B,"")} -> Team 2 (Group 2) | AB97: {=xlookup(A97,matchups!$I:$I,matchups!$D:$D,"")} | AD97: {=xlookup(A97,matchups!$I:$I,matchups!$E:$E,"")} | AF97: {=xlookup(A97,matchups!$I:$I,matchups!$C:$C,"")} -> TBD | AR97: {=xlookup(AF97,data!$N$2:$N$17,data!$O$2:$O$17,"")} | AU97: Bo3 | AZ97: Swiss Round 1 | BS97: TBA | CE97: Link
A99: =A97+1 -> 3 | C99: 29.07 | I99: 0.72916667 | N99: {=xlookup(P99,data!$N$2:$N$17,data!$O$2:$O$17,"")} | P99: {=xlookup(A99,matchups!$I:$I,matchups!$B:$B,"")} -> Team 3 (Group 2) | AB99: {=xlookup(A99,matchups!$I:$I,matchups!$D:$D,"")} | AD99: {=xlookup(A99,matchups!$I:$I,matchups!$E:$E,"")} | AF99: {=xlookup(A99,matchups!$I:$I,matchups!$C:$C,"")} -> TBD | AR99: {=xlookup(AF99,data!$N$2:$N$17,data!$O$2:$O$17,"")} | AU99: Bo3 | AZ99: Swiss Round 1 | BS99: TBA | CE99: Link
A101: =A99+1 -> 4 | C101: 29.07 | I101: 0.85416667 | N101: {=xlookup(P101,data!$N$2:$N$17,data!$O$2:$O$17,"")} | P101: {=xlookup(A101,matchups!$I:$I,matchups!$B:$B,"")} -> Team 4 (Group 2) | AB101: {=xlookup(A101,matchups!$I:$I,matchups!$D:$D,"")} | AD101: {=xlookup(A101,matchups!$I:$I,matchups!$E:$E,"")} | AF101: {=xlookup(A101,matchups!$I:$I,matchups!$C:$C,"")} -> TBD | AR101: {=xlookup(AF101,data!$N$2:$N$17,data!$O$2:$O$17,"")} | AU101: Bo3 | AZ101: Swiss Round 1 | BS101: TBA | CE101: Link
A103: =A101+1 -> 5 | C103: 30.07 | I103: 0.47916667 | N103: {=xlookup(P103,data!$N$2:$N$17,data!$O$2:$O$17,"")} | P103: {=xlookup(A103,matchups!$I:$I,matchups!$B:$B,"")} -> Team 5 (Group 2) | AB103: {=xlookup(A103,matchups!$I:$I,matchups!$D:$D,"")} | AD103: {=xlookup(A103,matchups!$I:$I,matchups!$E:$E,"")} | AF103: {=xlookup(A103,matchups!$I:$I,matchups!$C:$C,"")} -> TBD | AR103: {=xlookup(AF103,data!$N$2:$N$17,data!$O$2:$O$17,"")} | AU103: Bo3 | AZ103: Swiss Round 1 | BS103: TBA | CE103: Link
A105: =A103+1 -> 6 | C105: 30.07 | I105: 0.60416667 | N105: {=xlookup(P105,data!$N$2:$N$17,data!$O$2:$O$17,"")} | P105: {=xlookup(A105,matchups!$I:$I,matchups!$B:$B,"")} -> Team 6 (Group 2) | AB105: {=xlookup(A105,matchups!$I:$I,matchups!$D:$D,"")} | AD105: {=xlookup(A105,matchups!$I:$I,matchups!$E:$E,"")} | AF105: {=xlookup(A105,matchups!$I:$I,matchups!$C:$C,"")} -> TBD | AR105: {=xlookup(AF105,data!$N$2:$N$17,data!$O$2:$O$17,"")} | AU105: Bo3 | AZ105: Swiss Round 1 | BS105: TBA | CE105: Link
A107: =A105+1 -> 7 | C107: 30.07 | I107: 0.72916667 | N107: {=xlookup(P107,data!$N$2:$N$17,data!$O$2:$O$17,"")} | P107: {=xlookup(A107,matchups!$I:$I,matchups!$B:$B,"")} -> Team 7 (Group 2) | AB107: {=xlookup(A107,matchups!$I:$I,matchups!$D:$D,"")} | AD107: {=xlookup(A107,matchups!$I:$I,matchups!$E:$E,"")} | AF107: {=xlookup(A107,matchups!$I:$I,matchups!$C:$C,"")} -> TBD | AR107: {=xlookup(AF107,data!$N$2:$N$17,data!$O$2:$O$17,"")} | AU107: Bo3 | AZ107: Swiss Round 1 | BS107: TBA | CE107: Link
A109: =A107+1 -> 8 | C109: 30.07 | I109: 0.85416667 | N109: {=xlookup(P109,data!$N$2:$N$17,data!$O$2:$O$17,"")} | P109: {=xlookup(A109,matchups!$I:$I,matchups!$B:$B,"")} -> Team 8 (Group 2) | AB109: {=xlookup(A109,matchups!$I:$I,matchups!$D:$D,"")} | AD109: {=xlookup(A109,matchups!$I:$I,matchups!$E:$E,"")} | AF109: {=xlookup(A109,matchups!$I:$I,matchups!$C:$C,"")} -> TBD | AR109: {=xlookup(AF109,data!$N$2:$N$17,data!$O$2:$O$17,"")} | AU109: Bo3 | AZ109: Swiss Round 1 | BS109: TBA | CE109: Link
A113: =A109+1 -> 9 | C113: 31.07 | I113: 0.47916667 | N113: {=xlookup(P113,data!$N$2:$N$17,data!$O$2:$O$17,"")} | P113: {=xlookup(A113,matchups!$I:$I,matchups!$B:$B,"")} | AB113: {=xlookup(A113,matchups!$I:$I,matchups!$D:$D,"")} | AD113: {=xlookup(A113,matchups!$I:$I,matchups!$E:$E,"")} | AF113: {=xlookup(A113,matchups!$I:$I,matchups!$C:$C,"")} | AR113: {=xlookup(AF113,data!$N$2:$N$17,data!$O$2:$O$17,"")} | AU113: Bo3 | AZ113: Round 2 High | BS113: TBA | CE113: Link
A115: =A113+1 -> 10 | C115: 31.07 | I115: 0.60416667 | N115: {=xlookup(P115,data!$N$2:$N$17,data!$O$2:$O$17,"")} | P115: {=xlookup(A115,matchups!$I:$I,matchups!$B:$B,"")} | AB115: {=xlookup(A115,matchups!$I:$I,matchups!$D:$D,"")} | AD115: {=xlookup(A115,matchups!$I:$I,matchups!$E:$E,"")} | AF115: {=xlookup(A115,matchups!$I:$I,matchups!$C:$C,"")} | AR115: {=xlookup(AF115,data!$N$2:$N$17,data!$O$2:$O$17,"")} | AU115: Bo3 | AZ115: Round 2 High | BS115: TBA | CE115: Link
A117: =A115+1 -> 11 | C117: 31.07 | I117: 0.72916667 | N117: {=xlookup(P117,data!$N$2:$N$17,data!$O$2:$O$17,"")} | P117: {=xlookup(A117,matchups!$I:$I,matchups!$B:$B,"")} | AB117: {=xlookup(A117,matchups!$I:$I,matchups!$D:$D,"")} | AD117: {=xlookup(A117,matchups!$I:$I,matchups!$E:$E,"")} | AF117: {=xlookup(A117,matchups!$I:$I,matchups!$C:$C,"")} | AR117: {=xlookup(AF117,data!$N$2:$N$17,data!$O$2:$O$17,"")} | AU117: Bo3 | AZ117: Round 2 High | BS117: TBA | CE117: Link
...

Sheet Contender Stage
DD6: =IF(or(ED18="",EH18="",ED25="",EH25="",ED32="",EH32="",ED39="",EH39="",ED46="",EH46="",ED53="",EH53="",ED60="",EH60="",ED67="",EH67=""),0,1) -> 0
DD7: Round 1 Matches
DD12: Team 1 | EH12: Team 2
DL15: R1 | DO15: R2 | DR15: R3 | ED15: Score | EU15: R3 | EX15: R2 | FA15: R1
DC18: ='Choose matchups (Contender)'!Q5 -> 1 | DD18: {=xlookup(DC18,qualdata!$M$2:$M$17,qualdata!$O$2:$O$17,"")} | DH18: {=xlookup(DC18,qualdata!$M$2:$M$17,qualdata!$N$2:$N$17,"")} -> Team 1 (Group 1) | EL18: {=xlookup(FL18,qualdata!$M$2:$M$17,qualdata!$N$2:$N$17,"")} -> Team 16 (Group 1) | FH18: {=xlookup(FL18,qualdata!$M$2:$M$17,qualdata!$O$2:$O$17,"")} | FL18: {=xlookup(DC18,qualdata!$M$2:$M$17,qualdata!$P$2:$P$17,"")} -> 16
DC22: =DC18 -> 1 | ED22: =sum(DL22:DT24) -> 0 | EH22: =sum(EU22:FC24) -> 0 | FL22: =FL18 -> 16
DC25: ='Choose matchups (Contender)'!Q6 -> 2 | DD25: {=xlookup(DC25,qualdata!$M$2:$M$17,qualdata!$O$2:$O$17,"")} | DH25: {=xlookup(DC25,qualdata!$M$2:$M$17,qualdata!$N$2:$N$17,"")} -> Team 2 (Group 1) | EL25: {=xlookup(FL25,qualdata!$M$2:$M$17,qualdata!$N$2:$N$17,"")} -> Team 15 (Group 1) | FH25: {=xlookup(FL25,qualdata!$M$2:$M$17,qualdata!$O$2:$O$17,"")} | FL25: {=xlookup(DC25,qualdata!$M$2:$M$17,qualdata!$P$2:$P$17,"")} -> 15
DC29: =DC25 -> 2 | ED29: =sum(DL29:DT31) -> 0 | EH29: =sum(EU29:FC31) -> 0 | FL29: =FL25 -> 15
DC32: ='Choose matchups (Contender)'!Q7 -> 3 | DD32: {=xlookup(DC32,qualdata!$M$2:$M$17,qualdata!$O$2:$O$17,"")} | DH32: {=xlookup(DC32,qualdata!$M$2:$M$17,qualdata!$N$2:$N$17,"")} -> Team 3 (Group 1) | EL32: {=xlookup(FL32,qualdata!$M$2:$M$17,qualdata!$N$2:$N$17,"")} -> Team 14 (Group 1) | FH32: {=xlookup(FL32,qualdata!$M$2:$M$17,qualdata!$O$2:$O$17,"")} | FL32: {=xlookup(DC32,qualdata!$M$2:$M$17,qualdata!$P$2:$P$17,"")} -> 14
DC36: =DC32 -> 3 | ED36: =sum(DL36:DT38) -> 0 | EH36: =sum(EU36:FC38) -> 0 | FL36: =FL32 -> 14
DC39: ='Choose matchups (Contender)'!Q8 -> 4 | DD39: {=xlookup(DC39,qualdata!$M$2:$M$17,qualdata!$O$2:$O$17,"")} | DH39: {=xlookup(DC39,qualdata!$M$2:$M$17,qualdata!$N$2:$N$17,"")} -> Team 4 (Group 1) | EL39: {=xlookup(FL39,qualdata!$M$2:$M$17,qualdata!$N$2:$N$17,"")} -> Team 13 (Group 1) | FH39: {=xlookup(FL39,qualdata!$M$2:$M$17,qualdata!$O$2:$O$17,"")} | FL39: {=xlookup(DC39,qualdata!$M$2:$M$17,qualdata!$P$2:$P$17,"")} -> 13
DC43: =DC39 -> 4 | ED43: =sum(DL43:DT45) -> 0 | EH43: =sum(EU43:FC45) -> 0 | FL43: =FL39 -> 13
DC46: ='Choose matchups (Contender)'!Q9 -> 5 | DD46: {=xlookup(DC46,qualdata!$M$2:$M$17,qualdata!$O$2:$O$17,"")} | DH46: {=xlookup(DC46,qualdata!$M$2:$M$17,qualdata!$N$2:$N$17,"")} -> Team 5 (Group 1) | EL46: {=xlookup(FL46,qualdata!$M$2:$M$17,qualdata!$N$2:$N$17,"")} -> Team 12 (Group 1) | FH46: {=xlookup(FL46,qualdata!$M$2:$M$17,qualdata!$O$2:$O$17,"")} | FL46: {=xlookup(DC46,qualdata!$M$2:$M$17,qualdata!$P$2:$P$17,"")} -> 12
DC50: =DC46 -> 5 | ED50: =sum(DL50:DT52) -> 0 | EH50: =sum(EU50:FC52) -> 0 | FL50: =FL46 -> 12
DC53: ='Choose matchups (Contender)'!Q10 -> 6 | DD53: {=xlookup(DC53,qualdata!$M$2:$M$17,qualdata!$O$2:$O$17,"")} | DH53: {=xlookup(DC53,qualdata!$M$2:$M$17,qualdata!$N$2:$N$17,"")} -> Team 6 (Group 1) | EL53: {=xlookup(FL53,qualdata!$M$2:$M$17,qualdata!$N$2:$N$17,"")} -> Team 11 (Group 1) | FH53: {=xlookup(FL53,qualdata!$M$2:$M$17,qualdata!$O$2:$O$17,"")} | FL53: {=xlookup(DC53,qualdata!$M$2:$M$17,qualdata!$P$2:$P$17,"")} -> 11
DC57: =DC53 -> 6 | ED57: =sum(DL57:DT59) -> 0 | EH57: =sum(EU57:FC59) -> 0 | FL57: =FL53 -> 11
DC60: ='Choose matchups (Contender)'!Q11 -> 7 | DD60: {=xlookup(DC60,qualdata!$M$2:$M$17,qualdata!$O$2:$O$17,"")} | DH60: {=xlookup(DC60,qualdata!$M$2:$M$17,qualdata!$N$2:$N$17,"")} -> Team 7 (Group 1) | EL60: {=xlookup(FL60,qualdata!$M$2:$M$17,qualdata!$N$2:$N$17,"")} -> Team 10 (Group 1) | FH60: {=xlookup(FL60,qualdata!$M$2:$M$17,qualdata!$O$2:$O$17,"")} | FL60: {=xlookup(DC60,qualdata!$M$2:$M$17,qualdata!$P$2:$P$17,"")} -> 10
DC64: =DC60 -> 7 | ED64: =sum(DL64:DT66) -> 0 | EH64: =sum(EU64:FC66) -> 0 | FL64: =FL60 -> 10
DC67: ='Choose matchups (Contender)'!Q12 -> 8 | DD67: {=xlookup(DC67,qualdata!$M$2:$M$17,qualdata!$O$2:$O$17,"")} | DH67: {=xlookup(DC67,qualdata!$M$2:$M$17,qualdata!$N$2:$N$17,"")} -> Team 8 (Group 1) | EL67: {=xlookup(FL67,qualdata!$M$2:$M$17,qualdata!$N$2:$N$17,"")} -> Team 9 (Group 1) | FH67: {=xlookup(FL67,qualdata!$M$2:$M$17,qualdata!$O$2:$O$17,"")} | FL67: {=xlookup(DC67,qualdata!$M$2:$M$17,qualdata!$P$2:$P$17,"")} -> 9
DC71: =DC67 -> 8 | ED71: =sum(DL71:DT73) -> 0 | EH71: =sum(EU71:FC73) -> 0 | FL71: =FL67 -> 9
BX77: =if(or(CX89="",DB89="",CX96="",DB96="",CX103="",DB103="",CX110="",DB110=""),0,1) -> 0 | EJ77: =if(or(FJ89="",FN89="",FJ96="",FN96="",FJ103="",FN103="",FJ110="",FN110=""),0,1) -> 0
BX78: Round 2 High Matches | EJ78: Round 2 Lo Matches
BX83: Team 1 | DB83: Team 2 | EJ83: Team 1 | FN83: Team 2
CF86: R1 | CI86: R2 | CL86: R3 | CX86: Score | DO86: R3 | DR86: R2 | DU86: R1 | ER86: R1 | EU86: R2 | EX86: R3 | FJ86: Score | GA86: R3 | GD86: R2 | GG86: R1
BW89: =if($DD$6=0,"",qualreseeding!AC2) | BX89: {=xlookup(BW89,qualdata!$M$2:$M$17,qualdata!$O$2:$O$17,"")} | CB89: {=xlookup(BW89,qualdata!$M$2:$M$17,qualdata!$N$2:$N$17,"")} | DF89: {=xlookup(EF89,qualdata!$M$2:$M$17,qualdata!$N$2:$N$17,"")} | EB89: {=xlookup(EF89,qualdata!$M$2:$M$17,qualdata!$O$2:$O$17,"")} | EF89: =if($DD$6=0,"",qualreseeding!AD2) | EI89: =if($DD$6=0,"",qualreseeding!AC11) | EJ89: {=xlookup(EI89,qualdata!$M$2:$M$17,qualdata!$O$2:$O$17,"")} | EN89: {=xlookup(EI89,qualdata!$M$2:$M$17,qualdata!$N$2:$N$17,"")} | FR89: {=xlookup(GR89,qualdata!$M$2:$M$17,qualdata!$N$2:$N$17,"")} | GN89: {=xlookup(GR89,qualdata!$M$2:$M$17,qualdata!$O$2:$O$17,"")} | GR89: =if($DD$6=0,"",qualreseeding!AD11)
BW93: =BW89 | CX93: =sum(CF93:CN95) -> 0 | DB93: =sum(DO93:DW95) -> 0 | EF93: =EF89 | EI93: =EI89 | FJ93: =sum(ER93:EZ95) -> 0 | FN93: =sum(GA93:GI95) -> 0 | GR93: =GR89
BW96: =if($DD$6=0,"",qualreseeding!AC3) | BX96: {=xlookup(BW96,qualdata!$M$2:$M$17,qualdata!$O$2:$O$17,"")} | CB96: {=xlookup(BW96,qualdata!$M$2:$M$17,qualdata!$N$2:$N$17,"")} | DF96: {=xlookup(EF96,qualdata!$M$2:$M$17,qualdata!$N$2:$N$17,"")} | EB96: {=xlookup(EF96,qualdata!$M$2:$M$17,qualdata!$O$2:$O$17,"")} | EF96: =if($DD$6=0,"",qualreseeding!AD3) | EI96: =if($DD$6=0,"",qualreseeding!AC12) | EJ96: {=xlookup(EI96,qualdata!$M$2:$M$17,qualdata!$O$2:$O$17,"")} | EN96: {=xlookup(EI96,qualdata!$M$2:$M$17,qualdata!$N$2:$N$17,"")} | FR96: {=xlookup(GR96,qualdata!$M$2:$M$17,qualdata!$N$2:$N$17,"")} | GN96: {=xlookup(GR96,qualdata!$M$2:$M$17,qualdata!$O$2:$O$17,"")} | GR96: =if($DD$6=0,"",qualreseeding!AD12)
BW100: =BW96 | CX100: =sum(CF100:CN102) -> 0 | DB100: =sum(DO100:DW102) -> 0 | EF100: =EF96 | EI100: =EI96 | FJ100: =sum(ER100:EZ102) -> 0 | FN100: =sum(GA100:GI102) -> 0 | GR100: =GR96
BW103: =if($DD$6=0,"",qualreseeding!AC4) | BX103: {=xlookup(BW103,qualdata!$M$2:$M$17,qualdata!$O$2:$O$17,"")} | CB103: {=xlookup(BW103,qualdata!$M$2:$M$17,qualdata!$N$2:$N$17,"")} | DF103: {=xlookup(EF103,qualdata!$M$2:$M$17,qualdata!$N$2:$N$17,"")} | EB103: {=xlookup(EF103,qualdata!$M$2:$M$17,qualdata!$O$2:$O$17,"")} | EF103: =if($DD$6=0,"",qualreseeding!AD4) | EI103: =if($DD$6=0,"",qualreseeding!AC13) | EJ103: {=xlookup(EI103,qualdata!$M$2:$M$17,qualdata!$O$2:$O$17,"")} | EN103: {=xlookup(EI103,qualdata!$M$2:$M$17,qualdata!$N$2:$N$17,"")} | FR103: {=xlookup(GR103,qualdata!$M$2:$M$17,qualdata!$N$2:$N$17,"")} | GN103: {=xlookup(GR103,qualdata!$M$2:$M$17,qualdata!$O$2:$O$17,"")} | GR103: =if($DD$6=0,"",qualreseeding!AD13)
BW107: =BW103 | CX107: =sum(CF107:CN109) -> 0 | DB107: =sum(DO107:DW109) -> 0 | EF107: =EF103 | EI107: =EI103 | FJ107: =sum(ER107:EZ109) -> 0 | FN107: =sum(GA107:GI109) -> 0 | GR107: =GR103
BW110: =if($DD$6=0,"",qualreseeding!AC5) | BX110: {=xlookup(BW110,qualdata!$M$2:$M$17,qualdata!$O$2:$O$17,"")} | CB110: {=xlookup(BW110,qualdata!$M$2:$M$17,qualdata!$N$2:$N$17,"")} | DF110: {=xlookup(EF110,qualdata!$M$2:$M$17,qualdata!$N$2:$N$17,"")} | EB110: {=xlookup(EF110,qualdata!$M$2:$M$17,qualdata!$O$2:$O$17,"")} | EF110: =if($DD$6=0,"",qualreseeding!AD5) | EI110: =if($DD$6=0,"",qualreseeding!AC14) | EJ110: {=xlookup(EI110,qualdata!$M$2:$M$17,qualdata!$O$2:$O$17,"")} | EN110: {=xlookup(EI110,qualdata!$M$2:$M$17,qualdata!$N$2:$N$17,"")} | FR110: {=xlookup(GR110,qualdata!$M$2:$M$17,qualdata!$N$2:$N$17,"")} | GN110: {=xlookup(GR110,qualdata!$M$2:$M$17,qualdata!$O$2:$O$17,"")} | GR110: =if($DD$6=0,"",qualreseeding!AD14)
BW114: =BW110 | CX114: =sum(CF114:CN116) -> 0 | DB114: =sum(DO114:DW116) -> 0 | EF114: =EF110 | EI114: =EI110 | FJ114: =sum(ER114:EZ116) -> 0 | FN114: =sum(GA114:GI116) -> 0 | GR114: =GR110
AR120: =if(or(BR132="",BV132="",BR139="",BV139=""),0,1) -> 0 | DD120: =if(or(ED132="",EH132="",ED139="",EH139="",ED146="",EH146="",ED153="",EH153=""),0,1) -> 0 | FP120: =if(or(GP132="",GT132="",GP139="",GT139=""),0,1) -> 0
AR121: Round 3 High Matches | DD121: Round 3 Mid Matches | FP121: Round 3 Low Matches
AR126: Team 1 | BV126: Team 2 | DD126: Team 1 | EH126: Team 2 | FP126: Team 1 | GT126: Team 2
AZ129: R1 | BC129: R2 | BF129: R3 | BR129: Score | CI129: R3 | CL129: R2 | CO129: R1 | DL129: R1 | DO129: R2 | DR129: R3 | ED129: Score | EU129: R3 | EX129: R2 | FA129: R1 | FX129: R1 | GA129: R2 | GD129: R3 | GP129: Score | HG129: R3 | HJ129: R2 | HM129: R1
AQ132: =if(BX77=0,"",qualreseeding!AC56) | AR132: {=xlookup(AQ132,qualdata!$M$2:$M$17,qualdata!$O$2:$O$17,"")} | AV132: {=xlookup(AQ132,qualdata!$M$2:$M$17,qualdata!$N$2:$N$17,"")} | BZ132: {=xlookup(CZ132,qualdata!$M$2:$M$17,qualdata!$N$2:$N$17,"")} | CV132: {=xlookup(CZ132,qualdata!$M$2:$M$17,qualdata!$O$2:$O$17,"")} | CZ132: =if(BX77=0,"",qualreseeding!AD56) | DC132: =if(or(BX77=0,EJ77=0),"",qualreseeding!AC64) | DD132: {=xlookup(DC132,qualdata!$M$2:$M$17,qualdata!$O$2:$O$17,"")} | DH132: {=xlookup(DC132,qualdata!$M$2:$M$17,qualdata!$N$2:$N$17,"")} | EL132: {=xlookup(FL132,qualdata!$M$2:$M$17,qualdata!$N$2:$N$17,"")} | FH132: {=xlookup(FL132,qualdata!$M$2:$M$17,qualdata!$O$2:$O$17,"")} | FL132: =if(or(BX77=0,EJ77=0),"",qualreseeding!AD64) | FO132: =if(EJ77=0,"",qualreseeding!AC60) | FP132: {=xlookup(FO132,qualdata!$M$2:$M$17,qualdata!$O$2:$O$17,"")} | FT132: {=xlookup(FO132,qualdata!$M$2:$M$17,qualdata!$N$2:$N$17,"")} | GX132: {=xlookup(HX132,qualdata!$M$2:$M$17,qualdata!$N$2:$N$17,"")} | HT132: {=xlookup(HX132,qualdata!$M$2:$M$17,qualdata!$O$2:$O$17,"")} | HX132: =if(EJ77=0,"",qualreseeding!AD60)
AQ136: =AQ132 | BR136: =sum(AZ136:BH138) -> 0 | BV136: =sum(CI136:CQ138) -> 0 | CZ136: =CZ132 | DC136: =DC132 | ED136: =sum(DL136:DT138) -> 0 | EH136: =sum(EU136:FC138) -> 0 | FL136: =FL132 | FO136: =FO132 | GP136: =sum(FX136:GF138) -> 0 | GT136: =sum(HG136:HO138) -> 0 | HX136: =HX132
AQ139: =if(BX77=0,"",qualreseeding!AC57) | AR139: {=xlookup(AQ139,qualdata!$M$2:$M$17,qualdata!$O$2:$O$17,"")} | AV139: {=xlookup(AQ139,qualdata!$M$2:$M$17,qualdata!$N$2:$N$17,"")} | BZ139: {=xlookup(CZ139,qualdata!$M$2:$M$17,qualdata!$N$2:$N$17,"")} | CV139: {=xlookup(CZ139,qualdata!$M$2:$M$17,qualdata!$O$2:$O$17,"")} | CZ139: =if(BX77=0,"",qualreseeding!AD57) | DC139: =if(or(BX77=0,EJ77=0),"",qualreseeding!AC65) | DD139: {=xlookup(DC139,qualdata!$M$2:$M$17,qualdata!$O$2:$O$17,"")} | DH139: {=xlookup(DC139,qualdata!$M$2:$M$17,qualdata!$N$2:$N$17,"")} | EL139: {=xlookup(FL139,qualdata!$M$2:$M$17,qualdata!$N$2:$N$17,"")} | FH139: {=xlookup(FL139,qualdata!$M$2:$M$17,qualdata!$O$2:$O$17,"")} | FL139: =if(or(BX77=0,EJ77=0),"",qualreseeding!AD65) | FO139: =if(EJ77=0,"",qualreseeding!AC61) | FP139: {=xlookup(FO139,qualdata!$M$2:$M$17,qualdata!$O$2:$O$17,"")} | FT139: {=xlookup(FO139,qualdata!$M$2:$M$17,qualdata!$N$2:$N$17,"")} | GX139: {=xlookup(HX139,qualdata!$M$2:$M$17,qualdata!$N$2:$N$17,"")} | HT139: {=xlookup(HX139,qualdata!$M$2:$M$17,qualdata!$O$2:$O$17,"")} | HX139: =if(EJ77=0,"",qualreseeding!AD61)
AQ143: =AQ139 | BR143: =sum(AZ143:BH145) -> 0 | BV143: =sum(CI143:CQ145) -> 0 | CZ143: =CZ139 | DC143: =DC139 | ED143: =sum(DL143:DT145) -> 0 | EH143: =sum(EU143:FC145) -> 0 | FL143: =FL139 | FO143: =FO139 | GP143: =sum(FX143:GF145) -> 0 | GT143: =sum(HG143:HO145) -> 0 | HX143: =HX139
...

Sheet Main Event
DD6: =IF(or(ED18="",EH18="",ED25="",EH25="",ED32="",EH32="",ED39="",EH39="",ED46="",EH46="",ED53="",EH53="",ED60="",EH60="",ED67="",EH67=""),0,1) -> 0
DD7: Round 1 Matches
DD12: Team 1 | EH12: Team 2
DL15: R1 | DO15: R2 | DR15: R3 | ED15: Score | EU15: R3 | EX15: R2 | FA15: R1
DC18: ='Choose matchups (Main)'!Q5 -> 1 | DD18: {=xlookup(DC18,data!$M$2:$M$17,data!$O$2:$O$17,"")} | DH18: {=xlookup(DC18,data!$M$2:$M$17,data!$N$2:$N$17,"")} -> Team 1 (Group 2) | EL18: {=xlookup(FL18,data!$M$2:$M$17,data!$N$2:$N$17,"")} -> TBD | FH18: {=xlookup(FL18,data!$M$2:$M$17,data!$O$2:$O$17,"")} | FL18: {=xlookup(DC18,data!$M$2:$M$17,data!$P$2:$P$17,"")} -> 9
DC22: =DC18 -> 1 | ED22: =sum(DL22:DT24) -> 0 | EH22: =sum(EU22:FC24) -> 0 | FL22: =FL18 -> 9
DC25: ='Choose matchups (Main)'!Q6 -> 2 | DD25: {=xlookup(DC25,data!$M$2:$M$17,data!$O$2:$O$17,"")} | DH25: {=xlookup(DC25,data!$M$2:$M$17,data!$N$2:$N$17,"")} -> Team 2 (Group 2) | EL25: {=xlookup(FL25,data!$M$2:$M$17,data!$N$2:$N$17,"")} -> TBD | FH25: {=xlookup(FL25,data!$M$2:$M$17,data!$O$2:$O$17,"")} | FL25: {=xlookup(DC25,data!$M$2:$M$17,data!$P$2:$P$17,"")} -> 9
DC29: =DC25 -> 2 | ED29: =sum(DL29:DT31) -> 0 | EH29: =sum(EU29:FC31) -> 0 | FL29: =FL25 -> 9
DC32: ='Choose matchups (Main)'!Q7 -> 3 | DD32: {=xlookup(DC32,data!$M$2:$M$17,data!$O$2:$O$17,"")} | DH32: {=xlookup(DC32,data!$M$2:$M$17,data!$N$2:$N$17,"")} -> Team 3 (Group 2) | EL32: {=xlookup(FL32,data!$M$2:$M$17,data!$N$2:$N$17,"")} -> TBD | FH32: {=xlookup(FL32,data!$M$2:$M$17,data!$O$2:$O$17,"")} | FL32: {=xlookup(DC32,data!$M$2:$M$17,data!$P$2:$P$17,"")} -> 9
DC36: =DC32 -> 3 | ED36: =sum(DL36:DT38) -> 0 | EH36: =sum(EU36:FC38) -> 0 | FL36: =FL32 -> 9
DC39: ='Choose matchups (Main)'!Q8 -> 4 | DD39: {=xlookup(DC39,data!$M$2:$M$17,data!$O$2:$O$17,"")} | DH39: {=xlookup(DC39,data!$M$2:$M$17,data!$N$2:$N$17,"")} -> Team 4 (Group 2) | EL39: {=xlookup(FL39,data!$M$2:$M$17,data!$N$2:$N$17,"")} -> TBD | FH39: {=xlookup(FL39,data!$M$2:$M$17,data!$O$2:$O$17,"")} | FL39: {=xlookup(DC39,data!$M$2:$M$17,data!$P$2:$P$17,"")} -> 9
DC43: =DC39 -> 4 | ED43: =sum(DL43:DT45) -> 0 | EH43: =sum(EU43:FC45) -> 0 | FL43: =FL39 -> 9
DC46: ='Choose matchups (Main)'!Q9 -> 5 | DD46: {=xlookup(DC46,data!$M$2:$M$17,data!$O$2:$O$17,"")} | DH46: {=xlookup(DC46,data!$M$2:$M$17,data!$N$2:$N$17,"")} -> Team 5 (Group 2) | EL46: {=xlookup(FL46,data!$M$2:$M$17,data!$N$2:$N$17,"")} -> TBD | FH46: {=xlookup(FL46,data!$M$2:$M$17,data!$O$2:$O$17,"")} | FL46: {=xlookup(DC46,data!$M$2:$M$17,data!$P$2:$P$17,"")} -> 9
DC50: =DC46 -> 5 | ED50: =sum(DL50:DT52) -> 0 | EH50: =sum(EU50:FC52) -> 0 | FL50: =FL46 -> 9
DC53: ='Choose matchups (Main)'!Q10 -> 6 | DD53: {=xlookup(DC53,data!$M$2:$M$17,data!$O$2:$O$17,"")} | DH53: {=xlookup(DC53,data!$M$2:$M$17,data!$N$2:$N$17,"")} -> Team 6 (Group 2) | EL53: {=xlookup(FL53,data!$M$2:$M$17,data!$N$2:$N$17,"")} -> TBD | FH53: {=xlookup(FL53,data!$M$2:$M$17,data!$O$2:$O$17,"")} | FL53: {=xlookup(DC53,data!$M$2:$M$17,data!$P$2:$P$17,"")} -> 9
DC57: =DC53 -> 6 | ED57: =sum(DL57:DT59) -> 0 | EH57: =sum(EU57:FC59) -> 0 | FL57: =FL53 -> 9
DC60: ='Choose matchups (Main)'!Q11 -> 7 | DD60: {=xlookup(DC60,data!$M$2:$M$17,data!$O$2:$O$17,"")} | DH60: {=xlookup(DC60,data!$M$2:$M$17,data!$N$2:$N$17,"")} -> Team 7 (Group 2) | EL60: {=xlookup(FL60,data!$M$2:$M$17,data!$N$2:$N$17,"")} -> TBD | FH60: {=xlookup(FL60,data!$M$2:$M$17,data!$O$2:$O$17,"")} | FL60: {=xlookup(DC60,data!$M$2:$M$17,data!$P$2:$P$17,"")} -> 9
DC64: =DC60 -> 7 | ED64: =sum(DL64:DT66) -> 0 | EH64: =sum(EU64:FC66) -> 0 | FL64: =FL60 -> 9
DC67: ='Choose matchups (Main)'!Q12 -> 8 | DD67: {=xlookup(DC67,data!$M$2:$M$17,data!$O$2:$O$17,"")} | DH67: {=xlookup(DC67,data!$M$2:$M$17,data!$N$2:$N$17,"")} -> Team 8 (Group 2) | EL67: {=xlookup(FL67,data!$M$2:$M$17,data!$N$2:$N$17,"")} -> TBD | FH67: {=xlookup(FL67,data!$M$2:$M$17,data!$O$2:$O$17,"")} | FL67: {=xlookup(DC67,data!$M$2:$M$17,data!$P$2:$P$17,"")} -> 9
DC71: =DC67 -> 8 | ED71: =sum(DL71:DT73) -> 0 | EH71: =sum(EU71:FC73) -> 0 | FL71: =FL67 -> 9
BX77: =if(or(CX89="",DB89="",CX96="",DB96="",CX103="",DB103="",CX110="",DB110=""),0,1) -> 0 | EJ77: =if(or(FJ89="",FN89="",FJ96="",FN96="",FJ103="",FN103="",FJ110="",FN110=""),0,1) -> 0
BX78: Round 2 High Matches | EJ78: Round 2 Lo Matches
BX83: Team 1 | DB83: Team 2 | EJ83: Team 1 | FN83: Team 2
CF86: R1 | CI86: R2 | CL86: R3 | CX86: Score | DO86: R3 | DR86: R2 | DU86: R1 | ER86: R1 | EU86: R2 | EX86: R3 | FJ86: Score | GA86: R3 | GD86: R2 | GG86: R1
BW89: =if($DD$6=0,"",reseeding!AC2) | BX89: {=xlookup(BW89,data!$M$2:$M$17,data!$O$2:$O$17,"")} | CB89: {=xlookup(BW89,data!$M$2:$M$17,data!$N$2:$N$17,"")} | DF89: {=xlookup(EF89,data!$M$2:$M$17,data!$N$2:$N$17,"")} | EB89: {=xlookup(EF89,data!$M$2:$M$17,data!$O$2:$O$17,"")} | EF89: =if($DD$6=0,"",reseeding!AD2) | EI89: =if($DD$6=0,"",reseeding!AC11) | EJ89: {=xlookup(EI89,data!$M$2:$M$17,data!$O$2:$O$17,"")} | EN89: {=xlookup(EI89,data!$M$2:$M$17,data!$N$2:$N$17,"")} | FR89: {=xlookup(GR89,data!$M$2:$M$17,data!$N$2:$N$17,"")} | GN89: {=xlookup(GR89,data!$M$2:$M$17,data!$O$2:$O$17,"")} | GR89: =if($DD$6=0,"",reseeding!AD11)
BW93: =BW89 | CX93: =sum(CF93:CN95) -> 0 | DB93: =sum(DO93:DW95) -> 0 | EF93: =EF89 | EI93: =EI89 | FJ93: =sum(ER93:EZ95) -> 0 | FN93: =sum(GA93:GI95) -> 0 | GR93: =GR89
BW96: =if($DD$6=0,"",reseeding!AC3) | BX96: {=xlookup(BW96,data!$M$2:$M$17,data!$O$2:$O$17,"")} | CB96: {=xlookup(BW96,data!$M$2:$M$17,data!$N$2:$N$17,"")} | DF96: {=xlookup(EF96,data!$M$2:$M$17,data!$N$2:$N$17,"")} | EB96: {=xlookup(EF96,data!$M$2:$M$17,data!$O$2:$O$17,"")} | EF96: =if($DD$6=0,"",reseeding!AD3) | EI96: =if($DD$6=0,"",reseeding!AC12) | EJ96: {=xlookup(EI96,data!$M$2:$M$17,data!$O$2:$O$17,"")} | EN96: {=xlookup(EI96,data!$M$2:$M$17,data!$N$2:$N$17,"")} | FR96: {=xlookup(GR96,data!$M$2:$M$17,data!$N$2:$N$17,"")} | GN96: {=xlookup(GR96,data!$M$2:$M$17,data!$O$2:$O$17,"")} | GR96: =if($DD$6=0,"",reseeding!AD12)
BW100: =BW96 | CX100: =sum(CF100:CN102) -> 0 | DB100: =sum(DO100:DW102) -> 0 | EF100: =EF96 | EI100: =EI96 | FJ100: =sum(ER100:EZ102) -> 0 | FN100: =sum(GA100:GI102) -> 0 | GR100: =GR96
BW103: =if($DD$6=0,"",reseeding!AC4) | BX103: {=xlookup(BW103,data!$M$2:$M$17,data!$O$2:$O$17,"")} | CB103: {=xlookup(BW103,data!$M$2:$M$17,data!$N$2:$N$17,"")} | DF103: {=xlookup(EF103,data!$M$2:$M$17,data!$N$2:$N$17,"")} | EB103: {=xlookup(EF103,data!$M$2:$M$17,data!$O$2:$O$17,"")} | EF103: =if($DD$6=0,"",reseeding!AD4) | EI103: =if($DD$6=0,"",reseeding!AC13) | EJ103: {=xlookup(EI103,data!$M$2:$M$17,data!$O$2:$O$17,"")} | EN103: {=xlookup(EI103,data!$M$2:$M$17,data!$N$2:$N$17,"")} | FR103: {=xlookup(GR103,data!$M$2:$M$17,data!$N$2:$N$17,"")} | GN103: {=xlookup(GR103,data!$M$2:$M$17,data!$O$2:$O$17,"")} | GR103: =if($DD$6=0,"",reseeding!AD13)
BW107: =BW103 | CX107: =sum(CF107:CN109) -> 0 | DB107: =sum(DO107:DW109) -> 0 | EF107: =EF103 | EI107: =EI103 | FJ107: =sum(ER107:EZ109) -> 0 | FN107: =sum(GA107:GI109) -> 0 | GR107: =GR103
BW110: =if($DD$6=0,"",reseeding!AC5) | BX110: {=xlookup(BW110,data!$M$2:$M$17,data!$O$2:$O$17,"")} | CB110: {=xlookup(BW110,data!$M$2:$M$17,data!$N$2:$N$17,"")} | DF110: {=xlookup(EF110,data!$M$2:$M$17,data!$N$2:$N$17,"")} | EB110: {=xlookup(EF110,data!$M$2:$M$17,data!$O$2:$O$17,"")} | EF110: =if($DD$6=0,"",reseeding!AD5) | EI110: =if($DD$6=0,"",reseeding!AC14) | EJ110: {=xlookup(EI110,data!$M$2:$M$17,data!$O$2:$O$17,"")} | EN110: {=xlookup(EI110,data!$M$2:$M$17,data!$N$2:$N$17,"")} | FR110: {=xlookup(GR110,data!$M$2:$M$17,data!$N$2:$N$17,"")} | GN110: {=xlookup(GR110,data!$M$2:$M$17,data!$O$2:$O$17,"")} | GR110: =if($DD$6=0,"",reseeding!AD14)
BW114: =BW110 | CX114: =sum(CF114:CN116) -> 0 | DB114: =sum(DO114:DW116) -> 0 | EF114: =EF110 | EI114: =EI110 | FJ114: =sum(ER114:EZ116) -> 0 | FN114: =sum(GA114:GI116) -> 0 | GR114: =GR110
AR120: =if(or(BR132="",BV132="",BR139="",BV139=""),0,1) -> 0 | DD120: =if(or(ED132="",EH132="",ED139="",EH139="",ED146="",EH146="",ED153="",EH153=""),0,1) -> 0 | FP120: =if(or(GP132="",GT132="",GP139="",GT139=""),0,1) -> 0
AR121: Round 3 High Matches | DD121: Round 3 Mid Matches | FP121: Round 3 Low Matches
AR126: Team 1 | BV126: Team 2 | DD126: Team 1 | EH126: Team 2 | FP126: Team 1 | GT126: Team 2
AZ129: R1 | BC129: R2 | BF129: R3 | BR129: Score | CI129: R3 | CL129: R2 | CO129: R1 | DL129: R1 | DO129: R2 | DR129: R3 | ED129: Score | EU129: R3 | EX129: R2 | FA129: R1 | FX129: R1 | GA129: R2 | GD129: R3 | GP129: Score | HG129: R3 | HJ129: R2 | HM129: R1
AQ132: =if(BX77=0,"",reseeding!AC56) | AR132: {=xlookup(AQ132,data!$M$2:$M$17,data!$O$2:$O$17,"")} | AV132: {=xlookup(AQ132,data!$M$2:$M$17,data!$N$2:$N$17,"")} | BZ132: {=xlookup(CZ132,data!$M$2:$M$17,data!$N$2:$N$17,"")} | CV132: {=xlookup(CZ132,data!$M$2:$M$17,data!$O$2:$O$17,"")} | CZ132: =if(BX77=0,"",reseeding!AD56) | DC132: =if(or(BX77=0,EJ77=0),"",reseeding!AC64) | DD132: {=xlookup(DC132,data!$M$2:$M$17,data!$O$2:$O$17,"")} | DH132: {=xlookup(DC132,data!$M$2:$M$17,data!$N$2:$N$17,"")} | EL132: {=xlookup(FL132,data!$M$2:$M$17,data!$N$2:$N$17,"")} | FH132: {=xlookup(FL132,data!$M$2:$M$17,data!$O$2:$O$17,"")} | FL132: =if(or(BX77=0,EJ77=0),"",reseeding!AD64) | FO132: =if(EJ77=0,"",reseeding!AC60) | FP132: {=xlookup(FO132,data!$M$2:$M$17,data!$O$2:$O$17,"")} | FT132: {=xlookup(FO132,data!$M$2:$M$17,data!$N$2:$N$17,"")} | GX132: {=xlookup(HX132,data!$M$2:$M$17,data!$N$2:$N$17,"")} | HT132: {=xlookup(HX132,data!$M$2:$M$17,data!$O$2:$O$17,"")} | HX132: =if(EJ77=0,"",reseeding!AD60)
AQ136: =AQ132 | BR136: =sum(AZ136:BH138) -> 0 | BV136: =sum(CI136:CQ138) -> 0 | CZ136: =CZ132 | DC136: =DC132 | ED136: =sum(DL136:DT138) -> 0 | EH136: =sum(EU136:FC138) -> 0 | FL136: =FL132 | FO136: =FO132 | GP136: =sum(FX136:GF138) -> 0 | GT136: =sum(HG136:HO138) -> 0 | HX136: =HX132
AQ139: =if(BX77=0,"",reseeding!AC57) | AR139: {=xlookup(AQ139,data!$M$2:$M$17,data!$O$2:$O$17,"")} | AV139: {=xlookup(AQ139,data!$M$2:$M$17,data!$N$2:$N$17,"")} | BZ139: {=xlookup(CZ139,data!$M$2:$M$17,data!$N$2:$N$17,"")} | CV139: {=xlookup(CZ139,data!$M$2:$M$17,data!$O$2:$O$17,"")} | CZ139: =if(BX77=0,"",reseeding!AD57) | DC139: =if(or(BX77=0,EJ77=0),"",reseeding!AC65) | DD139: {=xlookup(DC139,data!$M$2:$M$17,data!$O$2:$O$17,"")} | DH139: {=xlookup(DC139,data!$M$2:$M$17,data!$N$2:$N$17,"")} | EL139: {=xlookup(FL139,data!$M$2:$M$17,data!$N$2:$N$17,"")} | FH139: {=xlookup(FL139,data!$M$2:$M$17,data!$O$2:$O$17,"")} | FL139: =if(or(BX77=0,EJ77=0),"",reseeding!AD65) | FO139: =if(EJ77=0,"",reseeding!AC61) | FP139: {=xlookup(FO139,data!$M$2:$M$17,data!$O$2:$O$17,"")} | FT139: {=xlookup(FO139,data!$M$2:$M$17,data!$N$2:$N$17,"")} | GX139: {=xlookup(HX139,data!$M$2:$M$17,data!$N$2:$N$17,"")} | HT139: {=xlookup(HX139,data!$M$2:$M$17,data!$O$2:$O$17,"")} | HX139: =if(EJ77=0,"",reseeding!AD61)
AQ143: =AQ139 | BR143: =sum(AZ143:BH145) -> 0 | BV143: =sum(CI143:CQ145) -> 0 | CZ143: =CZ139 | DC143: =DC139 | ED143: =sum(DL143:DT145) -> 0 | EH143: =sum(EU143:FC145) -> 0 | FL143: =FL139 | FO143: =FO139 | GP143: =sum(FX143:GF145) -> 0 | GT143: =sum(HG143:HO145) -> 0 | HX143: =HX139
...

Sheet Contender Results
M2: # | R2: Participant | BC2: Matches | BL2: Games | BU2: Rounds | CD2: RD | CJ2: Round 1 | CS2: Round 2 | DB2: Round 3 | DK2: Round 4 | DT2: Round 5
M9: =Q9&"." -> 1. | Q9: 1 | CJ9: {=xlookup($Y10,qualdata!$N$2:$N$17,xlookup("r1Ser",qualdata!$P$1:$BR$1,qualdata!$P$2:$BR$17,""))} | CL9: {=xlookup(xlookup($Y10,qualdata!$N$2:$N$17,xlookup("r1op",qualdata!$P$1:$BR$1,qualdata!$P$2:$BR$17,"")),qualdata!$M$2:$M$17,qualdata!$O$2:$O$17,"")} | CS9: {=xlookup($Y10,qualdata!$N$2:$N$17,xlookup("r2Ser",qualdata!$P$1:$BR$1,qualdata!$P$2:$BR$17,""))} | CU9: {=xlookup(xlookup($Y10,qualdata!$N$2:$N$17,xlookup("r2op",qualdata!$P$1:$BR$1,qualdata!$P$2:$BR$17,"")),qualdata!$M$2:$M$17,qualdata!$O$2:$O$17,"")} | DB9: {=xlookup($Y10,qualdata!$N$2:$N$17,xlookup("r3Ser",qualdata!$P$1:$BR$1,qualdata!$P$2:$BR$17,""))} | DD9: {=xlookup(xlookup($Y10,qualdata!$N$2:$N$17,xlookup("r3op",qualdata!$P$1:$BR$1,qualdata!$P$2:$BR$17,"")),qualdata!$M$2:$M$17,qualdata!$O$2:$O$17,"")} | DK9: {=xlookup($Y10,qualdata!$N$2:$N$17,xlookup("r4Ser",qualdata!$P$1:$BR$1,qualdata!$P$2:$BR$17,""))} | DM9: {=xlookup(xlookup($Y10,qualdata!$N$2:$N$17,xlookup("r4op",qualdata!$P$1:$BR$1,qualdata!$P$2:$BR$17,"")),qualdata!$M$2:$M$17,qualdata!$O$2:$O$17,"")} | DT9: {=xlookup($Y10,qualdata!$N$2:$N$17,xlookup("r5Ser",qualdata!$P$1:$BR$1,qualdata!$P$2:$BR$17,""))} | DV9: {=xlookup(xlookup($Y10,qualdata!$N$2:$N$17,xlookup("r5op",qualdata!$P$1:$BR$1,qualdata!$P$2:$BR$17,"")),qualdata!$M$2:$M$17,qualdata!$O$2:$O$17,"")}
R10: {=xlookup(Y10,qualdata!$N$2:$N$17,qualdata!$O$2:$O$17,"")} | Y10: {=xlookup(Q9,qualdata!$G$24:$G$39,qualdata!$A$24:$A$39,"")} -> Team 1 (Group 1) | BC10: {=xlookup(Y10,qualdata!$A$24:$A$39,qualdata!$B$24:$B$39,"")} -> 0-0 | BL10: {=xlookup(Y10,qualdata!$A$24:$A$39,qualdata!$C$24:$C$39,"")} -> 0-0 | BU10: {=xlookup(Y10,qualdata!$A$24:$A$39,qualdata!$D$24:$D$39,"")} -> 0-0 | CD10: {=xlookup(Y10,qualdata!$A$24:$A$39,qualdata!$F$24:$F$39,"")} -> 0
CJ14: {=xlookup($Y10,qualdata!$N$2:$N$17,xlookup("r1gw",qualdata!$P$1:$BR$1,qualdata!$P$2:$BR$17))&"-"&xlookup($Y10,qualdata!$N$2:$N$17,xlookup("r1gl",qualdata!$P$1:$BR$1,qualdata!$P$2:$BR$17))} -> - | CO14: {=if(xlookup($Y10,qualdata!$N$2:$N$17,xlookup("r1rd",qualdata!$P$1:$BR$1,qualdata!$P$2:$BR$17))>0,"+"&xlookup($Y10,qualdata!$N$2:$N$17,xlookup("r1rd",qualdata!$P$1:$BR$1,qualdata!$P$2:$BR$17)),xlookup($Y10,qualdata!$N$2:$N$17,xlookup("r1rd",qualdata!$P$1:$BR$1,qualdata!$P$2:$BR$17)))} -> 0 | CS14: {=xlookup($Y10,qualdata!$N$2:$N$17,xlookup("r2gw",qualdata!$P$1:$BR$1,qualdata!$P$2:$BR$17))&"-"&xlookup($Y10,qualdata!$N$2:$N$17,xlookup("r2gl",qualdata!$P$1:$BR$1,qualdata!$P$2:$BR$17))} -> - | CX14: {=if(xlookup($Y10,qualdata!$N$2:$N$17,xlookup("r2rd",qualdata!$P$1:$BR$1,qualdata!$P$2:$BR$17))>0,"+"&xlookup($Y10,qualdata!$N$2:$N$17,xlookup("r2rd",qualdata!$P$1:$BR$1,qualdata!$P$2:$BR$17)),xlookup($Y10,qualdata!$N$2:$N$17,xlookup("r2rd",qualdata!$P$1:$BR$1,qualdata!$P$2:$BR$17)))} -> 0 | DB14: {=xlookup($Y10,qualdata!$N$2:$N$17,xlookup("r3gw",qualdata!$P$1:$BR$1,qualdata!$P$2:$BR$17))&"-"&xlookup($Y10,qualdata!$N$2:$N$17,xlookup("r3gl",qualdata!$P$1:$BR$1,qualdata!$P$2:$BR$17))} -> - | DG14: {=if(xlookup($Y10,qualdata!$N$2:$N$17,xlookup("r3rd",qualdata!$P$1:$BR$1,qualdata!$P$2:$BR$17))>0,"+"&xlookup($Y10,qualdata!$N$2:$N$17,xlookup("r3rd",qualdata!$P$1:$BR$1,qualdata!$P$2:$BR$17)),xlookup($Y10,qualdata!$N$2:$N$17,xlookup("r3rd",qualdata!$P$1:$BR$1,qualdata!$P$2:$BR$17)))} -> 0
M17: =Q17&"." -> 2. | Q17: 2 | CJ17: {=xlookup($Y18,qualdata!$N$2:$N$17,xlookup("r1Ser",qualdata!$P$1:$BR$1,qualdata!$P$2:$BR$17,""))} | CL17: {=xlookup(xlookup($Y18,qualdata!$N$2:$N$17,xlookup("r1op",qualdata!$P$1:$BR$1,qualdata!$P$2:$BR$17,"")),qualdata!$M$2:$M$17,qualdata!$O$2:$O$17,"")} | CS17: {=xlookup($Y18,qualdata!$N$2:$N$17,xlookup("r2Ser",qualdata!$P$1:$BR$1,qualdata!$P$2:$BR$17,""))} | CU17: {=xlookup(xlookup($Y18,qualdata!$N$2:$N$17,xlookup("r2op",qualdata!$P$1:$BR$1,qualdata!$P$2:$BR$17,"")),qualdata!$M$2:$M$17,qualdata!$O$2:$O$17,"")} | DB17: {=xlookup($Y18,qualdata!$N$2:$N$17,xlookup("r3Ser",qualdata!$P$1:$BR$1,qualdata!$P$2:$BR$17,""))} | DD17: {=xlookup(xlookup($Y18,qualdata!$N$2:$N$17,xlookup("r3op",qualdata!$P$1:$BR$1,qualdata!$P$2:$BR$17,"")),qualdata!$M$2:$M$17,qualdata!$O$2:$O$17,"")} | DK17: {=xlookup($Y18,qualdata!$N$2:$N$17,xlookup("r4Ser",qualdata!$P$1:$BR$1,qualdata!$P$2:$BR$17,""))} | DM17: {=xlookup(xlookup($Y18,qualdata!$N$2:$N$17,xlookup("r4op",qualdata!$P$1:$BR$1,qualdata!$P$2:$BR$17,"")),qualdata!$M$2:$M$17,qualdata!$O$2:$O$17,"")} | DT17: {=xlookup($Y18,qualdata!$N$2:$N$17,xlookup("r5Ser",qualdata!$P$1:$BR$1,qualdata!$P$2:$BR$17,""))} | DV17: {=xlookup(xlookup($Y18,qualdata!$N$2:$N$17,xlookup("r5op",qualdata!$P$1:$BR$1,qualdata!$P$2:$BR$17,"")),qualdata!$M$2:$M$17,qualdata!$O$2:$O$17,"")}
R18: {=xlookup(Y18,qualdata!$N$2:$N$17,qualdata!$O$2:$O$17,"")} | Y18: {=xlookup(Q17,qualdata!$G$24:$G$39,qualdata!$A$24:$A$39,"")} -> Team 2 (Group 1) | BC18: {=xlookup(Y18,qualdata!$A$24:$A$39,qualdata!$B$24:$B$39,"")} -> 0-0 | BL18: {=xlookup(Y18,qualdata!$A$24:$A$39,qualdata!$C$24:$C$39,"")} -> 0-0 | BU18: {=xlookup(Y18,qualdata!$A$24:$A$39,qualdata!$D$24:$D$39,"")} -> 0-0 | CD18: {=xlookup(Y18,qualdata!$A$24:$A$39,qualdata!$F$24:$F$39,"")} -> 0
CJ22: {=xlookup($Y18,qualdata!$N$2:$N$17,xlookup("r1gw",qualdata!$P$1:$BR$1,qualdata!$P$2:$BR$17))&"-"&xlookup($Y18,qualdata!$N$2:$N$17,xlookup("r1gl",qualdata!$P$1:$BR$1,qualdata!$P$2:$BR$17))} -> - | CO22: {=if(xlookup($Y18,qualdata!$N$2:$N$17,xlookup("r1rd",qualdata!$P$1:$BR$1,qualdata!$P$2:$BR$17))>0,"+"&xlookup($Y18,qualdata!$N$2:$N$17,xlookup("r1rd",qualdata!$P$1:$BR$1,qualdata!$P$2:$BR$17)),xlookup($Y18,qualdata!$N$2:$N$17,xlookup("r1rd",qualdata!$P$1:$BR$1,qualdata!$P$2:$BR$17)))} -> 0 | CS22: {=xlookup($Y18,qualdata!$N$2:$N$17,xlookup("r2gw",qualdata!$P$1:$BR$1,qualdata!$P$2:$BR$17))&"-"&xlookup($Y18,qualdata!$N$2:$N$17,xlookup("r2gl",qualdata!$P$1:$BR$1,qualdata!$P$2:$BR$17))} -> - | CX22: {=if(xlookup($Y18,qualdata!$N$2:$N$17,xlookup("r2rd",qualdata!$P$1:$BR$1,qualdata!$P$2:$BR$17))>0,"+"&xlookup($Y18,qualdata!$N$2:$N$17,xlookup("r2rd",qualdata!$P$1:$BR$1,qualdata!$P$2:$BR$17)),xlookup($Y18,qualdata!$N$2:$N$17,xlookup("r2rd",qualdata!$P$1:$BR$1,qualdata!$P$2:$BR$17)))} -> 0 | DB22: {=xlookup($Y18,qualdata!$N$2:$N$17,xlookup("r3gw",qualdata!$P$1:$BR$1,qualdata!$P$2:$BR$17))&"-"&xlookup($Y18,qualdata!$N$2:$N$17,xlookup("r3gl",qualdata!$P$1:$BR$1,qualdata!$P$2:$BR$17))} -> - | DG22: {=if(xlookup($Y18,qualdata!$N$2:$N$17,xlookup("r3rd",qualdata!$P$1:$BR$1,qualdata!$P$2:$BR$17))>0,"+"&xlookup($Y18,qualdata!$N$2:$N$17,xlookup("r3rd",qualdata!$P$1:$BR$1,qualdata!$P$2:$BR$17)),xlookup($Y18,qualdata!$N$2:$N$17,xlookup("r3rd",qualdata!$P$1:$BR$1,qualdata!$P$2:$BR$17)))} -> 0
M25: =Q25&"." -> 3. | Q25: 3 | CJ25: {=xlookup($Y26,qualdata!$N$2:$N$17,xlookup("r1Ser",qualdata!$P$1:$BR$1,qualdata!$P$2:$BR$17,""))} | CL25: {=xlookup(xlookup($Y26,qualdata!$N$2:$N$17,xlookup("r1op",qualdata!$P$1:$BR$1,qualdata!$P$2:$BR$17,"")),qualdata!$M$2:$M$17,qualdata!$O$2:$O$17,"")} | CS25: {=xlookup($Y26,qualdata!$N$2:$N$17,xlookup("r2Ser",qualdata!$P$1:$BR$1,qualdata!$P$2:$BR$17,""))} | CU25: {=xlookup(xlookup($Y26,qualdata!$N$2:$N$17,xlookup("r2op",qualdata!$P$1:$BR$1,qualdata!$P$2:$BR$17,"")),qualdata!$M$2:$M$17,qualdata!$O$2:$O$17,"")} | DB25: {=xlookup($Y26,qualdata!$N$2:$N$17,xlookup("r3Ser",qualdata!$P$1:$BR$1,qualdata!$P$2:$BR$17,""))} | DD25: {=xlookup(xlookup($Y26,qualdata!$N$2:$N$17,xlookup("r3op",qualdata!$P$1:$BR$1,qualdata!$P$2:$BR$17,"")),qualdata!$M$2:$M$17,qualdata!$O$2:$O$17,"")} | DK25: {=xlookup($Y26,qualdata!$N$2:$N$17,xlookup("r4Ser",qualdata!$P$1:$BR$1,qualdata!$P$2:$BR$17,""))} | DM25: {=xlookup(xlookup($Y26,qualdata!$N$2:$N$17,xlookup("r4op",qualdata!$P$1:$BR$1,qualdata!$P$2:$BR$17,"")),qualdata!$M$2:$M$17,qualdata!$O$2:$O$17,"")} | DT25: {=xlookup($Y26,qualdata!$N$2:$N$17,xlookup("r5Ser",qualdata!$P$1:$BR$1,qualdata!$P$2:$BR$17,""))} | DV25: {=xlookup(xlookup($Y26,qualdata!$N$2:$N$17,xlookup("r5op",qualdata!$P$1:$BR$1,qualdata!$P$2:$BR$17,"")),qualdata!$M$2:$M$17,qualdata!$O$2:$O$17,"")}
R26: {=xlookup(Y26,qualdata!$N$2:$N$17,qualdata!$O$2:$O$17,"")} | Y26: {=xlookup(Q25,qualdata!$G$24:$G$39,qualdata!$A$24:$A$39,"")} -> Team 3 (Group 1) | BC26: {=xlookup(Y26,qualdata!$A$24:$A$39,qualdata!$B$24:$B$39,"")} -> 0-0 | BL26: {=xlookup(Y26,qualdata!$A$24:$A$39,qualdata!$C$24:$C$39,"")} -> 0-0 | BU26: {=xlookup(Y26,qualdata!$A$24:$A$39,qualdata!$D$24:$D$39,"")} -> 0-0 | CD26: {=xlookup(Y26,qualdata!$A$24:$A$39,qualdata!$F$24:$F$39,"")} -> 0
CJ30: {=xlookup($Y26,qualdata!$N$2:$N$17,xlookup("r1gw",qualdata!$P$1:$BR$1,qualdata!$P$2:$BR$17))&"-"&xlookup($Y26,qualdata!$N$2:$N$17,xlookup("r1gl",qualdata!$P$1:$BR$1,qualdata!$P$2:$BR$17))} -> - | CO30: {=if(xlookup($Y26,qualdata!$N$2:$N$17,xlookup("r1rd",qualdata!$P$1:$BR$1,qualdata!$P$2:$BR$17))>0,"+"&xlookup($Y26,qualdata!$N$2:$N$17,xlookup("r1rd",qualdata!$P$1:$BR$1,qualdata!$P$2:$BR$17)),xlookup($Y26,qualdata!$N$2:$N$17,xlookup("r1rd",qualdata!$P$1:$BR$1,qualdata!$P$2:$BR$17)))} -> 0 | CS30: {=xlookup($Y26,qualdata!$N$2:$N$17,xlookup("r2gw",qualdata!$P$1:$BR$1,qualdata!$P$2:$BR$17))&"-"&xlookup($Y26,qualdata!$N$2:$N$17,xlookup("r2gl",qualdata!$P$1:$BR$1,qualdata!$P$2:$BR$17))} -> - | CX30: {=if(xlookup($Y26,qualdata!$N$2:$N$17,xlookup("r2rd",qualdata!$P$1:$BR$1,qualdata!$P$2:$BR$17))>0,"+"&xlookup($Y26,qualdata!$N$2:$N$17,xlookup("r2rd",qualdata!$P$1:$BR$1,qualdata!$P$2:$BR$17)),xlookup($Y26,qualdata!$N$2:$N$17,xlookup("r2rd",qualdata!$P$1:$BR$1,qualdata!$P$2:$BR$17)))} -> 0 | DB30: {=xlookup($Y26,qualdata!$N$2:$N$17,xlookup("r3gw",qualdata!$P$1:$BR$1,qualdata!$P$2:$BR$17))&"-"&xlookup($Y26,qualdata!$N$2:$N$17,xlookup("r3gl",qualdata!$P$1:$BR$1,qualdata!$P$2:$BR$17))} -> - | DG30: {=if(xlookup($Y26,qualdata!$N$2:$N$17,xlookup("r3rd",qualdata!$P$1:$BR$1,qualdata!$P$2:$BR$17))>0,"+"&xlookup($Y26,qualdata!$N$2:$N$17,xlookup("r3rd",qualdata!$P$1:$BR$1,qualdata!$P$2:$BR$17)),xlookup($Y26,qualdata!$N$2:$N$17,xlookup("r3rd",qualdata!$P$1:$BR$1,qualdata!$P$2:$BR$17)))} -> 0 | DK30: {=xlookup($Y26,qualdata!$N$2:$N$17,xlookup("r4gw",qualdata!$P$1:$BR$1,qualdata!$P$2:$BR$17))&"-"&xlookup($Y26,qualdata!$N$2:$N$17,xlookup("r4gl",qualdata!$P$1:$BR$1,qualdata!$P$2:$BR$17))} -> - | DP30: {=if(xlookup($Y26,qualdata!$N$2:$N$17,xlookup("r4rd",qualdata!$P$1:$BR$1,qualdata!$P$2:$BR$17))>0,"+"&xlookup($Y26,qualdata!$N$2:$N$17,xlookup("r4rd",qualdata!$P$1:$BR$1,qualdata!$P$2:$BR$17)),xlookup($Y26,qualdata!$N$2:$N$17,xlookup("r4rd",qualdata!$P$1:$BR$1,qualdata!$P$2:$BR$17)))} -> 0
M33: =Q33&"." -> 4. | Q33: 4 | CJ33: {=xlookup($Y34,qualdata!$N$2:$N$17,xlookup("r1Ser",qualdata!$P$1:$BR$1,qualdata!$P$2:$BR$17,""))} | CL33: {=xlookup(xlookup($Y34,qualdata!$N$2:$N$17,xlookup("r1op",qualdata!$P$1:$BR$1,qualdata!$P$2:$BR$17,"")),qualdata!$M$2:$M$17,qualdata!$O$2:$O$17,"")} | CS33: {=xlookup($Y34,qualdata!$N$2:$N$17,xlookup("r2Ser",qualdata!$P$1:$BR$1,qualdata!$P$2:$BR$17,""))} | CU33: {=xlookup(xlookup($Y34,qualdata!$N$2:$N$17,xlookup("r2op",qualdata!$P$1:$BR$1,qualdata!$P$2:$BR$17,"")),qualdata!$M$2:$M$17,qualdata!$O$2:$O$17,"")} | DB33: {=xlookup($Y34,qualdata!$N$2:$N$17,xlookup("r3Ser",qualdata!$P$1:$BR$1,qualdata!$P$2:$BR$17,""))} | DD33: {=xlookup(xlookup($Y34,qualdata!$N$2:$N$17,xlookup("r3op",qualdata!$P$1:$BR$1,qualdata!$P$2:$BR$17,"")),qualdata!$M$2:$M$17,qualdata!$O$2:$O$17,"")} | DK33: {=xlookup($Y34,qualdata!$N$2:$N$17,xlookup("r4Ser",qualdata!$P$1:$BR$1,qualdata!$P$2:$BR$17,""))} | DM33: {=xlookup(xlookup($Y34,qualdata!$N$2:$N$17,xlookup("r4op",qualdata!$P$1:$BR$1,qualdata!$P$2:$BR$17,"")),qualdata!$M$2:$M$17,qualdata!$O$2:$O$17,"")} | DT33: {=xlookup($Y34,qualdata!$N$2:$N$17,xlookup("r5Ser",qualdata!$P$1:$BR$1,qualdata!$P$2:$BR$17,""))} | DV33: {=xlookup(xlookup($Y34,qualdata!$N$2:$N$17,xlookup("r5op",qualdata!$P$1:$BR$1,qualdata!$P$2:$BR$17,"")),qualdata!$M$2:$M$17,qualdata!$O$2:$O$17,"")}
R34: {=xlookup(Y34,qualdata!$N$2:$N$17,qualdata!$O$2:$O$17,"")} | Y34: {=xlookup(Q33,qualdata!$G$24:$G$39,qualdata!$A$24:$A$39,"")} -> Team 4 (Group 1) | BC34: {=xlookup(Y34,qualdata!$A$24:$A$39,qualdata!$B$24:$B$39,"")} -> 0-0 | BL34: {=xlookup(Y34,qualdata!$A$24:$A$39,qualdata!$C$24:$C$39,"")} -> 0-0 | BU34: {=xlookup(Y34,qualdata!$A$24:$A$39,qualdata!$D$24:$D$39,"")} -> 0-0 | CD34: {=xlookup(Y34,qualdata!$A$24:$A$39,qualdata!$F$24:$F$39,"")} -> 0
CJ38: {=xlookup($Y34,qualdata!$N$2:$N$17,xlookup("r1gw",qualdata!$P$1:$BR$1,qualdata!$P$2:$BR$17))&"-"&xlookup($Y34,qualdata!$N$2:$N$17,xlookup("r1gl",qualdata!$P$1:$BR$1,qualdata!$P$2:$BR$17))} -> - | CO38: {=if(xlookup($Y34,qualdata!$N$2:$N$17,xlookup("r1rd",qualdata!$P$1:$BR$1,qualdata!$P$2:$BR$17))>0,"+"&xlookup($Y34,qualdata!$N$2:$N$17,xlookup("r1rd",qualdata!$P$1:$BR$1,qualdata!$P$2:$BR$17)),xlookup($Y34,qualdata!$N$2:$N$17,xlookup("r1rd",qualdata!$P$1:$BR$1,qualdata!$P$2:$BR$17)))} -> 0 | CS38: {=xlookup($Y34,qualdata!$N$2:$N$17,xlookup("r2gw",qualdata!$P$1:$BR$1,qualdata!$P$2:$BR$17))&"-"&xlookup($Y34,qualdata!$N$2:$N$17,xlookup("r2gl",qualdata!$P$1:$BR$1,qualdata!$P$2:$BR$17))} -> - | CX38: {=if(xlookup($Y34,qualdata!$N$2:$N$17,xlookup("r2rd",qualdata!$P$1:$BR$1,qualdata!$P$2:$BR$17))>0,"+"&xlookup($Y34,qualdata!$N$2:$N$17,xlookup("r2rd",qualdata!$P$1:$BR$1,qualdata!$P$2:$BR$17)),xlookup($Y34,qualdata!$N$2:$N$17,xlookup("r2rd",qualdata!$P$1:$BR$1,qualdata!$P$2:$BR$17)))} -> 0 | DB38: {=xlookup($Y34,qualdata!$N$2:$N$17,xlookup("r3gw",qualdata!$P$1:$BR$1,qualdata!$P$2:$BR$17))&"-"&xlookup($Y34,qualdata!$N$2:$N$17,xlookup("r3gl",qualdata!$P$1:$BR$1,qualdata!$P$2:$BR$17))} -> - | DG38: {=if(xlookup($Y34,qualdata!$N$2:$N$17,xlookup("r3rd",qualdata!$P$1:$BR$1,qualdata!$P$2:$BR$17))>0,"+"&xlookup($Y34,qualdata!$N$2:$N$17,xlookup("r3rd",qualdata!$P$1:$BR$1,qualdata!$P$2:$BR$17)),xlookup($Y34,qualdata!$N$2:$N$17,xlookup("r3rd",qualdata!$P$1:$BR$1,qualdata!$P$2:$BR$17)))} -> 0 | DK38: {=xlookup($Y34,qualdata!$N$2:$N$17,xlookup("r4gw",qualdata!$P$1:$BR$1,qualdata!$P$2:$BR$17))&"-"&xlookup($Y34,qualdata!$N$2:$N$17,xlookup("r4gl",qualdata!$P$1:$BR$1,qualdata!$P$2:$BR$17))} -> - | DP38: {=if(xlookup($Y34,qualdata!$N$2:$N$17,xlookup("r4rd",qualdata!$P$1:$BR$1,qualdata!$P$2:$BR$17))>0,"+"&xlookup($Y34,qualdata!$N$2:$N$17,xlookup("r4rd",qualdata!$P$1:$BR$1,qualdata!$P$2:$BR$17)),xlookup($Y34,qualdata!$N$2:$N$17,xlookup("r4rd",qualdata!$P$1:$BR$1,qualdata!$P$2:$BR$17)))} -> 0
M41: =Q41&"." -> 5. | Q41: 5 | CJ41: {=xlookup($Y42,qualdata!$N$2:$N$17,xlookup("r1Ser",qualdata!$P$1:$BR$1,qualdata!$P$2:$BR$17,""))} | CL41: {=xlookup(xlookup($Y42,qualdata!$N$2:$N$17,xlookup("r1op",qualdata!$P$1:$BR$1,qualdata!$P$2:$BR$17,"")),qualdata!$M$2:$M$17,qualdata!$O$2:$O$17,"")} | CS41: {=xlookup($Y42,qualdata!$N$2:$N$17,xlookup("r2Ser",qualdata!$P$1:$BR$1,qualdata!$P$2:$BR$17,""))} | CU41: {=xlookup(xlookup($Y42,qualdata!$N$2:$N$17,xlookup("r2op",qualdata!$P$1:$BR$1,qualdata!$P$2:$BR$17,"")),qualdata!$M$2:$M$17,qualdata!$O$2:$O$17,"")} | DB41: {=xlookup($Y42,qualdata!$N$2:$N$17,xlookup("r3Ser",qualdata!$P$1:$BR$1,qualdata!$P$2:$BR$17,""))} | DD41: {=xlookup(xlookup($Y42,qualdata!$N$2:$N$17,xlookup("r3op",qualdata!$P$1:$BR$1,qualdata!$P$2:$BR$17,"")),qualdata!$M$2:$M$17,qualdata!$O$2:$O$17,"")} | DK41: {=xlookup($Y42,qualdata!$N$2:$N$17,xlookup("r4Ser",qualdata!$P$1:$BR$1,qualdata!$P$2:$BR$17,""))} | DM41: {=xlookup(xlookup($Y42,qualdata!$N$2:$N$17,xlookup("r4op",qualdata!$P$1:$BR$1,qualdata!$P$2:$BR$17,"")),qualdata!$M$2:$M$17,qualdata!$O$2:$O$17,"")} | DT41: {=xlookup($Y42,qualdata!$N$2:$N$17,xlookup("r5Ser",qualdata!$P$1:$BR$1,qualdata!$P$2:$BR$17,""))} | DV41: {=xlookup(xlookup($Y42,qualdata!$N$2:$N$17,xlookup("r5op",qualdata!$P$1:$BR$1,qualdata!$P$2:$BR$17,"")),qualdata!$M$2:$M$17,qualdata!$O$2:$O$17,"")}
R42: {=xlookup(Y42,qualdata!$N$2:$N$17,qualdata!$O$2:$O$17,"")} | Y42: {=xlookup(Q41,qualdata!$G$24:$G$39,qualdata!$A$24:$A$39,"")} -> Team 5 (Group 1) | BC42: {=xlookup(Y42,qualdata!$A$24:$A$39,qualdata!$B$24:$B$39,"")} -> 0-0 | BL42: {=xlookup(Y42,qualdata!$A$24:$A$39,qualdata!$C$24:$C$39,"")} -> 0-0 | BU42: {=xlookup(Y42,qualdata!$A$24:$A$39,qualdata!$D$24:$D$39,"")} -> 0-0 | CD42: {=xlookup(Y42,qualdata!$A$24:$A$39,qualdata!$F$24:$F$39,"")} -> 0
CJ46: {=xlookup($Y42,qualdata!$N$2:$N$17,xlookup("r1gw",qualdata!$P$1:$BR$1,qualdata!$P$2:$BR$17))&"-"&xlookup($Y42,qualdata!$N$2:$N$17,xlookup("r1gl",qualdata!$P$1:$BR$1,qualdata!$P$2:$BR$17))} -> - | CO46: {=if(xlookup($Y42,qualdata!$N$2:$N$17,xlookup("r1rd",qualdata!$P$1:$BR$1,qualdata!$P$2:$BR$17))>0,"+"&xlookup($Y42,qualdata!$N$2:$N$17,xlookup("r1rd",qualdata!$P$1:$BR$1,qualdata!$P$2:$BR$17)),xlookup($Y42,qualdata!$N$2:$N$17,xlookup("r1rd",qualdata!$P$1:$BR$1,qualdata!$P$2:$BR$17)))} -> 0 | CS46: {=xlookup($Y42,qualdata!$N$2:$N$17,xlookup("r2gw",qualdata!$P$1:$BR$1,qualdata!$P$2:$BR$17))&"-"&xlookup($Y42,qualdata!$N$2:$N$17,xlookup("r2gl",qualdata!$P$1:$BR$1,qualdata!$P$2:$BR$17))} -> - | CX46: {=if(xlookup($Y42,qualdata!$N$2:$N$17,xlookup("r2rd",qualdata!$P$1:$BR$1,qualdata!$P$2:$BR$17))>0,"+"&xlookup($Y42,qualdata!$N$2:$N$17,xlookup("r2rd",qualdata!$P$1:$BR$1,qualdata!$P$2:$BR$17)),xlookup($Y42,qualdata!$N$2:$N$17,xlookup("r2rd",qualdata!$P$1:$BR$1,qualdata!$P$2:$BR$17)))} -> 0 | DB46: {=xlookup($Y42,qualdata!$N$2:$N$17,xlookup("r3gw",qualdata!$P$1:$BR$1,qualdata!$P$2:$BR$17))&"-"&xlookup($Y42,qualdata!$N$2:$N$17,xlookup("r3gl",qualdata!$P$1:$BR$1,qualdata!$P$2:$BR$17))} -> - | DG46: {=if(xlookup($Y42,qualdata!$N$2:$N$17,xlookup("r3rd",qualdata!$P$1:$BR$1,qualdata!$P$2:$BR$17))>0,"+"&xlookup($Y42,qualdata!$N$2:$N$17,xlookup("r3rd",qualdata!$P$1:$BR$1,qualdata!$P$2:$BR$17)),xlookup($Y42,qualdata!$N$2:$N$17,xlookup("r3rd",qualdata!$P$1:$BR$1,qualdata!$P$2:$BR$17)))} -> 0 | DK46: {=xlookup($Y42,qualdata!$N$2:$N$17,xlookup("r4gw",qualdata!$P$1:$BR$1,qualdata!$P$2:$BR$17))&"-"&xlookup($Y42,qualdata!$N$2:$N$17,xlookup("r4gl",qualdata!$P$1:$BR$1,qualdata!$P$2:$BR$17))} -> - | DP46: {=if(xlookup($Y42,qualdata!$N$2:$N$17,xlookup("r4rd",qualdata!$P$1:$BR$1,qualdata!$P$2:$BR$17))>0,"+"&xlookup($Y42,qualdata!$N$2:$N$17,xlookup("r4rd",qualdata!$P$1:$BR$1,qualdata!$P$2:$BR$17)),xlookup($Y42,qualdata!$N$2:$N$17,xlookup("r4rd",qualdata!$P$1:$BR$1,qualdata!$P$2:$BR$17)))} -> 0
M49: =Q49&"." -> 6. | Q49: 6 | CJ49: {=xlookup($Y50,qualdata!$N$2:$N$17,xlookup("r1Ser",qualdata!$P$1:$BR$1,qualdata!$P$2:$BR$17,""))} | CL49: {=xlookup(xlookup($Y50,qualdata!$N$2:$N$17,xlookup("r1op",qualdata!$P$1:$BR$1,qualdata!$P$2:$BR$17,"")),qualdata!$M$2:$M$17,qualdata!$O$2:$O$17,"")} | CS49: {=xlookup($Y50,qualdata!$N$2:$N$17,xlookup("r2Ser",qualdata!$P$1:$BR$1,qualdata!$P$2:$BR$17,""))} | CU49: {=xlookup(xlookup($Y50,qualdata!$N$2:$N$17,xlookup("r2op",qualdata!$P$1:$BR$1,qualdata!$P$2:$BR$17,"")),qualdata!$M$2:$M$17,qualdata!$O$2:$O$17,"")} | DB49: {=xlookup($Y50,qualdata!$N$2:$N$17,xlookup("r3Ser",qualdata!$P$1:$BR$1,qualdata!$P$2:$BR$17,""))} | DD49: {=xlookup(xlookup($Y50,qualdata!$N$2:$N$17,xlookup("r3op",qualdata!$P$1:$BR$1,qualdata!$P$2:$BR$17,"")),qualdata!$M$2:$M$17,qualdata!$O$2:$O$17,"")} | DK49: {=xlookup($Y50,qualdata!$N$2:$N$17,xlookup("r4Ser",qualdata!$P$1:$BR$1,qualdata!$P$2:$BR$17,""))} | DM49: {=xlookup(xlookup($Y50,qualdata!$N$2:$N$17,xlookup("r4op",qualdata!$P$1:$BR$1,qualdata!$P$2:$BR$17,"")),qualdata!$M$2:$M$17,qualdata!$O$2:$O$17,"")} | DT49: {=xlookup($Y50,qualdata!$N$2:$N$17,xlookup("r5Ser",qualdata!$P$1:$BR$1,qualdata!$P$2:$BR$17,""))} | DV49: {=xlookup(xlookup($Y50,qualdata!$N$2:$N$17,xlookup("r5op",qualdata!$P$1:$BR$1,qualdata!$P$2:$BR$17,"")),qualdata!$M$2:$M$17,qualdata!$O$2:$O$17,"")}
R50: {=xlookup(Y50,qualdata!$N$2:$N$17,qualdata!$O$2:$O$17,"")} | Y50: {=xlookup(Q49,qualdata!$G$24:$G$39,qualdata!$A$24:$A$39,"")} -> Team 6 (Group 1) | BC50: {=xlookup(Y50,qualdata!$A$24:$A$39,qualdata!$B$24:$B$39,"")} -> 0-0 | BL50: {=xlookup(Y50,qualdata!$A$24:$A$39,qualdata!$C$24:$C$39,"")} -> 0-0 | BU50: {=xlookup(Y50,qualdata!$A$24:$A$39,qualdata!$D$24:$D$39,"")} -> 0-0 | CD50: {=xlookup(Y50,qualdata!$A$24:$A$39,qualdata!$F$24:$F$39,"")} -> 0
